# Converted from schematic
# THIS TEMPLATE USES DEFAULTS!  Please edit for corrections.
# If you need help, consult template_rules.txt

weight=3
embed_into_distance=5
acceptable_target_blocks=1,2,3,12,13,250
dimensions=17,13,24
allowable_overhang=0
max_cut_in=2
cut_in_buffer=1
max_leveling=2
leveling_buffer=1
preserve_water=0
preserve_lava=0
preserve_plants=0


rule1=0,100,3134-10
rule2=0,100,622,2838-4,2838-4,2838-4,2838-4,2838-4,2838-4
rule3=0,100,2843-4
rule4=0,100,300
rule5=0,100,2843-14,2843-14,2843-14,2843-14,2843
rule6=0,66,623
rule7=0,25,628
rule8=0,25,630
rule9=0,90,310,311
rule10=0,25,629
rule11=0,15,642
rule12=0,25,621
rule13=0,45,2004-3,2004-3,2015,2015,2015
rule14=0,100,603,603,3509,3509,3509,3509,3509,3509,3509,3509
rule15=0,95,2835-2,2835-2,2835-2,2835-2,2835-2,2835-2,2835-2,2835-1,2835-1,2835-0
rule16=0,66,3225-3
rule17=0,100,308
rule18=0,95,300
rule19=0,100,2843-15
rule20=0,100,2761-11
rule21=0,100,3134,3134,3134,3134,3134-8,3134-2
rule22=0,100,2245
rule23=0,100,2248
rule24=0,100,2291
rule25=0,100,2843


layer
1,1,1,1,1,1,1,1,1,1,1,1,1,1,1,1,1,1,1,1,1,1,1,1
1,1,1,1,1,1,1,1,1,1,1,1,1,1,1,1,1,1,1,1,1,1,1,1
1,1,1,1,1,1,1,1,1,1,1,1,1,1,1,1,1,1,1,1,1,1,1,1
1,1,1,3,3,3,3,3,3,3,3,3,3,3,3,3,3,3,3,3,2,1,1,1
1,1,1,3,3,3,3,3,3,3,3,3,3,3,3,3,3,3,3,3,3,1,1,1
1,1,1,3,3,3,3,3,3,3,3,3,3,3,3,3,3,3,3,3,3,1,1,1
1,1,1,3,3,3,3,3,3,3,3,3,3,3,3,3,3,3,3,3,3,1,1,1
1,1,1,3,3,3,3,3,3,3,3,3,3,3,3,3,3,3,3,3,3,1,1,1
1,1,1,3,3,3,3,3,3,3,3,3,3,3,3,3,3,3,3,3,3,1,1,1
1,1,1,3,3,3,3,3,3,3,3,3,3,3,3,3,3,3,3,3,3,1,1,1
1,1,1,1,1,1,1,3,3,1,1,1,1,1,1,1,1,3,1,1,1,1,1,1
1,1,1,1,1,1,1,1,1,1,1,1,1,1,1,1,1,1,1,1,1,1,1,1
1,1,1,1,1,1,1,1,1,1,1,1,1,1,1,1,1,1,1,1,1,1,1,1
endlayer

layer
4,4,4,4,4,4,4,4,4,4,4,4,4,4,4,4,4,4,4,4,4,4,4,4
4,4,4,4,4,4,4,4,4,4,4,4,4,4,4,4,4,4,4,4,4,4,4,4
4,4,5,5,5,5,5,5,5,5,5,5,5,5,5,5,5,5,5,5,5,5,4,4
4,4,5,0,0,0,0,13,0,11,9,0,0,0,0,0,0,0,0,0,6,5,4,4
4,4,5,0,14,14,14,0,0,0,7,7,0,0,0,0,0,0,0,0,0,5,4,4
4,4,5,0,14,14,14,0,0,0,10,8,0,0,0,0,0,0,0,0,0,5,4,4
4,4,5,0,14,14,14,0,12,0,0,0,0,0,0,0,0,0,0,0,0,5,4,4
4,4,5,0,0,0,0,0,0,0,0,0,0,0,0,0,0,0,0,0,0,5,4,4
4,4,5,0,0,0,4,0,0,0,0,0,0,0,0,0,0,0,0,0,0,5,4,4
4,4,5,0,0,0,0,4,4,0,0,0,0,0,0,0,0,0,0,0,0,5,4,4
4,4,5,5,5,5,5,0,4,5,5,5,5,5,5,5,5,5,5,5,5,5,4,4
4,4,4,4,4,4,4,4,4,4,4,4,4,4,4,4,4,4,4,4,4,4,4,4
4,4,4,4,4,4,4,4,4,4,4,4,4,4,4,4,4,4,4,4,4,4,4,4
endlayer

layer
4,4,4,4,4,4,4,4,4,4,4,4,4,4,4,4,4,4,4,4,4,4,4,4
4,4,4,4,4,4,4,4,4,4,4,4,4,4,4,4,4,4,4,4,4,4,4,4
4,4,5,15,16,16,15,16,16,15,16,16,15,5,15,16,15,16,15,16,15,5,4,4
4,4,15,0,0,0,0,0,0,0,0,0,0,0,0,0,0,0,0,0,6,15,4,4
4,4,16,0,14,14,14,0,0,0,0,0,0,0,0,0,0,0,0,0,0,16,4,4
4,4,15,0,14,17,14,0,0,0,0,0,0,0,0,0,0,0,0,0,0,15,4,4
4,4,16,0,14,14,14,0,0,0,0,0,0,0,0,0,0,0,0,0,0,16,4,4
4,4,15,0,0,0,0,0,0,0,0,0,0,0,0,0,0,0,0,0,0,15,4,4
4,4,16,0,0,0,0,0,0,0,0,0,0,0,0,0,0,0,0,0,0,16,4,4
4,4,15,0,0,0,0,0,0,0,0,0,0,0,0,0,0,0,0,0,0,15,4,4
4,4,5,15,16,16,15,0,4,15,16,16,15,5,15,16,15,16,15,16,15,5,4,4
4,4,4,4,4,4,4,4,4,4,4,4,4,4,4,4,4,4,4,4,4,4,4,4
4,4,4,4,4,4,4,4,4,4,4,4,4,4,4,4,4,4,4,4,4,4,4,4
endlayer

layer
4,4,4,4,4,4,4,4,4,4,4,4,4,4,4,4,4,4,4,4,4,4,4,4
4,4,4,4,4,4,4,4,4,4,4,4,4,4,4,4,4,4,4,4,4,4,4,4
4,4,5,15,16,16,15,16,16,15,16,16,15,5,15,16,15,16,15,16,15,5,4,4
4,4,15,0,0,0,0,0,0,0,0,0,0,0,0,0,0,0,0,0,6,15,4,4
4,4,16,0,14,14,14,0,0,0,0,0,0,0,0,0,0,0,0,0,0,16,4,4
4,4,15,0,14,14,14,0,0,0,0,0,0,0,0,0,0,0,0,0,0,15,4,4
4,4,16,0,14,14,14,0,0,0,0,0,0,0,0,0,0,0,0,0,0,16,4,4
4,4,15,0,0,0,0,0,0,0,0,0,0,0,0,0,0,0,0,0,0,15,4,4
4,4,16,0,0,0,0,0,0,0,0,0,0,0,0,0,0,0,0,0,0,16,4,4
4,4,15,0,0,0,0,0,0,0,0,0,0,0,0,0,0,0,0,0,0,15,4,4
4,4,5,15,16,16,15,15,15,15,16,16,15,5,15,16,15,16,15,16,15,5,4,4
4,4,4,4,4,4,4,4,4,4,4,4,4,4,4,4,4,4,4,4,4,4,4,4
4,4,4,4,4,4,4,4,4,4,4,4,4,4,4,4,4,4,4,4,4,4,4,4
endlayer

layer
18,18,18,18,18,18,18,18,18,18,18,18,18,18,18,18,18,18,18,18,18,18,18,18
18,18,18,18,18,18,18,18,18,18,18,18,18,18,18,18,18,18,18,18,18,18,18,18
18,18,5,15,16,16,15,16,16,15,16,16,15,5,15,16,15,16,15,16,15,5,18,18
18,18,15,0,0,0,0,0,0,0,0,0,0,0,0,0,0,0,0,0,6,15,18,18
18,18,16,0,0,0,0,0,0,0,0,0,0,0,0,0,0,0,0,0,0,16,18,18
18,18,15,0,0,0,19,0,0,0,0,0,0,0,0,0,0,0,0,0,0,15,18,18
18,18,16,0,0,0,0,0,0,0,0,0,0,0,0,0,0,0,0,0,0,16,18,18
18,18,15,0,0,0,0,0,0,0,0,0,0,0,0,0,0,0,0,0,0,15,18,18
18,18,16,0,0,0,0,0,0,0,0,0,0,0,0,0,0,0,0,0,0,16,18,18
18,18,15,0,0,0,0,0,0,0,0,0,0,0,0,0,0,0,0,0,0,15,18,18
18,18,5,15,16,16,15,16,16,15,16,16,15,5,15,16,15,16,15,16,15,5,18,18
18,18,18,18,18,18,18,18,18,18,18,18,18,18,18,18,18,18,18,18,18,18,18,18
18,18,18,18,18,18,18,18,18,18,18,18,18,18,18,18,18,18,18,18,18,18,18,18
endlayer

layer
0,0,0,0,0,0,0,0,0,0,0,0,0,0,0,0,0,0,0,0,0,0,0,0
0,0,0,0,0,0,0,0,0,0,0,0,0,0,0,0,0,0,0,0,0,0,0,0
0,0,5,15,16,16,15,16,16,15,16,16,15,5,15,16,15,16,15,16,15,5,0,0
0,0,15,0,0,0,0,0,0,0,0,0,0,0,0,0,0,0,0,0,6,15,0,0
0,0,16,0,0,0,0,0,0,0,0,0,0,0,0,0,0,0,0,0,0,16,0,0
0,0,15,0,0,0,19,0,0,0,0,0,0,0,0,0,0,0,0,0,0,15,0,0
0,0,16,0,0,0,0,0,0,0,0,0,0,0,0,0,0,0,0,0,0,16,0,0
0,0,15,0,0,0,0,0,0,0,0,0,0,0,0,0,0,0,0,0,0,15,0,0
0,0,16,0,0,0,0,0,0,0,0,0,0,0,0,0,0,0,0,0,0,16,0,0
0,0,15,0,0,0,0,0,0,0,0,0,0,0,0,0,0,0,0,0,0,15,0,0
0,0,5,15,16,16,15,16,16,15,16,16,15,5,15,16,15,16,15,16,15,5,0,0
0,0,0,0,0,0,0,0,0,0,0,0,0,0,0,0,0,0,0,0,0,0,0,0
0,0,0,0,0,0,0,0,0,0,0,0,0,0,0,0,0,0,0,0,0,0,0,0
endlayer

layer
0,0,0,0,0,0,0,0,0,0,0,0,0,0,0,0,0,0,0,0,0,0,0,0
0,0,0,0,0,0,0,0,0,0,0,0,0,0,0,0,0,0,0,0,0,0,0,0
0,0,5,15,16,16,15,16,16,15,16,16,15,5,15,16,15,16,15,16,15,5,0,0
0,0,15,0,0,0,0,0,0,0,0,0,0,0,0,0,0,0,0,0,6,15,0,0
0,0,16,0,0,0,0,0,0,0,0,0,0,0,0,0,0,0,0,0,0,16,0,0
0,0,15,0,0,0,19,0,0,0,0,0,0,0,0,0,0,0,0,0,0,15,0,0
0,0,16,0,0,0,0,0,0,0,0,0,0,0,0,0,0,0,0,0,0,16,0,0
0,0,15,0,0,0,0,0,0,0,0,0,0,0,0,0,0,0,0,0,0,15,0,0
0,0,16,0,0,0,0,0,0,0,0,0,0,0,0,0,0,0,0,0,0,16,0,0
0,0,15,0,0,0,0,0,0,0,0,0,0,0,0,0,0,0,0,0,0,15,0,0
0,0,5,15,16,16,15,16,16,15,16,16,15,5,15,16,15,16,15,16,15,5,0,0
0,0,0,0,0,0,0,0,0,0,0,0,0,0,0,0,0,0,0,0,0,0,0,0
0,0,0,0,0,0,0,0,0,0,0,0,0,0,0,0,0,0,0,0,0,0,0,0
endlayer

layer
0,0,0,0,0,0,0,0,0,0,0,0,0,0,0,0,0,0,0,0,0,0,0,0
0,0,0,0,0,0,0,0,0,0,0,0,0,0,0,0,0,0,0,0,0,0,0,0
0,0,5,15,16,16,15,16,16,15,16,16,15,5,15,16,15,16,15,16,15,5,0,0
0,0,15,0,0,0,0,0,0,0,0,0,0,0,0,0,0,0,0,0,6,15,0,0
0,0,16,0,0,0,0,0,0,0,0,0,0,0,0,0,0,0,0,0,0,16,0,0
0,0,15,0,0,0,19,0,0,0,0,0,0,0,0,0,0,0,0,0,0,15,0,0
0,0,16,0,0,0,0,0,0,0,0,0,0,0,0,0,0,0,0,0,0,16,0,0
0,0,15,0,0,0,0,0,0,0,0,0,0,0,0,0,0,0,0,0,0,15,0,0
0,0,16,0,0,0,0,0,0,0,0,0,0,0,0,0,0,0,0,0,0,16,0,0
0,0,15,0,0,0,0,0,0,0,0,0,0,0,0,0,0,0,0,0,0,15,0,0
0,0,5,15,16,16,15,16,16,15,16,16,15,5,15,16,15,16,15,16,15,5,0,0
0,0,0,0,0,0,0,0,0,0,0,0,0,0,0,0,0,0,0,0,0,0,0,0
0,0,0,0,0,0,0,0,0,0,0,0,0,0,0,0,0,0,0,0,0,0,0,0
endlayer

layer
0,0,0,0,0,0,0,0,0,0,0,0,0,0,0,0,0,0,0,0,0,0,0,0
0,0,0,0,0,0,0,0,0,0,0,0,0,0,0,0,0,0,0,0,0,0,0,0
0,0,5,5,5,5,5,5,5,5,5,5,5,5,5,5,5,5,5,5,5,5,0,0
0,0,5,21,21,21,21,21,21,21,21,21,21,5,20,20,20,20,20,20,6,5,0,0
0,0,5,21,21,21,21,21,21,21,21,21,21,5,20,20,20,20,20,20,20,5,0,0
0,0,5,21,21,21,19,21,21,21,21,21,21,5,20,20,20,20,20,20,20,5,0,0
0,0,5,21,21,21,21,21,21,21,21,21,21,5,20,20,20,20,20,20,20,5,0,0
0,0,5,21,21,21,21,21,21,21,21,21,21,5,20,20,20,20,20,20,20,5,0,0
0,0,5,21,21,21,21,21,21,21,21,21,21,5,20,20,20,20,20,20,20,5,0,0
0,0,5,21,21,21,21,21,21,21,21,21,21,5,20,20,20,20,20,20,20,5,0,0
0,0,5,5,5,5,5,5,5,5,5,5,5,5,5,5,5,5,5,5,5,5,0,0
0,0,0,0,0,0,0,0,0,0,0,0,0,0,0,0,0,0,0,0,0,0,0,0
0,0,0,0,0,0,0,0,0,0,0,0,0,0,0,0,0,0,0,0,0,0,0,0
endlayer

layer
0,0,0,0,0,0,0,0,0,0,0,0,0,0,0,0,0,0,0,0,0,0,0,0
0,0,0,0,0,0,0,0,0,0,0,0,0,0,0,0,0,0,0,0,0,0,0,0
0,0,0,0,0,0,0,0,0,0,0,0,0,5,15,16,15,16,15,16,15,5,0,0
0,0,0,0,0,0,0,0,0,0,0,0,0,15,0,0,0,0,0,0,6,15,0,0
0,0,0,0,0,0,0,0,0,0,0,0,0,16,0,0,0,0,0,0,0,16,0,0
0,0,0,0,0,0,19,0,0,0,0,0,0,15,0,0,22,0,0,0,0,15,0,0
0,0,0,0,0,0,0,0,0,0,0,0,0,16,0,24,23,0,0,0,0,16,0,0
0,0,0,0,0,0,0,0,0,0,0,0,0,15,0,17,22,0,0,0,0,15,0,0
0,0,0,0,0,0,0,0,0,0,0,0,0,16,0,0,0,0,0,0,0,16,0,0
0,0,0,0,0,0,0,0,0,0,0,0,0,15,0,0,0,0,0,0,9,15,0,0
0,0,0,0,0,0,0,0,0,0,0,0,0,5,15,16,15,16,15,16,15,5,0,0
0,0,0,0,0,0,0,0,0,0,0,0,0,0,0,0,0,0,0,0,0,0,0,0
0,0,0,0,0,0,0,0,0,0,0,0,0,0,0,0,0,0,0,0,0,0,0,0
endlayer

layer
0,0,0,0,0,0,0,0,0,0,0,0,0,0,0,0,0,0,0,0,0,0,0,0
0,0,0,0,0,0,0,0,0,0,0,0,0,0,0,0,0,0,0,0,0,0,0,0
0,0,0,0,0,0,0,0,0,0,0,0,0,5,15,16,15,16,15,16,15,5,0,0
0,0,0,0,0,0,0,0,0,0,0,0,0,15,0,0,0,0,0,0,6,15,0,0
0,0,0,0,0,0,0,0,0,0,0,0,0,16,0,0,0,0,0,0,0,16,0,0
0,0,0,0,0,0,19,0,0,0,0,0,0,15,0,0,0,0,0,0,0,15,0,0
0,0,0,0,0,0,0,0,0,0,0,0,0,16,0,0,0,0,0,0,0,16,0,0
0,0,0,0,0,0,0,0,0,0,0,0,0,15,0,0,0,0,0,0,0,15,0,0
0,0,0,0,0,0,0,0,0,0,0,0,0,16,0,0,0,0,0,0,0,16,0,0
0,0,0,0,0,0,0,0,0,0,0,0,0,15,0,0,0,0,0,0,0,15,0,0
0,0,0,0,0,0,0,0,0,0,0,0,0,5,15,16,15,16,15,16,15,5,0,0
0,0,0,0,0,0,0,0,0,0,0,0,0,0,0,0,0,0,0,0,0,0,0,0
0,0,0,0,0,0,0,0,0,0,0,0,0,0,0,0,0,0,0,0,0,0,0,0
endlayer

layer
0,0,0,0,0,0,0,0,0,0,0,0,0,0,0,0,0,0,0,0,0,0,0,0
0,0,0,0,0,0,0,0,0,0,0,0,0,0,0,0,0,0,0,0,0,0,0,0
0,0,0,0,0,0,0,0,0,0,0,0,0,5,15,16,15,16,15,16,15,5,0,0
0,0,0,0,0,0,0,0,0,0,0,0,0,15,0,0,0,0,0,0,0,15,0,0
0,0,0,0,0,0,0,0,0,0,0,0,0,16,0,0,0,0,0,0,0,16,0,0
0,0,0,0,0,0,25,0,0,0,0,0,0,15,0,0,0,0,0,0,0,15,0,0
0,0,0,0,0,0,0,0,0,0,0,0,0,16,0,0,0,0,0,0,0,16,0,0
0,0,0,0,0,0,0,0,0,0,0,0,0,15,0,0,0,0,0,0,0,15,0,0
0,0,0,0,0,0,0,0,0,0,0,0,0,16,0,0,0,0,0,0,0,16,0,0
0,0,0,0,0,0,0,0,0,0,0,0,0,15,0,0,0,0,0,0,0,15,0,0
0,0,0,0,0,0,0,0,0,0,0,0,0,5,15,16,15,16,15,16,15,5,0,0
0,0,0,0,0,0,0,0,0,0,0,0,0,0,0,0,0,0,0,0,0,0,0,0
0,0,0,0,0,0,0,0,0,0,0,0,0,0,0,0,0,0,0,0,0,0,0,0
endlayer

layer
0,0,0,0,0,0,0,0,0,0,0,0,0,0,0,0,0,0,0,0,0,0,0,0
0,0,0,0,0,0,0,0,0,0,0,0,0,0,0,0,0,0,0,0,0,0,0,0
0,0,0,0,0,0,0,0,0,0,0,0,0,5,15,16,15,16,15,16,15,5,0,0
0,0,0,0,0,0,0,0,0,0,0,0,0,15,0,0,0,0,0,0,0,15,0,0
0,0,0,0,0,0,0,0,0,0,0,0,0,16,0,0,0,0,0,0,0,16,0,0
0,0,0,0,0,0,19,0,0,0,0,0,0,15,0,0,0,0,0,0,0,15,0,0
0,0,0,0,0,0,0,0,0,0,0,0,0,16,0,0,0,0,0,0,0,16,0,0
0,0,0,0,0,0,0,0,0,0,0,0,0,15,0,0,0,0,0,0,0,15,0,0
0,0,0,0,0,0,0,0,0,0,0,0,0,16,0,0,0,0,0,0,0,16,0,0
0,0,0,0,0,0,0,0,0,0,0,0,0,15,0,0,0,0,0,0,0,15,0,0
0,0,0,0,0,0,0,0,0,0,0,0,0,5,15,16,15,16,15,16,15,5,0,0
0,0,0,0,0,0,0,0,0,0,0,0,0,0,0,0,0,0,0,0,0,0,0,0
0,0,0,0,0,0,0,0,0,0,0,0,0,0,0,0,0,0,0,0,0,0,0,0
endlayer

layer
0,0,0,0,0,0,0,0,0,0,0,0,0,0,0,0,0,0,0,0,0,0,0,0
0,0,0,0,0,0,0,0,0,0,0,0,0,0,0,0,0,0,0,0,0,0,0,0
0,0,0,0,0,0,0,0,0,0,0,0,0,5,15,16,15,16,15,16,15,5,0,0
0,0,0,0,0,0,0,0,0,0,0,0,0,15,0,0,0,0,0,0,0,15,0,0
0,0,0,0,0,0,0,0,0,0,0,0,0,16,0,0,0,0,0,0,0,16,0,0
0,0,0,0,0,0,19,0,0,0,0,0,0,15,0,0,0,0,0,0,0,15,0,0
0,0,0,0,0,0,0,0,0,0,0,0,0,16,0,0,0,0,0,0,0,16,0,0
0,0,0,0,0,0,0,0,0,0,0,0,0,15,0,0,0,0,0,0,0,15,0,0
0,0,0,0,0,0,0,0,0,0,0,0,0,16,0,0,0,0,0,0,0,16,0,0
0,0,0,0,0,0,0,0,0,0,0,0,0,15,0,0,0,0,0,0,0,15,0,0
0,0,0,0,0,0,0,0,0,0,0,0,0,5,15,16,15,16,15,16,15,5,0,0
0,0,0,0,0,0,0,0,0,0,0,0,0,0,0,0,0,0,0,0,0,0,0,0
0,0,0,0,0,0,0,0,0,0,0,0,0,0,0,0,0,0,0,0,0,0,0,0
endlayer

layer
0,0,0,0,0,0,0,0,0,0,0,0,0,0,0,0,0,0,0,0,0,0,0,0
0,0,0,0,0,0,0,0,0,0,0,0,0,0,0,0,0,0,0,0,0,0,0,0
0,0,0,0,0,0,0,0,0,0,0,0,0,5,15,16,15,16,15,16,15,5,0,0
0,0,0,0,0,0,0,0,0,0,0,0,0,15,0,0,0,0,0,0,0,15,0,0
0,0,0,0,0,0,0,0,0,0,0,0,0,16,0,0,0,0,0,0,0,16,0,0
0,0,0,0,0,0,25,0,0,0,0,0,0,15,0,0,0,0,0,0,0,15,0,0
0,0,0,0,0,0,0,0,0,0,0,0,0,16,0,0,0,0,0,0,0,16,0,0
0,0,0,0,0,0,0,0,0,0,0,0,0,15,0,0,0,0,0,0,0,15,0,0
0,0,0,0,0,0,0,0,0,0,0,0,0,16,0,0,0,0,0,0,0,16,0,0
0,0,0,0,0,0,0,0,0,0,0,0,0,15,0,0,0,0,0,0,0,15,0,0
0,0,0,0,0,0,0,0,0,0,0,0,0,5,15,16,15,16,15,16,15,5,0,0
0,0,0,0,0,0,0,0,0,0,0,0,0,0,0,0,0,0,0,0,0,0,0,0
0,0,0,0,0,0,0,0,0,0,0,0,0,0,0,0,0,0,0,0,0,0,0,0
endlayer

layer
0,0,0,0,0,0,0,0,0,0,0,0,0,0,0,0,0,0,0,0,0,0,0,0
0,0,0,0,0,0,0,0,0,0,0,0,0,0,0,0,0,0,0,0,0,0,0,0
0,0,0,0,0,0,0,0,0,0,0,0,0,5,15,16,15,16,15,16,15,5,0,0
0,0,0,0,0,0,0,0,0,0,0,0,0,15,0,0,0,0,0,0,0,15,0,0
0,0,0,0,0,0,0,0,0,0,0,0,0,16,0,0,0,0,0,0,0,16,0,0
0,0,0,0,0,0,19,0,0,0,0,0,0,15,0,0,0,0,0,0,0,15,0,0
0,0,0,0,0,0,0,0,0,0,0,0,0,16,0,0,0,0,0,0,0,16,0,0
0,0,0,0,0,0,0,0,0,0,0,0,0,15,0,0,0,0,0,0,0,15,0,0
0,0,0,0,0,0,0,0,0,0,0,0,0,16,0,0,0,0,0,0,0,16,0,0
0,0,0,0,0,0,0,0,0,0,0,0,0,15,0,0,0,0,0,0,0,15,0,0
0,0,0,0,0,0,0,0,0,0,0,0,0,5,15,16,15,16,15,16,15,5,0,0
0,0,0,0,0,0,0,0,0,0,0,0,0,0,0,0,0,0,0,0,0,0,0,0
0,0,0,0,0,0,0,0,0,0,0,0,0,0,0,0,0,0,0,0,0,0,0,0
endlayer

layer
0,0,0,0,0,0,0,0,0,0,0,0,0,0,0,0,0,0,0,0,0,0,0,0
0,0,0,0,0,0,0,0,0,0,0,0,0,0,0,0,0,0,0,0,0,0,0,0
0,0,0,0,0,0,0,0,0,0,0,0,0,5,5,5,5,5,5,5,5,5,0,0
0,0,0,0,0,0,0,0,0,0,0,0,0,5,21,21,21,21,21,21,21,5,0,0
0,0,0,0,0,0,0,0,0,0,0,0,0,5,21,21,21,21,21,21,21,5,0,0
0,0,0,0,0,0,19,0,0,0,0,0,0,5,21,21,21,21,21,21,21,5,0,0
0,0,0,0,0,0,0,0,0,0,0,0,0,5,21,21,21,21,21,21,21,5,0,0
0,0,0,0,0,0,0,0,0,0,0,0,0,5,21,21,21,21,21,21,21,5,0,0
0,0,0,0,0,0,0,0,0,0,0,0,0,5,21,21,21,21,21,21,21,5,0,0
0,0,0,0,0,0,0,0,0,0,0,0,0,5,21,21,21,21,21,21,21,5,0,0
0,0,0,0,0,0,0,0,0,0,0,0,0,5,5,5,5,5,5,5,5,5,0,0
0,0,0,0,0,0,0,0,0,0,0,0,0,0,0,0,0,0,0,0,0,0,0,0
0,0,0,0,0,0,0,0,0,0,0,0,0,0,0,0,0,0,0,0,0,0,0,0
endlayer

