# Converted from schematic
# THIS TEMPLATE USES DEFAULTS!  Please edit for corrections.
# If you need help, consult template_rules.txt

weight=10
embed_into_distance=1
acceptable_target_blocks=1,2,3,12,13,250
dimensions=16,15,15
allowable_overhang=0
max_cut_in=2
cut_in_buffer=1
max_leveling=2
leveling_buffer=1
preserve_water=0
preserve_lava=0
preserve_plants=0


rule1=0,100,3134-10
rule2=0,100,2843-4
rule3=0,66,311
rule4=0,100,300
rule5=0,100,2542
rule6=0,100,2843-14,2843-14,2843-14,2843-14,2843
rule7=0,100,2761-6,2761-6,2761-6,2761-7,2761-7
rule8=0,100,2843-12
rule9=0,100,2291
rule10=0,100,2248
rule11=1,100,47,2837-7,2837-5,2837-8,47,2837-7,2837-5,2837-8,311,250,250
rule12=0,95,2835-2,2835-2,2835-2,2835-2,2835-2,2835-2,2835-2,2835-1,2835-1,2835-0
rule13=0,25,3225-3
rule14=0,100,308,308,308,308,308,308,313,313,314,327
rule15=0,100,3134,3134,3134,3134,3134,3134,3134,3134,3134,3134-8,3134-2


layer
1,1,1,1,1,1,1,1,1,1,1,1,1,1,1
1,1,1,1,1,1,1,1,1,1,1,1,1,1,1
1,1,2,2,2,2,2,2,2,2,2,2,2,1,1
1,1,2,2,2,2,2,2,2,2,2,2,2,1,1
1,1,2,2,2,2,2,2,2,2,2,2,2,1,1
1,1,2,2,2,2,2,2,2,2,2,2,2,1,1
1,1,2,2,2,2,2,2,4,3,2,2,2,1,1
1,1,2,5,2,2,2,2,2,4,2,2,2,1,1
1,1,2,2,2,2,2,2,4,4,2,2,2,1,1
1,1,2,2,2,2,2,2,2,2,2,2,2,1,1
1,1,2,2,2,2,2,2,2,2,2,2,2,1,1
1,1,2,2,2,2,2,2,2,2,2,2,2,1,1
1,1,2,2,2,2,2,2,2,2,2,2,2,1,1
1,1,1,1,1,1,1,1,1,1,1,1,1,1,1
1,1,1,1,1,1,1,1,1,1,1,1,1,1,1
endlayer

layer
0,0,0,0,0,0,0,0,0,0,0,0,0,0,0
0,0,0,0,0,0,0,0,0,0,0,0,0,0,0
0,0,6,6,6,6,6,6,6,6,6,6,6,0,0
0,0,6,10,9,8,0,0,0,0,0,0,6,0,0
0,0,6,11,0,8,0,0,0,0,0,0,6,0,0
0,0,6,8,0,8,0,0,0,0,0,0,6,0,0
0,0,6,0,0,0,0,0,7,7,0,0,6,0,0
0,0,6,0,0,0,0,0,0,7,0,0,0,0,0
0,0,6,0,0,0,0,0,7,7,0,0,6,0,0
0,0,6,8,0,8,0,0,0,0,0,0,6,0,0
0,0,6,11,0,8,0,0,0,0,0,0,6,0,0
0,0,6,10,9,8,0,0,0,0,0,0,6,0,0
0,0,6,6,6,6,6,6,6,6,6,6,6,0,0
0,0,0,0,0,0,0,0,0,0,0,0,0,0,0
0,0,0,0,0,0,0,0,0,0,0,0,0,0,0
endlayer

layer
0,0,0,0,0,0,0,0,0,0,0,0,0,0,0
0,0,0,0,0,0,0,0,0,0,0,0,0,0,0
0,0,6,12,13,13,12,13,12,13,13,12,6,0,0
0,0,12,0,0,8,0,0,0,0,0,0,12,0,0
0,0,13,11,0,8,0,0,0,0,0,0,13,0,0
0,0,13,8,0,8,0,0,0,0,0,0,13,0,0
0,0,12,0,0,0,0,0,0,0,0,0,12,0,0
0,0,13,0,0,0,0,0,0,0,0,0,0,0,0
0,0,12,0,0,0,0,0,0,0,0,0,12,0,0
0,0,13,8,0,8,0,0,0,0,0,0,13,0,0
0,0,13,11,0,8,0,0,0,0,0,0,13,0,0
0,0,12,0,0,8,0,0,0,0,0,0,12,0,0
0,0,6,12,13,13,12,13,12,13,13,12,6,0,0
0,0,0,0,0,0,0,0,0,0,0,0,0,0,0
0,0,0,0,0,0,0,0,0,0,0,0,0,0,0
endlayer

layer
0,0,0,0,0,0,0,0,0,0,0,0,0,0,0
0,0,0,0,0,0,0,0,0,0,0,0,0,0,0
0,0,6,12,13,13,12,13,12,13,13,12,6,0,0
0,0,12,0,0,0,0,0,0,0,0,0,12,0,0
0,0,13,0,0,0,0,0,0,0,0,0,13,0,0
0,0,13,0,0,0,0,0,0,0,0,0,13,0,0
0,0,12,0,0,0,0,0,0,0,0,0,12,0,0
0,0,13,0,0,0,0,0,0,0,0,0,12,0,0
0,0,12,0,0,0,0,0,0,0,0,0,12,0,0
0,0,13,0,0,0,0,0,0,0,0,0,13,0,0
0,0,13,0,0,0,0,0,0,0,0,0,13,0,0
0,0,12,0,0,0,0,0,0,0,0,0,12,0,0
0,0,6,12,13,13,12,13,12,13,13,12,6,0,0
0,0,0,0,0,0,0,0,0,0,0,0,0,0,0
0,0,0,0,0,0,0,0,0,0,0,0,0,0,0
endlayer

layer
0,0,0,0,0,0,0,0,0,0,0,0,0,0,0
0,0,0,0,0,0,0,0,0,0,0,0,0,0,0
0,0,6,12,13,13,12,13,12,13,13,12,6,0,0
0,0,12,0,0,0,0,0,0,0,0,0,12,0,0
0,0,13,0,0,0,0,0,0,0,0,0,13,0,0
0,0,13,0,0,0,0,0,0,0,0,0,13,0,0
0,0,12,0,0,0,0,0,0,0,0,0,12,0,0
0,0,13,0,0,0,0,0,0,0,0,0,13,0,0
0,0,12,0,0,0,0,0,0,0,0,0,12,0,0
0,0,13,0,0,0,0,0,0,0,0,0,13,0,0
0,0,13,0,0,0,0,0,0,0,0,0,13,0,0
0,0,12,0,0,0,0,0,0,0,0,0,12,0,0
0,0,6,12,13,13,12,13,12,13,13,12,6,0,0
0,0,0,0,0,0,0,0,0,0,0,0,0,0,0
0,0,0,0,0,0,0,0,0,0,0,0,0,0,0
endlayer

layer
0,0,0,0,0,0,0,0,0,0,0,0,0,0,0
0,0,0,0,0,0,0,0,0,0,0,0,0,0,0
0,0,6,12,13,13,12,13,12,13,13,12,6,0,0
0,0,12,0,0,0,0,0,0,0,0,0,12,0,0
0,0,13,0,0,0,0,0,0,0,0,0,13,0,0
0,0,13,0,0,0,0,0,0,0,0,0,13,0,0
0,0,12,0,0,0,0,0,0,0,0,0,12,0,0
0,0,13,0,0,0,0,0,0,0,0,0,13,0,0
0,0,12,0,0,0,0,0,0,0,0,0,12,0,0
0,0,13,0,0,0,0,0,0,0,0,0,13,0,0
0,0,13,0,0,0,0,0,0,0,0,0,13,0,0
0,0,12,0,0,0,0,0,0,0,0,0,12,0,0
0,0,6,12,13,13,12,13,12,13,13,12,6,0,0
0,0,0,0,0,0,0,0,0,0,0,0,0,0,0
0,0,0,0,0,0,0,0,0,0,0,0,0,0,0
endlayer

layer
0,0,0,0,0,0,0,0,0,0,0,0,0,0,0
0,0,0,0,0,0,0,0,0,0,0,0,0,0,0
0,0,6,12,13,13,12,13,12,13,13,12,6,0,0
0,0,12,0,0,0,0,0,0,0,0,0,12,0,0
0,0,13,0,0,0,0,0,0,0,0,0,13,0,0
0,0,13,0,0,0,0,0,0,0,0,0,13,0,0
0,0,12,0,0,0,0,0,0,0,0,0,12,0,0
0,0,13,0,0,0,0,0,0,0,0,0,13,0,0
0,0,12,0,0,0,0,0,0,0,0,0,12,0,0
0,0,13,0,0,0,0,0,0,0,0,0,13,0,0
0,0,13,0,0,0,0,0,0,0,0,0,13,0,0
0,0,12,0,0,0,0,0,0,0,0,0,12,0,0
0,0,6,12,13,13,12,13,12,13,13,12,6,0,0
0,0,0,0,0,0,0,0,0,0,0,0,0,0,0
0,0,0,0,0,0,0,0,0,0,0,0,0,0,0
endlayer

layer
0,0,0,0,0,0,0,0,0,0,0,0,0,0,0
0,0,0,0,0,0,0,0,0,0,0,0,0,0,0
0,0,6,12,13,13,12,13,12,13,13,12,6,0,0
0,0,12,0,0,0,0,0,0,0,0,0,12,0,0
0,0,13,0,0,0,0,0,0,0,0,0,13,0,0
0,0,13,0,0,0,0,0,0,0,0,0,13,0,0
0,0,12,0,0,0,0,0,0,0,0,0,12,0,0
0,0,13,0,0,0,0,0,0,0,0,0,13,0,0
0,0,12,0,0,0,0,0,0,0,0,0,12,0,0
0,0,13,0,0,0,0,0,0,0,0,0,13,0,0
0,0,13,0,0,0,0,0,0,0,0,0,13,0,0
0,0,12,0,0,0,0,0,0,0,0,0,12,0,0
0,0,6,12,13,13,12,13,12,13,13,12,6,0,0
0,0,0,0,0,0,0,0,0,0,0,0,0,0,0
0,0,0,0,0,0,0,0,0,0,0,0,0,0,0
endlayer

layer
0,0,0,0,0,0,0,0,0,0,0,0,0,0,0
0,0,0,0,0,0,0,0,0,0,0,0,0,0,0
0,0,6,12,13,13,12,13,12,13,13,12,6,0,0
0,0,12,0,0,0,0,0,0,0,0,0,12,0,0
0,0,13,0,0,0,0,0,0,0,0,0,13,0,0
0,0,13,0,0,0,0,0,0,0,0,0,13,0,0
0,0,12,0,0,0,0,0,0,0,0,0,12,0,0
0,0,13,0,0,0,0,0,0,0,0,0,13,0,0
0,0,12,0,0,0,0,0,0,0,0,0,12,0,0
0,0,13,0,0,0,0,0,0,0,0,0,13,0,0
0,0,13,0,0,0,0,0,0,0,0,0,13,0,0
0,0,12,0,0,0,0,0,0,0,0,0,12,0,0
0,0,6,12,13,13,12,13,12,13,13,12,6,0,0
0,0,0,0,0,0,0,0,0,0,0,0,0,0,0
0,0,0,0,0,0,0,0,0,0,0,0,0,0,0
endlayer

layer
0,0,0,0,0,0,0,0,0,0,0,0,0,0,0
0,0,0,0,0,0,0,0,0,0,0,0,0,0,0
0,0,6,6,6,6,6,6,6,6,6,6,6,0,0
0,0,6,2,2,2,2,2,2,2,2,2,6,0,0
0,0,6,2,2,2,2,2,2,2,2,2,6,0,0
0,0,6,2,2,2,2,2,2,2,2,2,6,0,0
0,0,6,2,2,2,2,2,2,2,2,2,6,0,0
0,0,6,5,2,2,2,2,2,2,2,2,6,0,0
0,0,6,2,2,2,2,2,2,2,2,2,6,0,0
0,0,6,2,2,2,2,2,2,2,2,2,6,0,0
0,0,6,2,2,2,2,2,2,2,2,2,6,0,0
0,0,6,2,2,2,2,2,2,2,2,2,6,0,0
0,0,6,6,6,6,6,6,6,6,6,6,6,0,0
0,0,0,0,0,0,0,0,0,0,0,0,0,0,0
0,0,0,0,0,0,0,0,0,0,0,0,0,0,0
endlayer

layer
0,0,0,0,0,0,0,0,0,0,0,0,0,0,0
0,0,0,0,0,0,0,0,0,0,0,0,0,0,0
0,0,6,12,13,13,12,13,12,13,13,12,6,0,0
0,0,12,0,0,0,0,0,0,0,0,0,12,0,0
0,0,13,0,8,10,9,8,9,10,8,0,13,0,0
0,0,13,0,8,11,11,14,11,11,8,0,13,0,0
0,0,12,0,8,10,9,8,9,10,8,0,12,0,0
0,0,13,0,0,0,0,0,0,0,0,0,13,0,0
0,0,12,0,8,10,9,8,9,10,8,0,12,0,0
0,0,13,0,8,11,11,14,11,11,8,0,13,0,0
0,0,13,0,8,10,9,8,9,10,8,0,13,0,0
0,0,12,0,0,0,0,0,0,0,0,0,12,0,0
0,0,6,12,13,13,12,13,12,13,13,12,6,0,0
0,0,0,0,0,0,0,0,0,0,0,0,0,0,0
0,0,0,0,0,0,0,0,0,0,0,0,0,0,0
endlayer

layer
0,0,0,0,0,0,0,0,0,0,0,0,0,0,0
0,0,0,0,0,0,0,0,0,0,0,0,0,0,0
0,0,6,12,13,13,12,13,12,13,13,12,6,0,0
0,0,12,0,0,0,0,0,0,0,0,0,12,0,0
0,0,13,0,8,0,0,8,0,0,8,0,13,0,0
0,0,13,0,8,11,11,8,11,11,8,0,13,0,0
0,0,12,0,8,0,0,8,0,0,8,0,12,0,0
0,0,13,0,0,0,0,0,0,0,0,0,13,0,0
0,0,12,0,8,0,0,8,0,0,8,0,12,0,0
0,0,13,0,8,11,11,8,11,11,8,0,13,0,0
0,0,13,0,8,0,0,8,0,0,8,0,13,0,0
0,0,12,0,0,0,0,0,0,0,0,0,12,0,0
0,0,6,12,13,13,12,13,12,13,13,12,6,0,0
0,0,0,0,0,0,0,0,0,0,0,0,0,0,0
0,0,0,0,0,0,0,0,0,0,0,0,0,0,0
endlayer

layer
0,0,0,0,0,0,0,0,0,0,0,0,0,0,0
0,0,0,0,0,0,0,0,0,0,0,0,0,0,0
0,0,6,12,13,13,12,13,12,13,13,12,6,0,0
0,0,12,0,0,0,0,0,0,0,0,0,12,0,0
0,0,13,0,0,0,0,0,0,0,0,0,13,0,0
0,0,13,0,0,0,0,0,0,0,0,0,13,0,0
0,0,12,0,0,0,0,0,0,0,0,0,12,0,0
0,0,13,0,0,0,0,0,0,0,0,0,13,0,0
0,0,12,0,0,0,0,0,0,0,0,0,12,0,0
0,0,13,0,0,0,0,0,0,0,0,0,13,0,0
0,0,13,0,0,0,0,0,0,0,0,0,13,0,0
0,0,12,0,0,0,0,0,0,0,0,0,12,0,0
0,0,6,12,13,13,12,13,12,13,13,12,6,0,0
0,0,0,0,0,0,0,0,0,0,0,0,0,0,0
0,0,0,0,0,0,0,0,0,0,0,0,0,0,0
endlayer

layer
0,0,0,0,0,0,0,0,0,0,0,0,0,0,0
0,0,0,0,0,0,0,0,0,0,0,0,0,0,0
0,0,6,12,13,13,12,13,12,13,13,12,6,0,0
0,0,12,0,0,0,0,0,0,0,0,0,12,0,0
0,0,13,0,0,0,0,0,0,0,0,0,13,0,0
0,0,13,0,0,0,0,0,0,0,0,0,13,0,0
0,0,12,0,0,0,0,0,0,0,0,0,12,0,0
0,0,13,0,0,0,0,0,0,0,0,0,13,0,0
0,0,12,0,0,0,0,0,0,0,0,0,12,0,0
0,0,13,0,0,0,0,0,0,0,0,0,13,0,0
0,0,13,0,0,0,0,0,0,0,0,0,13,0,0
0,0,12,0,0,0,0,0,0,0,0,0,12,0,0
0,0,6,12,13,13,12,13,12,13,13,12,6,0,0
0,0,0,0,0,0,0,0,0,0,0,0,0,0,0
0,0,0,0,0,0,0,0,0,0,0,0,0,0,0
endlayer

layer
0,0,0,0,0,0,0,0,0,0,0,0,0,0,0
0,0,0,0,0,0,0,0,0,0,0,0,0,0,0
0,0,6,12,13,13,12,13,12,13,13,12,6,0,0
0,0,12,0,0,0,0,0,0,0,0,0,12,0,0
0,0,13,0,0,0,0,0,0,0,0,0,13,0,0
0,0,13,0,0,0,0,0,0,0,0,0,13,0,0
0,0,12,0,0,0,0,0,0,0,0,0,12,0,0
0,0,13,0,0,0,0,0,0,0,0,0,13,0,0
0,0,12,0,0,0,0,0,0,0,0,0,12,0,0
0,0,13,0,0,0,0,0,0,0,0,0,13,0,0
0,0,13,0,0,0,0,0,0,0,0,0,13,0,0
0,0,12,0,0,0,0,0,0,0,0,0,12,0,0
0,0,6,12,13,13,12,13,12,13,13,12,6,0,0
0,0,0,0,0,0,0,0,0,0,0,0,0,0,0
0,0,0,0,0,0,0,0,0,0,0,0,0,0,0
endlayer

layer
0,0,0,0,0,0,0,0,0,0,0,0,0,0,0
0,0,0,0,0,0,0,0,0,0,0,0,0,0,0
0,0,6,6,6,6,6,6,6,6,6,6,6,0,0
0,0,6,15,15,15,15,15,15,15,15,15,6,0,0
0,0,6,15,15,15,15,15,15,15,15,15,6,0,0
0,0,6,15,15,15,15,15,15,15,15,15,6,0,0
0,0,6,15,15,15,15,15,15,15,15,15,6,0,0
0,0,6,15,15,15,15,15,15,15,15,15,6,0,0
0,0,6,15,15,15,15,15,15,15,15,15,6,0,0
0,0,6,15,15,15,15,15,15,15,15,15,6,0,0
0,0,6,15,15,15,15,15,15,15,15,15,6,0,0
0,0,6,15,15,15,15,15,15,15,15,15,6,0,0
0,0,6,6,6,6,6,6,6,6,6,6,6,0,0
0,0,0,0,0,0,0,0,0,0,0,0,0,0,0
0,0,0,0,0,0,0,0,0,0,0,0,0,0,0
endlayer

