# Converted from schematic
# THIS TEMPLATE USES DEFAULTS!  Please edit for corrections.
# If you need help, consult template_rules.txt

weight=1
embed_into_distance=41
acceptable_target_blocks=1,2,3,12,13,250
dimensions=56,31,21
allowable_overhang=0
max_cut_in=2
cut_in_buffer=1
max_leveling=2
leveling_buffer=1
preserve_water=0
preserve_lava=0
preserve_plants=0


rule1=0,100,250
rule2=0,100,2799-7
rule3=0,100,11
rule4=0,100,0
rule5=0,100,0
rule6=0,100,0
rule7=0,100,3134-10
rule8=0,100,1476-3
rule9=0,100,159-14
rule10=0,100,3123-1
rule11=0,100,2762-10
rule12=0,100,2764-11
rule13=0,100,17
rule14=0,100,2799-8
rule15=0,100,2802-8
rule16=0,100,2802-9
rule17=0,100,17-4
rule18=0,100,17-8


layer
1,1,1,1,1,1,1,1,1,1,1,1,1,1,1,1,1,1,1,1,1
1,1,1,1,1,1,1,1,1,1,1,1,1,1,1,1,1,1,1,1,1
1,1,1,1,1,1,1,1,1,1,1,1,1,1,1,1,1,1,1,1,1
1,1,1,1,1,1,1,1,1,1,1,1,1,1,1,1,1,1,1,1,1
1,1,1,1,1,1,1,1,1,1,1,1,1,1,1,1,1,1,1,1,1
1,1,1,1,1,1,1,1,1,1,1,1,1,1,1,1,1,1,1,1,1
1,1,1,1,1,1,1,1,1,1,1,1,1,1,1,1,1,1,1,1,1
1,1,1,1,1,1,1,1,1,1,1,1,1,1,1,1,1,1,1,1,1
1,1,1,1,1,1,1,1,1,1,1,1,1,1,1,1,1,1,1,1,1
1,1,1,1,1,1,1,1,1,1,1,1,1,1,1,1,1,1,1,1,1
1,1,1,1,1,1,1,1,1,1,1,1,1,1,1,1,1,1,1,1,1
1,1,1,1,1,1,1,1,1,1,1,1,1,1,1,1,1,1,1,1,1
1,1,1,1,1,1,1,1,1,1,1,1,1,1,1,1,1,1,1,1,1
1,1,1,1,1,1,1,1,1,1,1,1,1,1,1,1,1,1,1,1,1
1,1,1,1,1,1,1,1,1,1,1,1,1,1,1,1,1,1,1,1,1
1,1,1,2,2,2,2,0,0,3,3,3,0,0,0,0,2,2,1,1,1
1,1,1,2,2,0,0,0,3,3,3,3,3,0,0,0,0,2,1,1,1
1,1,1,2,2,2,0,3,3,3,3,3,3,3,0,0,0,0,1,1,1
1,1,1,2,2,0,3,3,3,3,3,3,3,3,3,0,0,0,1,1,1
1,1,1,0,0,3,3,3,3,3,3,3,3,3,3,3,0,0,1,1,1
1,1,1,0,3,3,3,3,3,3,3,3,3,3,3,3,3,0,1,1,1
1,1,1,3,3,3,3,3,3,3,3,3,3,3,3,3,3,3,1,1,1
1,1,1,3,3,3,3,3,3,3,3,3,3,3,3,3,3,3,1,1,1
1,1,1,0,3,3,3,3,3,3,3,3,3,3,3,3,3,3,1,1,1
1,1,1,0,3,3,3,3,3,3,3,3,3,3,3,3,3,0,1,1,1
1,1,1,0,0,3,3,3,3,3,3,3,3,3,3,3,0,0,1,1,1
1,1,1,0,0,0,3,3,3,3,3,3,3,3,3,0,0,2,1,1,1
1,1,1,2,0,0,0,3,3,3,3,3,3,3,0,0,0,2,1,1,1
1,1,1,0,0,0,0,0,3,3,3,3,3,0,0,0,2,2,1,1,1
1,1,1,0,0,0,0,0,0,3,3,3,0,0,0,0,2,2,1,1,1
1,1,1,1,1,1,1,1,1,1,1,1,1,1,1,1,1,1,1,1,1
endlayer

layer
1,1,1,1,1,1,1,1,1,1,1,1,1,1,1,1,1,1,1,1,1
1,1,1,1,1,1,1,1,1,1,1,1,1,1,1,1,1,1,1,1,1
1,1,1,1,1,1,1,1,1,1,1,1,1,1,1,1,1,1,1,1,1
1,1,1,1,1,1,1,1,1,1,1,1,1,1,1,1,1,1,1,1,1
1,1,1,1,1,1,1,1,1,1,1,1,1,1,1,1,1,1,1,1,1
1,1,1,1,1,1,1,1,1,1,1,1,1,1,1,1,1,1,1,1,1
1,1,1,1,1,1,1,1,1,1,1,1,1,1,1,1,1,1,1,1,1
1,1,1,1,1,1,1,1,1,1,1,1,1,1,1,1,1,1,1,1,1
1,1,1,1,1,1,1,1,1,1,1,1,1,1,1,1,1,1,1,1,1
1,1,1,1,1,1,1,1,1,1,1,1,1,1,1,1,1,1,1,1,1
1,1,1,1,1,1,1,1,1,1,1,1,1,1,1,1,1,1,1,1,1
1,1,1,1,1,1,1,1,1,1,1,1,1,1,1,1,1,1,1,1,1
1,1,1,1,1,1,1,1,1,1,1,1,1,1,1,1,1,1,1,1,1
1,1,1,1,1,1,1,1,1,1,1,1,1,1,1,1,1,1,1,1,1
1,1,1,1,1,1,1,1,1,1,1,1,1,1,1,1,1,1,1,1,1
1,1,1,2,0,0,0,0,0,0,0,0,0,0,0,0,0,2,1,1,1
1,1,1,2,2,0,0,0,0,0,0,0,0,0,0,0,0,0,1,1,1
1,1,1,2,0,0,0,0,0,0,0,0,0,0,0,0,0,0,1,1,1
1,1,1,0,0,0,0,0,0,0,0,0,0,0,0,0,0,0,1,1,1
1,1,1,0,0,0,0,0,0,0,0,0,0,0,0,0,0,0,1,1,1
1,1,1,0,0,0,0,0,0,0,0,0,0,0,0,0,0,0,1,1,1
1,1,1,0,0,0,0,0,0,0,0,0,0,0,0,0,0,0,1,1,1
1,1,1,0,0,0,0,0,0,0,0,0,0,0,0,0,0,0,1,1,1
1,1,1,0,0,0,0,0,0,0,0,0,0,0,0,0,0,0,1,1,1
1,1,1,0,0,0,0,0,0,0,0,0,0,0,0,0,0,0,1,1,1
1,1,1,0,0,0,0,0,0,0,0,0,0,0,0,0,0,0,1,1,1
1,1,1,0,0,0,0,0,0,0,0,0,0,0,0,0,0,0,1,1,1
1,1,1,0,0,0,0,0,0,0,0,0,0,0,0,0,0,0,1,1,1
1,1,1,0,0,0,0,0,0,0,0,0,0,0,0,0,0,2,1,1,1
1,1,1,0,0,0,0,0,0,0,0,0,0,0,0,0,0,2,1,1,1
1,1,1,1,1,1,1,1,1,1,1,1,1,1,1,1,1,1,1,1,1
endlayer

layer
1,1,1,1,1,1,1,1,1,1,1,1,1,1,1,1,1,1,1,1,1
1,1,1,1,1,1,1,1,1,1,1,1,1,1,1,1,1,1,1,1,1
1,1,1,1,1,1,1,1,1,1,1,1,1,1,1,1,1,1,1,1,1
1,1,1,1,1,1,1,1,1,1,1,1,1,1,1,1,1,1,1,1,1
1,1,1,1,1,1,1,1,1,1,1,1,1,1,1,1,1,1,1,1,1
1,1,1,1,1,1,1,1,1,1,1,1,1,1,1,1,1,1,1,1,1
1,1,1,1,1,1,1,1,1,1,1,1,1,1,1,1,1,1,1,1,1
1,1,1,1,1,1,1,1,1,1,1,1,1,1,1,1,1,1,1,1,1
1,1,1,1,1,1,1,1,1,1,1,1,1,1,1,1,1,1,1,1,1
1,1,1,1,1,1,1,1,1,1,1,1,1,1,1,1,1,1,1,1,1
1,1,1,1,1,1,1,1,1,1,1,1,1,1,1,1,1,1,1,1,1
1,1,1,1,1,1,1,1,1,1,1,1,1,1,1,1,1,1,1,1,1
1,1,1,1,1,1,1,1,1,1,1,1,1,1,1,1,1,1,1,1,1
1,1,1,1,1,1,1,1,1,1,1,1,1,1,1,1,1,1,1,1,1
1,1,1,1,1,1,1,1,1,1,1,1,1,1,1,1,1,1,1,1,1
1,1,1,0,0,0,0,0,0,0,0,0,0,0,0,0,0,2,1,1,1
1,1,1,0,0,0,0,0,0,0,0,0,0,0,0,0,0,0,1,1,1
1,1,1,0,0,0,0,0,0,0,0,0,0,0,0,0,0,0,1,1,1
1,1,1,0,0,0,0,0,0,0,0,0,0,0,0,0,0,0,1,1,1
1,1,1,0,0,0,0,0,0,0,0,0,0,0,0,0,0,0,1,1,1
1,1,1,0,0,0,0,0,0,0,0,0,0,0,0,0,0,0,1,1,1
1,1,1,0,0,0,0,0,0,0,0,0,0,0,0,0,0,0,1,1,1
1,1,1,0,0,0,0,0,0,0,0,0,0,0,0,0,0,0,1,1,1
1,1,1,0,0,0,0,0,0,0,0,0,0,0,0,0,0,0,1,1,1
1,1,1,0,0,0,0,0,0,0,0,0,0,0,0,0,0,0,1,1,1
1,1,1,0,0,0,0,0,0,0,0,0,0,0,0,0,0,0,1,1,1
1,1,1,0,0,0,0,0,0,0,0,0,0,0,0,0,0,0,1,1,1
1,1,1,0,0,0,0,0,0,0,0,0,0,0,0,0,0,0,1,1,1
1,1,1,0,0,0,0,0,0,0,0,0,0,0,0,0,0,2,1,1,1
1,1,1,0,0,0,0,0,0,0,0,0,0,0,0,0,0,2,1,1,1
1,1,1,1,1,1,1,1,1,1,1,1,1,1,1,1,1,1,1,1,1
endlayer

layer
1,1,1,1,1,1,1,1,1,1,1,1,1,1,1,1,1,1,1,1,1
1,1,1,1,1,1,1,1,1,1,1,1,1,1,1,1,1,1,1,1,1
1,1,1,1,1,1,1,1,1,1,1,1,1,1,1,1,1,1,1,1,1
1,1,1,1,1,1,1,1,1,1,1,1,1,1,1,1,1,1,1,1,1
1,1,1,1,1,1,1,1,1,1,1,1,1,1,1,1,1,1,1,1,1
1,1,1,1,1,1,1,1,1,1,1,1,1,1,1,1,1,1,1,1,1
1,1,1,1,1,1,1,1,1,1,1,1,1,1,1,1,1,1,1,1,1
1,1,1,1,1,1,1,1,1,1,1,1,1,1,1,1,1,1,1,1,1
1,1,1,1,1,1,1,1,1,1,1,1,1,1,1,1,1,1,1,1,1
1,1,1,1,1,1,1,1,1,1,1,1,1,1,1,1,1,1,1,1,1
1,1,1,1,1,1,1,1,1,1,1,1,1,1,1,1,1,1,1,1,1
1,1,1,1,1,1,1,1,1,1,1,1,1,1,1,1,1,1,1,1,1
1,1,1,1,1,1,1,1,1,1,1,1,1,1,1,1,1,1,1,1,1
1,1,1,1,1,1,1,1,1,1,1,1,1,1,1,1,1,1,1,1,1
1,1,1,1,1,1,1,1,1,1,1,1,1,1,1,1,1,1,1,1,1
1,1,1,0,0,0,0,0,0,0,0,0,0,0,0,0,0,0,1,1,1
1,1,1,0,0,0,0,0,0,0,0,0,0,0,0,0,0,0,1,1,1
1,1,1,0,0,0,0,0,0,0,0,0,0,0,0,0,0,0,1,1,1
1,1,1,0,0,0,0,0,0,0,0,0,0,0,0,0,0,0,1,1,1
1,1,1,0,0,0,0,0,0,0,0,0,0,0,0,0,0,0,1,1,1
1,1,1,0,0,0,0,0,0,0,0,0,0,0,0,0,0,0,1,1,1
1,1,1,0,0,0,0,0,0,0,0,0,0,0,0,0,0,0,1,1,1
1,1,1,0,0,0,0,0,0,0,0,0,0,0,0,0,0,0,1,1,1
1,1,1,0,0,0,0,0,0,0,0,0,0,0,0,0,0,0,1,1,1
1,1,1,0,0,0,0,0,0,0,0,0,0,0,0,0,0,0,1,1,1
1,1,1,0,0,0,0,0,0,0,0,0,0,0,0,0,0,0,1,1,1
1,1,1,0,0,0,0,0,0,0,0,0,0,0,0,0,0,0,1,1,1
1,1,1,0,0,0,0,0,0,0,0,0,0,0,0,0,0,0,1,1,1
1,1,1,0,0,0,0,0,0,0,0,0,0,0,0,0,0,0,1,1,1
1,1,1,0,0,0,0,0,0,0,0,0,0,0,0,0,0,0,1,1,1
1,1,1,1,1,1,1,1,1,1,1,1,1,1,1,1,1,1,1,1,1
endlayer

layer
1,1,1,1,1,1,1,1,1,1,1,1,1,1,1,1,1,1,1,1,1
1,1,1,1,1,1,1,1,1,1,1,1,1,1,1,1,1,1,1,1,1
1,1,1,1,1,1,1,1,1,1,1,1,1,1,1,1,1,1,1,1,1
1,1,1,1,1,1,1,1,1,1,1,1,1,1,1,1,1,1,1,1,1
1,1,1,1,1,1,1,1,1,1,1,1,1,1,1,1,1,1,1,1,1
1,1,1,1,1,1,1,1,1,1,1,1,1,1,1,1,1,1,1,1,1
1,1,1,1,1,1,1,1,1,1,1,1,1,1,1,1,1,1,1,1,1
1,1,1,1,1,1,1,1,1,1,1,1,1,1,1,1,1,1,1,1,1
1,1,1,1,1,1,1,1,1,1,1,1,1,1,1,1,1,1,1,1,1
1,1,1,1,1,1,1,1,1,1,1,1,1,1,1,1,1,1,1,1,1
1,1,1,1,1,1,1,1,1,1,1,1,1,1,1,1,1,1,1,1,1
1,1,1,1,1,1,1,1,1,1,1,1,1,1,1,1,1,1,1,1,1
1,1,1,1,1,1,1,1,1,1,1,1,1,1,1,1,1,1,1,1,1
1,1,1,1,1,1,1,1,1,1,1,1,1,1,1,1,1,1,1,1,1
1,1,1,1,1,1,1,1,1,1,1,1,1,1,1,1,1,1,1,1,1
1,1,1,0,0,0,0,0,0,0,0,0,0,0,0,0,0,0,1,1,1
1,1,1,0,0,0,0,0,0,0,0,0,0,0,0,0,0,0,1,1,1
1,1,1,0,0,0,0,0,0,0,0,0,0,0,0,0,0,0,1,1,1
1,1,1,0,0,0,0,0,0,0,0,0,0,0,0,0,0,0,1,1,1
1,1,1,0,0,0,0,0,0,0,0,0,0,0,0,0,0,0,1,1,1
1,1,1,0,0,0,0,0,0,0,0,0,0,0,0,0,0,0,1,1,1
1,1,1,0,0,0,0,0,0,0,0,0,0,0,0,0,0,0,1,1,1
1,1,1,0,0,0,0,0,0,0,0,0,0,0,0,0,0,0,1,1,1
1,1,1,0,0,0,0,0,0,0,0,0,0,0,0,0,0,0,1,1,1
1,1,1,0,0,0,0,0,0,0,0,0,0,0,0,0,0,0,1,1,1
1,1,1,0,0,0,0,0,0,0,0,0,0,0,0,0,0,0,1,1,1
1,1,1,0,0,0,0,0,0,0,0,0,0,0,0,0,0,0,1,1,1
1,1,1,0,0,0,0,0,0,0,0,0,0,0,0,0,0,0,1,1,1
1,1,1,0,0,0,0,0,0,0,0,0,0,0,0,0,0,0,1,1,1
1,1,1,0,0,0,0,0,0,0,0,0,0,0,0,0,0,0,1,1,1
1,1,1,1,1,1,1,1,1,1,1,1,1,1,1,1,1,1,1,1,1
endlayer

layer
1,1,1,1,1,1,1,1,1,1,1,1,1,1,1,1,1,1,1,1,1
1,1,1,1,1,1,1,1,1,1,1,1,1,1,1,1,1,1,1,1,1
1,1,1,1,1,1,1,1,1,1,1,1,1,1,1,1,1,1,1,1,1
1,1,1,1,1,1,1,1,1,1,1,1,1,1,1,1,1,1,1,1,1
1,1,1,1,1,1,1,1,1,1,1,1,1,1,1,1,1,1,1,1,1
1,1,1,1,1,1,1,1,1,1,1,1,1,1,1,1,1,1,1,1,1
1,1,1,1,1,1,1,1,1,1,1,1,1,1,1,1,1,1,1,1,1
1,1,1,1,1,1,1,1,1,1,1,1,1,1,1,1,1,1,1,1,1
1,1,1,1,1,1,1,1,1,1,1,1,1,1,1,1,1,1,1,1,1
1,1,1,1,1,1,1,1,1,1,1,1,1,1,1,1,1,1,1,1,1
1,1,1,1,1,1,1,1,1,1,1,1,1,1,1,1,1,1,1,1,1
1,1,1,1,1,1,1,1,1,1,1,1,1,1,1,1,1,1,1,1,1
1,1,1,1,1,1,1,1,1,1,1,1,1,1,1,1,1,1,1,1,1
1,1,1,1,1,1,1,1,1,1,1,1,1,1,1,1,1,1,1,1,1
1,1,1,1,1,1,1,1,1,1,1,1,1,1,1,1,1,1,1,1,1
1,1,1,0,0,0,0,0,0,0,0,0,0,0,0,0,0,0,1,1,1
1,1,1,0,0,0,0,0,0,0,0,0,0,0,0,0,0,0,1,1,1
1,1,1,0,0,0,0,0,0,0,0,0,0,0,0,0,0,0,1,1,1
1,1,1,0,0,0,0,0,0,0,0,0,0,0,0,0,0,0,1,1,1
1,1,1,0,0,0,0,0,0,0,0,0,0,0,0,0,0,0,1,1,1
1,1,1,0,0,0,0,0,0,0,0,0,0,0,0,0,0,0,1,1,1
1,1,1,0,0,0,0,0,0,0,0,0,0,0,0,0,0,0,1,1,1
1,1,1,0,0,0,0,0,0,0,0,0,0,0,0,0,0,0,1,1,1
1,1,1,0,0,0,0,0,0,0,0,0,0,0,0,0,0,0,1,1,1
1,1,1,0,0,0,0,0,0,0,0,0,0,0,0,0,0,0,1,1,1
1,1,1,0,0,0,0,0,0,0,0,0,0,0,0,0,0,0,1,1,1
1,1,1,0,0,0,0,0,0,0,0,0,0,0,0,0,0,0,1,1,1
1,1,1,0,0,0,0,0,0,0,0,0,0,0,0,0,0,2,1,1,1
1,1,1,0,0,0,0,0,0,0,0,0,0,0,0,0,2,2,1,1,1
1,1,1,0,0,0,0,0,0,0,0,0,0,0,2,2,2,0,1,1,1
1,1,1,1,1,1,1,1,1,1,1,1,1,1,1,1,1,1,1,1,1
endlayer

layer
1,1,1,1,1,1,1,1,1,1,1,1,1,1,1,1,1,1,1,1,1
1,1,1,1,1,1,1,1,1,1,1,1,1,1,1,1,1,1,1,1,1
1,1,1,1,1,1,1,1,1,1,1,1,1,1,1,1,1,1,1,1,1
1,1,1,1,1,1,1,1,1,1,1,1,1,1,1,1,1,1,1,1,1
1,1,1,1,1,1,1,1,1,1,1,1,1,1,1,1,1,1,1,1,1
1,1,1,1,1,1,1,1,1,1,1,1,1,1,1,1,1,1,1,1,1
1,1,1,1,1,1,1,1,1,1,1,1,1,1,1,1,1,1,1,1,1
1,1,1,1,1,1,1,1,1,1,1,1,1,1,1,1,1,1,1,1,1
1,1,1,1,1,1,1,1,1,1,1,1,1,1,1,1,1,1,1,1,1
1,1,1,1,1,1,1,1,1,1,1,1,1,1,1,1,1,1,1,1,1
1,1,1,1,1,1,1,1,1,1,1,1,1,1,1,1,1,1,1,1,1
1,1,1,1,1,1,1,1,1,1,1,1,1,1,1,1,1,1,1,1,1
1,1,1,1,1,1,1,1,1,1,1,1,1,1,1,1,1,1,1,1,1
1,1,1,1,1,1,1,1,1,1,1,1,1,1,1,1,1,1,1,1,1
1,1,1,1,1,1,1,1,1,1,1,1,1,1,1,1,1,1,1,1,1
1,1,1,0,0,0,0,0,0,0,0,0,0,0,0,0,0,0,1,1,1
1,1,1,0,0,0,0,0,0,0,0,0,0,2,0,0,0,0,1,1,1
1,1,1,0,0,0,0,0,0,0,0,0,0,0,0,0,0,0,1,1,1
1,1,1,0,0,0,0,0,0,0,0,0,0,0,0,0,0,0,1,1,1
1,1,1,0,0,0,0,0,0,0,0,0,0,0,0,0,0,0,1,1,1
1,1,1,0,0,0,0,0,0,0,0,0,0,0,0,0,0,0,1,1,1
1,1,1,0,0,0,0,0,0,0,0,0,0,0,0,0,0,0,1,1,1
1,1,1,0,0,0,0,0,0,0,0,0,0,0,0,0,0,0,1,1,1
1,1,1,0,0,0,0,0,0,0,0,0,0,0,0,0,0,2,1,1,1
1,1,1,0,0,0,0,0,0,0,0,0,0,0,0,0,0,2,1,1,1
1,1,1,0,0,0,0,0,0,0,0,0,0,0,0,0,0,2,1,1,1
1,1,1,0,0,0,0,0,0,0,0,0,0,0,0,0,0,0,1,1,1
1,1,1,0,0,0,0,0,0,0,0,0,0,0,0,0,0,2,1,1,1
1,1,1,2,0,0,0,0,0,0,0,0,0,0,0,2,2,2,1,1,1
1,1,1,2,2,0,0,0,0,0,0,0,0,0,2,2,2,2,1,1,1
1,1,1,1,1,1,1,1,1,1,1,1,1,1,1,1,1,1,1,1,1
endlayer

layer
1,1,1,1,1,1,1,1,1,1,1,1,1,1,1,1,1,1,1,1,1
1,1,1,1,1,1,1,1,1,1,1,1,1,1,1,1,1,1,1,1,1
1,1,1,1,1,1,1,1,1,1,1,1,1,1,1,1,1,1,1,1,1
1,1,1,1,1,1,1,1,1,1,1,1,1,1,1,1,1,1,1,1,1
1,1,1,1,1,1,1,1,1,1,1,1,1,1,1,1,1,1,1,1,1
1,1,1,1,1,1,1,1,1,1,1,1,1,1,1,1,1,1,1,1,1
1,1,1,1,1,1,1,1,1,1,1,1,1,1,1,1,1,1,1,1,1
1,1,1,1,1,1,1,1,1,1,1,1,1,1,1,1,1,1,1,1,1
1,1,1,1,1,1,1,1,1,1,1,1,1,1,1,1,1,1,1,1,1
1,1,1,1,1,1,1,1,1,1,1,1,1,1,1,1,1,1,1,1,1
1,1,1,1,1,1,1,1,1,1,1,1,1,1,1,1,1,1,1,1,1
1,1,1,1,1,1,1,1,1,1,1,1,1,1,1,1,1,1,1,1,1
1,1,1,1,1,1,1,1,1,1,1,1,1,1,1,1,1,1,1,1,1
1,1,1,1,1,1,1,1,1,1,1,1,1,1,1,1,1,1,1,1,1
1,1,1,1,1,1,1,1,1,1,1,1,1,1,1,1,1,1,1,1,1
1,1,1,2,2,0,0,0,0,0,0,0,0,0,0,0,0,0,1,1,1
1,1,1,0,2,0,0,0,0,0,0,0,2,0,0,0,0,0,1,1,1
1,1,1,2,0,0,0,0,0,0,0,0,0,0,0,0,0,0,1,1,1
1,1,1,0,0,0,0,0,0,0,0,0,0,0,0,0,0,0,1,1,1
1,1,1,0,0,0,0,0,0,0,0,0,0,0,0,0,0,0,1,1,1
1,1,1,0,0,0,0,0,0,0,0,0,0,0,0,0,0,0,1,1,1
1,1,1,0,0,0,0,0,0,0,0,0,0,0,0,0,0,0,1,1,1
1,1,1,0,0,0,0,0,0,0,0,0,0,0,0,0,0,0,1,1,1
1,1,1,0,0,0,0,0,0,0,0,0,0,0,0,0,0,0,1,1,1
1,1,1,0,0,0,0,0,0,0,0,0,0,0,0,0,0,2,1,1,1
1,1,1,0,0,0,0,0,0,0,0,0,0,0,0,0,0,0,1,1,1
1,1,1,2,0,0,0,0,0,0,0,0,0,0,0,0,0,2,1,1,1
1,1,1,0,0,0,0,0,0,0,0,0,0,0,0,0,2,2,1,1,1
1,1,1,0,0,0,0,0,0,0,0,0,0,0,2,2,2,2,1,1,1
1,1,1,2,2,2,0,0,0,0,0,0,0,2,2,2,2,2,1,1,1
1,1,1,1,1,1,1,1,1,1,1,1,1,1,1,1,1,1,1,1,1
endlayer

layer
1,1,1,1,1,1,1,1,1,1,1,1,1,1,1,1,1,1,1,1,1
1,1,1,1,1,1,1,1,1,1,1,1,1,1,1,1,1,1,1,1,1
1,1,1,1,1,1,1,1,1,1,1,1,1,1,1,1,1,1,1,1,1
1,1,1,1,1,1,1,1,1,1,1,1,1,1,1,1,1,1,1,1,1
1,1,1,1,1,1,1,1,1,1,1,1,1,1,1,1,1,1,1,1,1
1,1,1,1,1,1,1,1,1,1,1,1,1,1,1,1,1,1,1,1,1
1,1,1,1,1,1,1,1,1,1,1,1,1,1,1,1,1,1,1,1,1
1,1,1,1,1,1,1,1,1,1,1,1,1,1,1,1,1,1,1,1,1
1,1,1,1,1,1,1,1,1,1,1,1,1,1,1,1,1,1,1,1,1
1,1,1,1,1,1,1,1,1,1,1,1,1,1,1,1,1,1,1,1,1
1,1,1,1,1,1,1,1,1,1,1,1,1,1,1,1,1,1,1,1,1
1,1,1,1,1,1,1,1,1,1,1,1,1,1,1,1,1,1,1,1,1
1,1,1,1,1,1,1,1,1,1,1,1,1,1,1,1,1,1,1,1,1
1,1,1,1,1,1,1,1,1,1,1,1,1,1,1,1,1,1,1,1,1
1,1,1,1,1,1,1,1,1,1,1,1,1,1,1,1,1,1,1,1,1
1,1,1,2,2,0,0,0,0,0,0,0,0,0,0,0,0,0,1,1,1
1,1,1,2,2,0,0,0,0,0,0,0,0,0,0,0,0,0,1,1,1
1,1,1,0,0,0,0,0,0,0,0,0,0,0,0,0,0,0,1,1,1
1,1,1,0,0,0,0,0,0,0,0,0,0,0,0,0,0,0,1,1,1
1,1,1,0,0,0,0,0,0,0,0,0,0,0,0,0,0,0,1,1,1
1,1,1,0,0,0,0,0,0,0,0,0,0,0,0,0,0,2,1,1,1
1,1,1,0,0,0,0,0,0,0,0,0,0,0,0,0,0,2,1,1,1
1,1,1,0,0,0,0,0,0,0,0,0,0,0,0,0,0,2,1,1,1
1,1,1,0,0,0,0,0,0,0,0,0,0,0,0,0,0,2,1,1,1
1,1,1,0,0,0,0,0,0,0,0,0,0,0,0,0,0,0,1,1,1
1,1,1,0,0,0,0,0,0,0,0,0,0,0,0,0,0,0,1,1,1
1,1,1,0,0,0,0,0,0,0,0,0,0,0,0,0,0,2,1,1,1
1,1,1,0,0,0,0,0,0,0,0,0,0,0,0,0,0,2,1,1,1
1,1,1,0,0,0,0,0,0,0,0,0,0,0,0,0,2,2,1,1,1
1,1,1,0,0,0,0,0,0,0,0,0,0,0,2,2,2,2,1,1,1
1,1,1,1,1,1,1,1,1,1,1,1,1,1,1,1,1,1,1,1,1
endlayer

layer
1,1,1,1,1,1,1,1,1,1,1,1,1,1,1,1,1,1,1,1,1
1,1,1,1,1,1,1,1,1,1,1,1,1,1,1,1,1,1,1,1,1
1,1,1,1,1,1,1,1,1,1,1,1,1,1,1,1,1,1,1,1,1
1,1,1,1,1,1,1,1,1,1,1,1,1,1,1,1,1,1,1,1,1
1,1,1,1,1,1,1,1,1,1,1,1,1,1,1,1,1,1,1,1,1
1,1,1,1,1,1,1,1,1,1,1,1,1,1,1,1,1,1,1,1,1
1,1,1,1,1,1,1,1,1,1,1,1,1,1,1,1,1,1,1,1,1
1,1,1,1,1,1,1,1,1,1,1,1,1,1,1,1,1,1,1,1,1
1,1,1,1,1,1,1,1,1,1,1,1,1,1,1,1,1,1,1,1,1
1,1,1,1,1,1,1,1,1,1,1,1,1,1,1,1,1,1,1,1,1
1,1,1,1,1,1,1,1,1,1,1,1,1,1,1,1,1,1,1,1,1
1,1,1,1,1,1,1,1,1,1,1,1,1,1,1,1,1,1,1,1,1
1,1,1,1,1,1,1,1,1,1,1,1,1,1,1,1,1,1,1,1,1
1,1,1,1,1,1,1,1,1,1,1,1,1,1,1,1,1,1,1,1,1
1,1,1,1,1,1,1,1,1,1,1,1,1,1,1,1,1,1,1,1,1
1,1,1,2,0,0,0,0,0,0,0,0,0,0,0,0,0,0,1,1,1
1,1,1,2,0,0,0,0,0,0,0,0,0,0,0,0,0,0,1,1,1
1,1,1,0,0,0,0,0,0,0,0,0,0,0,0,0,0,0,1,1,1
1,1,1,0,0,0,0,0,0,0,0,0,0,0,0,0,0,0,1,1,1
1,1,1,0,0,0,0,0,0,0,0,0,0,0,0,0,2,2,1,1,1
1,1,1,0,0,0,0,0,0,0,0,0,0,0,0,0,0,2,1,1,1
1,1,1,0,0,0,0,0,0,0,0,0,0,0,0,0,0,0,1,1,1
1,1,1,0,0,0,0,0,0,0,0,0,0,0,0,0,0,2,1,1,1
1,1,1,0,0,0,0,0,0,0,0,0,0,0,0,0,0,2,1,1,1
1,1,1,0,0,0,0,0,0,0,0,0,0,0,0,0,0,0,1,1,1
1,1,1,0,0,0,0,0,0,0,0,0,0,0,0,0,0,0,1,1,1
1,1,1,0,0,0,0,0,0,0,0,0,0,0,0,0,0,2,1,1,1
1,1,1,0,0,0,0,0,0,0,0,0,0,0,0,0,0,2,1,1,1
1,1,1,0,0,0,0,0,0,0,0,0,0,0,2,2,2,2,1,1,1
1,1,1,0,0,0,0,0,0,0,0,0,0,2,2,2,2,2,1,1,1
1,1,1,1,1,1,1,1,1,1,1,1,1,1,1,1,1,1,1,1,1
endlayer

layer
1,1,1,1,1,1,1,1,1,1,1,1,1,1,1,1,1,1,1,1,1
1,1,1,1,1,1,1,1,1,1,1,1,1,1,1,1,1,1,1,1,1
1,1,1,1,1,1,1,1,1,1,1,1,1,1,1,1,1,1,1,1,1
1,1,1,1,1,1,1,1,1,1,1,1,1,1,1,1,1,1,1,1,1
1,1,1,1,1,1,1,1,1,1,1,1,1,1,1,1,1,1,1,1,1
1,1,1,1,1,1,1,1,1,1,1,1,1,1,1,1,1,1,1,1,1
1,1,1,1,1,1,1,1,1,1,1,1,1,1,1,1,1,1,1,1,1
1,1,1,1,1,1,1,1,1,1,1,1,1,1,1,1,1,1,1,1,1
1,1,1,1,1,1,1,1,1,1,1,1,1,1,1,1,1,1,1,1,1
1,1,1,1,1,1,1,1,1,1,1,1,1,1,1,1,1,1,1,1,1
1,1,1,1,1,1,1,1,1,1,1,1,1,1,1,1,1,1,1,1,1
1,1,1,1,1,1,1,1,1,1,1,1,1,1,1,1,1,1,1,1,1
1,1,1,1,1,1,1,1,1,1,1,1,1,1,1,1,1,1,1,1,1
1,1,1,1,1,1,1,1,1,1,1,1,1,1,1,1,1,1,1,1,1
1,1,1,1,1,1,1,1,1,1,1,1,1,1,1,1,1,1,1,1,1
1,1,1,0,0,0,0,2,0,0,0,0,0,0,0,0,0,0,1,1,1
1,1,1,0,0,0,0,0,0,0,0,0,0,0,0,0,0,0,1,1,1
1,1,1,0,0,0,0,0,0,0,0,0,0,0,0,0,2,0,1,1,1
1,1,1,0,0,0,0,0,0,0,0,0,0,0,0,0,2,2,1,1,1
1,1,1,0,0,0,0,0,0,0,0,0,0,0,0,0,0,2,1,1,1
1,1,1,0,0,0,0,0,0,0,0,0,0,0,0,0,2,2,1,1,1
1,1,1,0,0,0,0,0,0,0,0,0,0,0,0,0,0,2,1,1,1
1,1,1,0,0,0,0,0,0,0,0,0,0,0,0,0,0,2,1,1,1
1,1,1,0,0,0,0,0,0,0,0,0,0,0,0,0,0,0,1,1,1
1,1,1,2,0,0,0,0,0,0,0,0,0,0,0,0,0,0,1,1,1
1,1,1,0,0,0,0,0,0,0,0,0,0,0,0,0,0,0,1,1,1
1,1,1,0,0,0,0,0,0,0,0,0,0,0,0,0,0,0,1,1,1
1,1,1,0,0,0,0,0,0,0,0,0,0,0,0,0,0,0,1,1,1
1,1,1,0,0,0,0,0,0,0,0,0,0,0,0,0,2,2,1,1,1
1,1,1,0,0,0,0,0,0,0,0,0,0,0,0,2,2,2,1,1,1
1,1,1,1,1,1,1,1,1,1,1,1,1,1,1,1,1,1,1,1,1
endlayer

layer
1,1,1,1,1,1,1,1,1,1,1,1,1,1,1,1,1,1,1,1,1
1,1,1,1,1,1,1,1,1,1,1,1,1,1,1,1,1,1,1,1,1
1,1,1,1,1,1,1,1,1,1,1,1,1,1,1,1,1,1,1,1,1
1,1,1,1,1,1,1,1,1,1,1,1,1,1,1,1,1,1,1,1,1
1,1,1,1,1,1,1,1,1,1,1,1,1,1,1,1,1,1,1,1,1
1,1,1,1,1,1,1,1,1,1,1,1,1,1,1,1,1,1,1,1,1
1,1,1,1,1,1,1,1,1,1,1,1,1,1,1,1,1,1,1,1,1
1,1,1,1,1,1,1,1,1,1,1,1,1,1,1,1,1,1,1,1,1
1,1,1,1,1,1,1,1,1,1,1,1,1,1,1,1,1,1,1,1,1
1,1,1,1,1,1,1,1,1,1,1,1,1,1,1,1,1,1,1,1,1
1,1,1,1,1,1,1,1,1,1,1,1,1,1,1,1,1,1,1,1,1
1,1,1,1,1,1,1,1,1,1,1,1,1,1,1,1,1,1,1,1,1
1,1,1,1,1,1,1,1,1,1,1,1,1,1,1,1,1,1,1,1,1
1,1,1,1,1,1,1,1,1,1,1,1,1,1,1,1,1,1,1,1,1
1,1,1,1,1,1,1,1,1,1,1,1,1,1,1,1,1,1,1,1,1
1,1,1,0,0,0,2,2,2,2,0,2,2,2,0,0,0,2,1,1,1
1,1,1,0,0,0,0,0,0,0,0,0,0,0,0,0,0,0,1,1,1
1,1,1,0,0,0,0,0,0,0,0,0,0,0,0,0,0,2,1,1,1
1,1,1,0,0,0,0,0,0,0,0,0,0,0,4,2,2,2,1,1,1
1,1,1,0,0,0,0,0,0,0,0,0,0,0,0,0,2,2,1,1,1
1,1,1,0,0,0,0,0,0,0,0,0,0,0,0,0,0,2,1,1,1
1,1,1,0,0,0,0,0,0,0,0,0,0,0,0,0,0,0,1,1,1
1,1,1,0,0,0,0,0,0,0,0,0,0,0,0,0,0,2,1,1,1
1,1,1,2,0,0,0,0,0,0,0,0,0,0,0,0,0,0,1,1,1
1,1,1,2,0,0,0,0,0,0,0,0,0,0,0,0,0,0,1,1,1
1,1,1,0,0,0,0,0,0,0,0,0,0,0,0,0,0,2,1,1,1
1,1,1,0,0,0,0,0,0,0,0,0,0,0,0,0,0,0,1,1,1
1,1,1,0,0,0,0,0,0,0,0,0,0,0,0,0,0,0,1,1,1
1,1,1,0,0,0,0,0,0,0,0,0,0,0,0,0,0,0,1,1,1
1,1,1,0,0,0,0,0,0,0,0,0,0,2,0,0,2,2,1,1,1
1,1,1,1,1,1,1,1,1,1,1,1,1,1,1,1,1,1,1,1,1
endlayer

layer
1,1,1,1,1,1,1,1,1,1,1,1,1,1,1,1,1,1,1,1,1
1,1,1,1,1,1,1,1,1,1,1,1,1,1,1,1,1,1,1,1,1
1,1,1,1,1,1,1,1,1,1,1,1,1,1,1,1,1,1,1,1,1
1,1,1,1,1,1,1,1,1,1,1,1,1,1,1,1,1,1,1,1,1
1,1,1,1,1,1,1,1,1,1,1,1,1,1,1,1,1,1,1,1,1
1,1,1,1,1,1,1,1,1,1,1,1,1,1,1,1,1,1,1,1,1
1,1,1,1,1,1,1,1,1,1,1,1,1,1,1,1,1,1,1,1,1
1,1,1,1,1,1,1,1,1,1,1,1,1,1,1,1,1,1,1,1,1
1,1,1,1,1,1,1,1,1,1,1,1,1,1,1,1,1,1,1,1,1
1,1,1,1,1,1,1,1,1,1,1,1,1,1,1,1,1,1,1,1,1
1,1,1,1,1,1,1,1,1,1,1,1,1,1,1,1,1,1,1,1,1
1,1,1,1,1,1,1,1,1,1,1,1,1,1,1,1,1,1,1,1,1
1,1,1,1,1,1,1,1,1,1,1,1,1,1,1,1,1,1,1,1,1
1,1,1,1,1,1,1,1,1,1,1,1,1,1,1,1,1,1,1,1,1
1,1,1,1,1,1,1,1,1,1,1,1,1,1,1,1,1,1,1,1,1
1,1,1,0,0,2,0,0,0,2,2,2,2,2,0,0,0,2,1,1,1
1,1,1,0,0,0,0,0,0,0,2,2,2,2,0,0,0,2,1,1,1
1,1,1,0,0,0,0,0,0,0,2,0,0,2,0,0,0,0,1,1,1
1,1,1,0,0,0,0,0,0,0,0,0,2,2,0,0,0,0,1,1,1
1,1,1,0,0,0,0,0,0,0,0,0,2,0,2,0,0,2,1,1,1
1,1,1,0,0,0,0,0,0,0,0,0,0,2,2,0,0,2,1,1,1
1,1,1,0,0,2,2,0,0,0,0,0,2,2,2,0,0,0,1,1,1
1,1,1,0,0,2,0,2,2,0,0,0,2,2,2,0,0,2,1,1,1
1,1,1,0,0,0,0,0,0,0,0,0,0,0,0,0,0,0,1,1,1
1,1,1,2,0,0,0,0,0,0,0,0,0,0,0,0,0,2,1,1,1
1,1,1,0,0,0,0,0,0,0,0,0,0,0,0,0,2,2,1,1,1
1,1,1,0,0,0,0,0,0,0,0,2,0,0,0,0,0,2,1,1,1
1,1,1,0,0,0,0,2,0,0,0,0,0,0,0,0,0,0,1,1,1
1,1,1,0,0,0,0,2,0,0,0,0,0,0,0,0,0,0,1,1,1
1,1,1,2,0,0,0,2,2,0,0,0,0,2,0,0,0,0,1,1,1
1,1,1,1,1,1,1,1,1,1,1,1,1,1,1,1,1,1,1,1,1
endlayer

layer
1,1,1,1,1,1,1,1,1,1,1,1,1,1,1,1,1,1,1,1,1
1,1,1,1,1,1,1,1,1,1,1,1,1,1,1,1,1,1,1,1,1
1,1,1,1,1,1,1,1,1,1,1,1,1,1,1,1,1,1,1,1,1
1,1,1,1,1,1,1,1,1,1,1,1,1,1,1,1,1,1,1,1,1
1,1,1,1,1,1,1,1,1,1,1,1,1,1,1,1,1,1,1,1,1
1,1,1,1,1,1,1,1,1,1,1,1,1,1,1,1,1,1,1,1,1
1,1,1,1,1,1,1,1,1,1,1,1,1,1,1,1,1,1,1,1,1
1,1,1,1,1,1,1,1,1,1,1,1,1,1,1,1,1,1,1,1,1
1,1,1,1,1,1,1,1,1,1,1,1,1,1,1,1,1,1,1,1,1
1,1,1,1,1,1,1,1,1,1,1,1,1,1,1,1,1,1,1,1,1
1,1,1,1,1,1,1,1,1,1,1,1,1,1,1,1,1,1,1,1,1
1,1,1,1,1,1,1,1,1,1,1,1,1,1,1,1,1,1,1,1,1
1,1,1,1,1,1,1,1,1,1,1,1,1,1,1,1,1,1,1,1,1
1,1,1,1,1,1,1,1,1,1,1,1,1,1,1,1,1,1,1,1,1
1,1,1,1,1,1,1,1,1,1,1,1,1,1,1,1,1,1,1,1,1
1,1,1,0,0,0,0,0,0,0,2,2,2,2,0,0,0,2,1,1,1
1,1,1,0,0,0,0,0,0,0,0,0,0,0,0,0,0,0,1,1,1
1,1,1,0,0,0,0,0,0,0,2,0,2,2,0,0,0,0,1,1,1
1,1,1,0,0,0,0,0,0,0,0,0,2,2,0,0,0,0,1,1,1
1,1,1,0,0,0,0,0,0,0,0,0,0,0,2,2,0,0,1,1,1
1,1,1,0,0,0,0,0,0,0,0,0,0,0,0,0,0,0,1,1,1
1,1,1,0,0,0,0,0,0,0,0,0,2,2,2,0,0,2,1,1,1
1,1,1,2,0,0,0,0,0,0,0,0,0,0,0,0,0,2,1,1,1
1,1,1,0,0,0,0,0,0,0,0,0,0,2,0,0,0,0,1,1,1
1,1,1,2,0,0,0,0,0,0,0,0,0,0,0,2,0,2,1,1,1
1,1,1,0,0,0,0,0,0,0,2,0,0,0,0,2,0,2,1,1,1
1,1,1,0,0,0,0,0,0,0,0,0,0,0,0,0,0,2,1,1,1
1,1,1,0,0,0,0,0,0,0,0,0,0,0,0,0,0,0,1,1,1
1,1,1,0,0,0,0,0,0,0,0,0,0,0,0,0,0,0,1,1,1
1,1,1,0,0,0,0,0,2,0,0,0,0,2,0,0,0,0,1,1,1
1,1,1,1,1,1,1,1,1,1,1,1,1,1,1,1,1,1,1,1,1
endlayer

layer
1,1,1,1,1,1,1,1,1,1,1,1,1,1,1,1,1,1,1,1,1
1,1,1,1,1,1,1,1,1,1,1,1,1,1,1,1,1,1,1,1,1
1,1,1,1,1,1,1,1,1,1,1,1,1,1,1,1,1,1,1,1,1
1,1,1,1,1,1,1,1,1,1,1,1,1,1,1,1,1,1,1,1,1
1,1,1,1,1,1,1,1,1,1,1,1,1,1,1,1,1,1,1,1,1
1,1,1,1,1,1,1,1,1,1,1,1,1,1,1,1,1,1,1,1,1
1,1,1,1,1,1,1,1,1,1,1,1,1,1,1,1,1,1,1,1,1
1,1,1,1,1,1,1,1,1,1,1,1,1,1,1,1,1,1,1,1,1
1,1,1,1,1,1,1,1,1,1,1,1,1,1,1,1,1,1,1,1,1
1,1,1,1,1,1,1,1,1,1,1,1,1,1,1,1,1,1,1,1,1
1,1,1,1,1,1,1,1,1,1,1,1,1,1,1,1,1,1,1,1,1
1,1,1,1,1,1,1,1,1,1,1,1,1,1,1,1,1,1,1,1,1
1,1,1,1,1,1,1,1,1,1,1,1,1,1,1,1,1,1,1,1,1
1,1,1,1,1,1,1,1,1,1,1,1,1,1,1,1,1,1,1,1,1
1,1,1,1,1,1,1,1,1,1,1,1,1,1,1,1,1,1,1,1,1
1,1,1,0,0,0,0,0,0,0,0,2,2,0,0,0,0,0,1,1,1
1,1,1,0,0,0,0,0,0,0,0,0,0,0,0,0,0,0,1,1,1
1,1,1,0,0,0,0,0,0,0,0,0,2,0,0,0,0,0,1,1,1
1,1,1,0,0,0,0,0,0,0,0,0,0,0,0,0,0,0,1,1,1
1,1,1,0,0,0,0,0,0,0,0,0,0,0,0,0,0,0,1,1,1
1,1,1,0,0,0,0,0,0,0,0,0,0,0,0,0,0,0,1,1,1
1,1,1,0,0,0,0,0,0,0,0,0,0,0,2,0,0,0,1,1,1
1,1,1,0,0,0,0,0,0,0,0,0,0,0,0,0,0,2,1,1,1
1,1,1,0,0,0,0,0,0,0,0,0,0,2,0,0,0,0,1,1,1
1,1,1,0,0,0,0,0,0,0,0,0,0,0,0,2,0,2,1,1,1
1,1,1,2,0,0,0,0,0,0,0,0,0,0,0,0,0,2,1,1,1
1,1,1,2,0,0,0,0,0,0,0,0,0,0,0,0,0,2,1,1,1
1,1,1,0,0,0,0,0,0,0,0,0,0,0,0,0,0,0,1,1,1
1,1,1,2,5,0,0,0,0,0,0,0,0,0,0,0,0,0,1,1,1
1,1,1,2,0,0,2,2,2,0,0,0,0,2,2,2,2,0,1,1,1
1,1,1,1,1,1,1,1,1,1,1,1,1,1,1,1,1,1,1,1,1
endlayer

layer
1,1,1,1,1,1,1,1,1,1,1,1,1,1,1,1,1,1,1,1,1
1,1,1,1,1,1,1,1,1,1,1,1,1,1,1,1,1,1,1,1,1
1,1,1,1,1,1,1,1,1,1,1,1,1,1,1,1,1,1,1,1,1
1,1,1,1,1,1,1,1,1,1,1,1,1,1,1,1,1,1,1,1,1
1,1,1,1,1,1,1,1,1,1,1,1,1,1,1,1,1,1,1,1,1
1,1,1,1,1,1,1,1,1,1,1,1,1,1,1,1,1,1,1,1,1
1,1,1,1,1,1,1,1,1,1,1,1,1,1,1,1,1,1,1,1,1
1,1,1,1,1,1,1,1,1,1,1,1,1,1,1,1,1,1,1,1,1
1,1,1,1,1,1,1,1,1,1,1,1,1,1,1,1,1,1,1,1,1
1,1,1,1,1,1,1,1,1,1,1,1,1,1,1,1,1,1,1,1,1
1,1,1,1,1,1,1,1,1,1,1,1,1,1,1,1,1,1,1,1,1
1,1,1,1,1,1,1,1,1,1,1,1,1,1,1,1,1,1,1,1,1
1,1,1,1,1,1,1,1,1,1,1,1,1,1,1,1,1,1,1,1,1
1,1,1,1,1,1,1,1,1,1,1,1,1,1,1,1,1,1,1,1,1
1,1,1,1,1,1,1,1,1,1,1,1,1,1,1,1,1,1,1,1,1
1,1,1,0,0,0,0,0,0,0,2,0,2,2,0,0,0,0,1,1,1
1,1,1,0,0,0,0,0,0,0,0,0,0,0,0,0,0,0,1,1,1
1,1,1,0,0,0,0,0,0,0,0,2,2,0,0,0,0,2,1,1,1
1,1,1,0,0,0,0,0,0,0,0,0,0,2,0,0,0,0,1,1,1
1,1,1,0,0,0,0,0,0,0,0,0,0,0,0,0,0,0,1,1,1
1,1,1,0,0,0,0,0,0,0,0,0,0,0,0,0,0,0,1,1,1
1,1,1,0,0,0,0,0,0,0,0,0,2,2,2,2,0,0,1,1,1
1,1,1,0,0,0,0,0,0,0,0,0,0,0,0,2,0,0,1,1,1
1,1,1,0,0,0,0,0,0,0,0,0,0,2,0,2,0,2,1,1,1
1,1,1,2,0,0,0,0,0,0,0,0,0,0,0,2,0,2,1,1,1
1,1,1,0,0,0,0,0,0,0,0,0,0,0,0,0,0,2,1,1,1
1,1,1,2,0,0,0,0,0,0,0,0,0,0,0,0,0,0,1,1,1
1,1,1,2,0,0,0,0,0,0,0,0,0,0,0,0,0,0,1,1,1
1,1,1,2,5,0,2,2,0,0,0,0,0,0,0,0,0,0,1,1,1
1,1,1,2,0,0,2,2,2,0,2,0,0,2,2,2,2,2,1,1,1
1,1,1,1,1,1,1,1,1,1,1,1,1,1,1,1,1,1,1,1,1
endlayer

layer
1,1,1,1,1,1,1,1,1,1,1,1,1,1,1,1,1,1,1,1,1
1,1,1,1,1,1,1,1,1,1,1,1,1,1,1,1,1,1,1,1,1
1,1,1,1,1,1,1,1,1,1,1,1,1,1,1,1,1,1,1,1,1
1,1,1,1,1,1,1,1,1,1,1,1,1,1,1,1,1,1,1,1,1
1,1,1,1,1,1,1,1,1,1,1,1,1,1,1,1,1,1,1,1,1
1,1,1,1,1,1,1,1,1,1,1,1,1,1,1,1,1,1,1,1,1
1,1,1,1,1,1,1,1,1,1,1,1,1,1,1,1,1,1,1,1,1
1,1,1,1,1,1,1,1,1,1,1,1,1,1,1,1,1,1,1,1,1
1,1,1,1,1,1,1,1,1,1,1,1,1,1,1,1,1,1,1,1,1
1,1,1,1,1,1,1,1,1,1,1,1,1,1,1,1,1,1,1,1,1
1,1,1,1,1,1,1,1,1,1,1,1,1,1,1,1,1,1,1,1,1
1,1,1,1,1,1,1,1,1,1,1,1,1,1,1,1,1,1,1,1,1
1,1,1,1,1,1,1,1,1,1,1,1,1,1,1,1,1,1,1,1,1
1,1,1,1,1,1,1,1,1,1,1,1,1,1,1,1,1,1,1,1,1
1,1,1,1,1,1,1,1,1,1,1,1,1,1,1,1,1,1,1,1,1
1,1,1,2,0,0,0,0,0,2,2,2,2,0,0,0,0,0,1,1,1
1,1,1,0,0,0,0,0,0,0,0,2,0,2,0,0,0,0,1,1,1
1,1,1,0,0,0,0,0,0,0,0,0,0,0,0,0,0,2,1,1,1
1,1,1,0,0,0,0,0,0,0,0,0,0,2,2,2,0,2,1,1,1
1,1,1,0,0,0,0,0,0,0,0,0,0,2,0,0,0,0,1,1,1
1,1,1,0,0,0,0,0,0,0,0,0,0,2,2,2,0,0,1,1,1
1,1,1,0,0,0,0,0,0,0,0,0,2,2,2,2,2,0,1,1,1
1,1,1,0,0,0,0,0,0,2,2,2,2,2,2,2,2,2,1,1,1
1,1,1,2,0,0,0,0,0,0,0,0,0,0,2,2,2,2,1,1,1
1,1,1,0,0,0,0,0,0,0,0,2,0,2,0,0,0,2,1,1,1
1,1,1,0,0,0,0,0,0,2,0,0,0,2,0,0,0,2,1,1,1
1,1,1,2,0,0,0,0,0,0,0,0,0,0,0,0,0,2,1,1,1
1,1,1,2,0,0,0,0,0,2,0,0,0,0,0,0,0,0,1,1,1
1,1,1,0,0,0,2,0,0,0,0,0,0,0,2,0,0,0,1,1,1
1,1,1,2,0,0,2,2,2,2,2,2,2,2,2,2,2,0,1,1,1
1,1,1,1,1,1,1,1,1,1,1,1,1,1,1,1,1,1,1,1,1
endlayer

layer
1,1,1,1,1,1,1,1,1,1,1,1,1,1,1,1,1,1,1,1,1
1,1,1,1,1,1,1,1,1,1,1,1,1,1,1,1,1,1,1,1,1
1,1,1,1,1,1,1,1,1,1,1,1,1,1,1,1,1,1,1,1,1
1,1,1,1,1,1,1,1,1,1,1,1,1,1,1,1,1,1,1,1,1
1,1,1,1,1,1,1,1,1,1,1,1,1,1,1,1,1,1,1,1,1
1,1,1,1,1,1,1,1,1,1,1,1,1,1,1,1,1,1,1,1,1
1,1,1,1,1,1,1,1,1,1,1,1,1,1,1,1,1,1,1,1,1
1,1,1,1,1,1,1,1,1,1,1,1,1,1,1,1,1,1,1,1,1
1,1,1,1,1,1,1,1,1,1,1,1,1,1,1,1,1,1,1,1,1
1,1,1,1,1,1,1,1,1,1,1,1,1,1,1,1,1,1,1,1,1
1,1,1,1,1,1,1,1,1,1,1,1,1,1,1,1,1,1,1,1,1
1,1,1,1,1,1,1,1,1,1,1,1,1,1,1,1,1,1,1,1,1
1,1,1,1,1,1,1,1,1,1,1,1,1,1,1,1,1,1,1,1,1
1,1,1,1,1,1,1,1,1,1,1,1,1,1,1,1,1,1,1,1,1
1,1,1,1,1,1,1,1,1,1,1,1,1,1,1,1,1,1,1,1,1
1,1,1,0,0,0,0,2,2,0,0,2,2,2,0,0,0,0,1,1,1
1,1,1,0,0,0,0,0,0,0,0,0,0,0,0,0,0,0,1,1,1
1,1,1,0,0,0,0,0,0,0,0,0,0,0,0,0,0,0,1,1,1
1,1,1,0,0,0,0,0,0,0,0,0,0,0,0,2,0,2,1,1,1
1,1,1,0,0,0,0,0,0,0,0,0,0,0,0,2,0,2,1,1,1
1,1,1,0,0,0,0,0,0,0,0,0,0,0,0,2,0,2,1,1,1
1,1,1,0,0,0,0,0,0,0,2,0,0,0,0,2,0,2,1,1,1
1,1,1,2,0,0,0,0,0,0,2,0,0,0,0,0,0,2,1,1,1
1,1,1,0,0,0,0,0,0,0,0,0,0,2,0,2,0,2,1,1,1
1,1,1,0,0,0,0,0,0,0,0,0,0,2,0,0,0,0,1,1,1
1,1,1,0,0,0,0,0,0,0,0,0,0,0,0,0,0,0,1,1,1
1,1,1,2,0,0,0,0,0,2,0,0,0,0,0,0,0,2,1,1,1
1,1,1,0,0,0,0,0,0,0,0,0,0,0,0,0,0,0,1,1,1
1,1,1,0,0,0,0,0,0,0,0,0,0,0,0,0,0,0,1,1,1
1,1,1,0,0,0,2,2,2,0,0,0,0,2,0,2,0,0,1,1,1
1,1,1,1,1,1,1,1,1,1,1,1,1,1,1,1,1,1,1,1,1
endlayer

layer
1,1,1,1,1,1,1,1,1,1,1,1,1,1,1,1,1,1,1,1,1
1,1,1,1,1,1,1,1,1,1,1,1,1,1,1,1,1,1,1,1,1
1,1,1,1,1,1,1,1,1,1,1,1,1,1,1,1,1,1,1,1,1
1,1,1,1,1,1,1,1,1,1,1,1,1,1,1,1,1,1,1,1,1
1,1,1,1,1,1,1,1,1,1,1,1,1,1,1,1,1,1,1,1,1
1,1,1,1,1,1,1,1,1,1,1,1,1,1,1,1,1,1,1,1,1
1,1,1,1,1,1,1,1,1,1,1,1,1,1,1,1,1,1,1,1,1
1,1,1,1,1,1,1,1,1,1,1,1,1,1,1,1,1,1,1,1,1
1,1,1,1,1,1,1,1,1,1,1,1,1,1,1,1,1,1,1,1,1
1,1,1,1,1,1,1,1,1,1,1,1,1,1,1,1,1,1,1,1,1
1,1,1,1,1,1,1,1,1,1,1,1,1,1,1,1,1,1,1,1,1
1,1,1,1,1,1,1,1,1,1,1,1,1,1,1,1,1,1,1,1,1
1,1,1,1,1,1,1,1,1,1,1,1,1,1,1,1,1,1,1,1,1
1,1,1,1,1,1,1,1,1,1,1,1,1,1,1,1,1,1,1,1,1
1,1,1,1,1,1,1,1,1,1,1,1,1,1,1,1,1,1,1,1,1
1,1,1,0,0,0,0,0,0,2,2,2,2,0,0,0,0,2,1,1,1
1,1,1,0,0,0,0,0,0,0,0,0,0,0,0,0,0,0,1,1,1
1,1,1,0,0,0,0,0,0,0,0,0,0,2,0,0,0,0,1,1,1
1,1,1,0,0,0,0,0,0,0,0,0,0,0,4,2,0,0,1,1,1
1,1,1,0,0,0,0,0,0,0,0,0,0,0,0,2,0,2,1,1,1
1,1,1,0,0,0,0,0,0,0,0,0,0,0,0,2,0,2,1,1,1
1,1,1,0,0,0,0,0,0,0,0,0,0,0,0,2,0,0,1,1,1
1,1,1,2,0,0,0,0,0,0,2,0,0,0,0,0,0,2,1,1,1
1,1,1,0,0,0,0,0,0,0,0,0,0,2,0,0,0,0,1,1,1
1,1,1,0,0,0,0,0,0,0,0,0,0,0,0,0,0,0,1,1,1
1,1,1,2,0,0,0,0,0,0,0,0,0,0,0,0,0,0,1,1,1
1,1,1,2,0,0,0,0,0,0,0,0,0,0,0,0,0,0,1,1,1
1,1,1,0,0,0,0,0,0,0,0,0,0,0,0,0,0,0,1,1,1
1,1,1,0,0,0,0,0,0,0,0,0,0,0,0,0,0,0,1,1,1
1,1,1,2,0,0,0,2,0,0,0,0,2,2,0,0,0,0,1,1,1
1,1,1,1,1,1,1,1,1,1,1,1,1,1,1,1,1,1,1,1,1
endlayer

layer
1,1,1,1,1,1,1,1,1,1,1,1,1,1,1,1,1,1,1,1,1
1,1,1,1,1,1,1,1,1,1,1,1,1,1,1,1,1,1,1,1,1
1,1,1,1,1,1,1,1,1,1,1,1,1,1,1,1,1,1,1,1,1
1,1,1,1,1,1,1,1,1,1,1,1,1,1,1,1,1,1,1,1,1
1,1,1,1,1,1,1,1,1,1,1,1,1,1,1,1,1,1,1,1,1
1,1,1,1,1,1,1,1,1,1,1,1,1,1,1,1,1,1,1,1,1
1,1,1,1,1,1,1,1,1,1,1,1,1,1,1,1,1,1,1,1,1
1,1,1,1,1,1,1,1,1,1,1,1,1,1,1,1,1,1,1,1,1
1,1,1,1,1,1,1,1,1,1,1,1,1,1,1,1,1,1,1,1,1
1,1,1,1,1,1,1,1,1,1,1,1,1,1,1,1,1,1,1,1,1
1,1,1,1,1,1,1,1,1,1,1,1,1,1,1,1,1,1,1,1,1
1,1,1,1,1,1,1,1,1,1,1,1,1,1,1,1,1,1,1,1,1
1,1,1,1,1,1,1,1,1,1,1,1,1,1,1,1,1,1,1,1,1
1,1,1,1,1,1,1,1,1,1,1,1,1,1,1,1,1,1,1,1,1
1,1,1,1,1,1,1,1,1,1,1,1,1,1,1,1,1,1,1,1,1
1,1,1,0,0,0,0,0,2,2,2,2,2,2,2,0,2,2,1,1,1
1,1,1,0,0,0,0,0,0,0,0,0,0,0,0,0,0,0,1,1,1
1,1,1,0,0,0,0,0,0,0,0,2,0,2,2,0,0,0,1,1,1
1,1,1,0,0,0,0,0,0,0,0,0,0,0,0,0,0,0,1,1,1
1,1,1,0,0,2,2,0,0,0,0,0,0,0,0,2,0,0,1,1,1
1,1,1,0,0,0,0,0,0,0,0,0,0,0,0,2,0,2,1,1,1
1,1,1,2,0,0,2,0,0,0,0,0,0,0,0,2,0,2,1,1,1
1,1,1,2,0,0,0,0,0,0,0,0,0,0,0,2,0,2,1,1,1
1,1,1,2,0,0,0,0,0,0,2,0,0,2,0,2,0,2,1,1,1
1,1,1,2,0,0,0,0,0,0,0,0,0,0,0,0,0,0,1,1,1
1,1,1,2,0,0,0,0,0,0,0,0,0,2,0,0,0,0,1,1,1
1,1,1,2,0,0,0,0,0,0,0,2,0,0,0,0,0,2,1,1,1
1,1,1,2,0,0,0,0,0,0,0,2,0,2,0,0,0,0,1,1,1
1,1,1,2,0,0,0,0,0,0,0,2,0,0,0,0,0,0,1,1,1
1,1,1,2,2,0,0,0,2,0,2,2,2,2,2,0,0,0,1,1,1
1,1,1,1,1,1,1,1,1,1,1,1,1,1,1,1,1,1,1,1,1
endlayer

layer
1,1,1,1,1,1,1,1,1,1,1,1,1,1,1,1,1,1,1,1,1
1,1,1,1,1,1,1,1,1,1,1,1,1,1,1,1,1,1,1,1,1
1,1,1,1,1,1,1,1,1,1,1,1,1,1,1,1,1,1,1,1,1
1,1,1,1,1,1,1,1,1,1,1,1,1,1,1,1,1,1,1,1,1
1,1,1,1,1,1,1,1,1,1,1,1,1,1,1,1,1,1,1,1,1
1,1,1,1,1,1,1,1,1,1,1,1,1,1,1,1,1,1,1,1,1
1,1,1,1,1,1,1,1,1,1,1,1,1,1,1,1,1,1,1,1,1
1,1,1,1,1,1,1,1,1,1,1,1,1,1,1,1,1,1,1,1,1
1,1,1,1,1,1,1,1,1,1,1,1,1,1,1,1,1,1,1,1,1
1,1,1,1,1,1,1,1,1,1,1,1,1,1,1,1,1,1,1,1,1
1,1,1,1,1,1,1,1,1,1,1,1,1,1,1,1,1,1,1,1,1
1,1,1,1,1,1,1,1,1,1,1,1,1,1,1,1,1,1,1,1,1
1,1,1,1,1,1,1,1,1,1,1,1,1,1,1,1,1,1,1,1,1
1,1,1,1,1,1,1,1,1,1,1,1,1,1,1,1,1,1,1,1,1
1,1,1,1,1,1,1,1,1,1,1,1,1,1,1,1,1,1,1,1,1
1,1,1,0,0,0,0,0,0,2,2,0,0,2,2,2,0,0,1,1,1
1,1,1,0,0,0,0,0,0,2,0,2,2,2,2,0,0,0,1,1,1
1,1,1,0,0,0,0,0,0,0,0,2,2,2,2,0,0,0,1,1,1
1,1,1,2,0,2,0,0,0,2,0,2,0,2,0,0,0,0,1,1,1
1,1,1,2,2,2,2,2,0,2,0,0,2,0,2,2,0,0,1,1,1
1,1,1,2,2,2,2,0,0,0,0,0,0,0,2,2,2,2,1,1,1
1,1,1,2,2,2,2,0,0,0,0,0,0,2,2,2,2,2,1,1,1
1,1,1,2,2,0,2,2,2,0,0,0,0,0,2,0,2,2,1,1,1
1,1,1,2,0,0,0,2,2,0,0,0,0,0,0,2,2,2,1,1,1
1,1,1,2,0,0,0,0,0,2,2,0,0,0,0,2,0,2,1,1,1
1,1,1,0,0,0,0,0,0,2,2,2,2,2,0,2,0,2,1,1,1
1,1,1,0,0,0,0,0,0,2,2,2,2,2,2,0,2,2,1,1,1
1,1,1,2,0,0,0,0,2,2,0,2,2,2,0,0,0,0,1,1,1
1,1,1,2,2,2,0,0,2,2,2,2,2,5,0,0,0,0,1,1,1
1,1,1,2,2,2,0,2,2,2,2,2,2,2,0,0,0,2,1,1,1
1,1,1,1,1,1,1,1,1,1,1,1,1,1,1,1,1,1,1,1,1
endlayer

layer
1,1,1,1,1,1,1,1,1,1,1,1,1,1,1,1,1,1,1,1,1
1,1,1,1,1,1,1,1,1,1,1,1,1,1,1,1,1,1,1,1,1
1,1,1,1,1,1,1,1,1,1,1,1,1,1,1,1,1,1,1,1,1
1,1,1,1,1,1,1,1,1,1,1,1,1,1,1,1,1,1,1,1,1
1,1,1,1,1,1,1,1,1,1,1,1,1,1,1,1,1,1,1,1,1
1,1,1,1,1,1,1,1,1,1,1,1,1,1,1,1,1,1,1,1,1
1,1,1,1,1,1,1,1,1,1,1,1,1,1,1,1,1,1,1,1,1
1,1,1,1,1,1,1,1,1,1,1,1,1,1,1,1,1,1,1,1,1
1,1,1,1,1,1,1,1,1,1,1,1,1,1,1,1,1,1,1,1,1
1,1,1,1,1,1,1,1,1,1,1,1,1,1,1,1,1,1,1,1,1
1,1,1,1,1,1,1,1,1,1,1,1,1,1,1,1,1,1,1,1,1
1,1,1,1,1,1,1,1,1,1,1,1,1,1,1,1,1,1,1,1,1
1,1,1,1,1,1,1,1,1,1,1,1,1,1,1,1,1,1,1,1,1
1,1,1,1,1,1,1,1,1,1,1,1,1,1,1,1,1,1,1,1,1
1,1,1,1,1,1,1,1,1,1,1,1,1,1,1,1,1,1,1,1,1
1,1,1,2,0,2,0,0,0,0,0,0,0,0,0,0,0,0,1,1,1
1,1,1,2,0,0,0,0,0,0,0,0,0,0,0,0,0,0,1,1,1
1,1,1,0,0,0,0,0,0,2,0,2,0,2,0,0,0,0,1,1,1
1,1,1,2,0,0,0,0,0,0,0,2,0,0,0,0,0,0,1,1,1
1,1,1,2,0,0,0,0,2,0,0,0,0,0,0,0,0,2,1,1,1
1,1,1,2,0,0,0,0,2,0,0,0,0,0,0,0,0,2,1,1,1
1,1,1,2,0,2,2,0,2,0,0,2,0,0,2,2,0,2,1,1,1
1,1,1,2,0,0,0,0,0,0,0,0,0,0,0,2,0,2,1,1,1
1,1,1,2,0,0,0,0,2,0,0,0,0,0,0,2,0,2,1,1,1
1,1,1,2,0,0,0,0,0,2,0,0,0,0,0,2,0,2,1,1,1
1,1,1,0,0,0,0,0,0,0,2,2,0,2,2,2,0,2,1,1,1
1,1,1,2,0,0,0,0,0,0,0,0,0,0,0,0,0,2,1,1,1
1,1,1,2,0,0,0,0,0,2,2,2,2,2,0,0,0,0,1,1,1
1,1,1,2,5,0,0,0,0,0,0,0,2,0,0,0,0,0,1,1,1
1,1,1,2,2,2,2,2,2,2,2,2,2,2,2,0,0,0,1,1,1
1,1,1,1,1,1,1,1,1,1,1,1,1,1,1,1,1,1,1,1,1
endlayer

layer
1,1,1,1,1,1,1,1,1,1,1,1,1,1,1,1,1,1,1,1,1
1,1,1,1,1,1,1,1,1,1,1,1,1,1,1,1,1,1,1,1,1
1,1,1,1,1,1,1,1,1,1,1,1,1,1,1,1,1,1,1,1,1
1,1,1,1,1,1,1,1,1,1,1,1,1,1,1,1,1,1,1,1,1
1,1,1,1,1,1,1,1,1,1,1,1,1,1,1,1,1,1,1,1,1
1,1,1,1,1,1,1,1,1,1,1,1,1,1,1,1,1,1,1,1,1
1,1,1,1,1,1,1,1,1,1,1,1,1,1,1,1,1,1,1,1,1
1,1,1,1,1,1,1,1,1,1,1,1,1,1,1,1,1,1,1,1,1
1,1,1,1,1,1,1,1,1,1,1,1,1,1,1,1,1,1,1,1,1
1,1,1,1,1,1,1,1,1,1,1,1,1,1,1,1,1,1,1,1,1
1,1,1,1,1,1,1,1,1,1,1,1,1,1,1,1,1,1,1,1,1
1,1,1,1,1,1,1,1,1,1,1,1,1,1,1,1,1,1,1,1,1
1,1,1,1,1,1,1,1,1,1,1,1,1,1,1,1,1,1,1,1,1
1,1,1,1,1,1,1,1,1,1,1,1,1,1,1,1,1,1,1,1,1
1,1,1,1,1,1,1,1,1,1,1,1,1,1,1,1,1,1,1,1,1
1,1,1,0,0,0,0,0,0,0,0,0,0,2,0,2,0,0,1,1,1
1,1,1,0,0,0,0,0,0,0,0,0,0,0,0,0,0,0,1,1,1
1,1,1,0,0,0,0,0,0,0,0,2,0,2,2,0,0,0,1,1,1
1,1,1,2,0,0,0,0,0,0,0,0,0,2,0,0,0,0,1,1,1
1,1,1,2,0,0,0,0,0,0,0,0,0,0,0,0,0,0,1,1,1
1,1,1,2,0,0,0,0,2,0,0,0,0,0,0,0,0,2,1,1,1
1,1,1,2,0,2,0,0,0,0,0,2,0,2,2,2,0,2,1,1,1
1,1,1,2,0,0,0,0,0,0,0,0,0,0,0,1,0,2,1,1,1
1,1,1,2,0,2,0,0,2,0,2,0,2,2,0,2,0,2,1,1,1
1,1,1,0,0,0,0,0,0,2,0,0,0,0,0,2,0,2,1,1,1
1,1,1,2,0,0,0,0,0,0,2,0,2,0,0,2,0,2,1,1,1
1,1,1,0,0,0,0,0,0,0,0,0,0,0,0,0,0,0,1,1,1
1,1,1,2,0,0,0,2,0,2,2,2,2,2,0,0,0,0,1,1,1
1,1,1,2,5,0,0,2,0,0,0,0,0,0,0,0,0,0,1,1,1
1,1,1,2,2,2,2,2,2,2,2,2,2,2,2,2,0,2,1,1,1
1,1,1,1,1,1,1,1,1,1,1,1,1,1,1,1,1,1,1,1,1
endlayer

layer
1,1,1,1,1,1,1,1,1,1,1,1,1,1,1,1,1,1,1,1,1
1,1,1,1,1,1,1,1,1,1,1,1,1,1,1,1,1,1,1,1,1
1,1,1,1,1,1,1,1,1,1,1,1,1,1,1,1,1,1,1,1,1
1,1,1,1,1,1,1,1,1,1,1,1,1,1,1,1,1,1,1,1,1
1,1,1,1,1,1,1,1,1,1,1,1,1,1,1,1,1,1,1,1,1
1,1,1,1,1,1,1,1,1,1,1,1,1,1,1,1,1,1,1,1,1
1,1,1,1,1,1,1,1,1,1,1,1,1,1,1,1,1,1,1,1,1
1,1,1,1,1,1,1,1,1,1,1,1,1,1,1,1,1,1,1,1,1
1,1,1,1,1,1,1,1,1,1,1,1,1,1,1,1,1,1,1,1,1
1,1,1,1,1,1,1,1,1,1,1,1,1,1,1,1,1,1,1,1,1
1,1,1,1,1,1,1,1,1,1,1,1,1,1,1,1,1,1,1,1,1
1,1,1,1,1,1,1,1,1,1,1,1,1,1,1,1,1,1,1,1,1
1,1,1,1,1,1,1,1,1,1,1,1,1,1,1,1,1,1,1,1,1
1,1,1,1,1,1,1,1,1,1,1,1,1,1,1,1,1,1,1,1,1
1,1,1,1,1,1,1,1,1,1,1,1,1,1,1,1,1,1,1,1,1
1,1,1,0,0,2,0,0,0,2,2,2,2,0,0,0,2,0,1,1,1
1,1,1,0,0,0,0,0,0,0,0,0,0,0,0,0,0,2,1,1,1
1,1,1,0,0,0,0,0,0,0,0,2,0,0,0,0,0,0,1,1,1
1,1,1,2,0,0,0,0,0,0,0,2,0,2,0,0,0,0,1,1,1
1,1,1,2,0,0,0,2,0,0,0,0,0,2,2,0,0,2,1,1,1
1,1,1,2,0,0,0,0,0,0,0,0,0,0,0,0,0,2,1,1,1
1,1,1,2,0,2,2,0,2,0,0,0,0,0,0,2,0,2,1,1,1
1,1,1,2,0,2,0,0,0,0,0,0,0,0,0,2,0,2,1,1,1
1,1,1,2,0,2,0,0,0,0,2,2,0,0,0,2,0,2,1,1,1
1,1,1,2,0,0,0,0,0,0,0,0,0,0,0,2,0,2,1,1,1
1,1,1,2,0,0,0,0,0,0,2,0,0,0,0,0,0,0,1,1,1
1,1,1,2,0,2,0,0,0,0,0,0,0,0,0,0,0,0,1,1,1
1,1,1,2,0,0,0,2,0,2,2,2,2,0,0,0,0,2,1,1,1
1,1,1,2,5,0,0,2,0,0,0,0,2,0,0,0,0,0,1,1,1
1,1,1,2,2,0,2,2,2,2,2,2,2,2,2,2,0,2,1,1,1
1,1,1,1,1,1,1,1,1,1,1,1,1,1,1,1,1,1,1,1,1
endlayer

layer
1,1,1,1,1,1,1,1,1,1,1,1,1,1,1,1,1,1,1,1,1
1,1,1,1,1,1,1,1,1,1,1,1,1,1,1,1,1,1,1,1,1
1,1,1,1,1,1,1,1,1,1,1,1,1,1,1,1,1,1,1,1,1
1,1,1,1,1,1,1,1,1,1,1,1,1,1,1,1,1,1,1,1,1
1,1,1,1,1,1,1,1,1,1,1,1,1,1,1,1,1,1,1,1,1
1,1,1,1,1,1,1,1,1,1,1,1,1,1,1,1,1,1,1,1,1
1,1,1,1,1,1,1,1,1,1,1,1,1,1,1,1,1,1,1,1,1
1,1,1,1,1,1,1,1,1,1,1,1,1,1,1,1,1,1,1,1,1
1,1,1,1,1,1,1,1,1,1,1,1,1,1,1,1,1,1,1,1,1
1,1,1,1,1,1,1,1,1,1,1,1,1,1,1,1,1,1,1,1,1
1,1,1,1,1,1,1,1,1,1,1,1,1,1,1,1,1,1,1,1,1
1,1,1,1,1,1,1,1,1,1,1,1,1,1,1,1,1,1,1,1,1
1,1,1,1,1,1,1,1,1,1,1,1,1,1,1,1,1,1,1,1,1
1,1,1,1,1,1,1,1,1,1,1,1,1,1,1,1,1,1,1,1,1
1,1,1,1,1,1,1,1,1,1,1,1,1,1,1,1,1,1,1,1,1
1,1,1,2,2,2,0,0,0,0,2,2,2,0,0,0,2,2,1,1,1
1,1,1,0,0,0,0,0,0,0,2,2,2,0,0,0,0,2,1,1,1
1,1,1,2,2,2,0,0,0,0,2,2,2,2,0,0,0,2,1,1,1
1,1,1,0,0,2,0,0,0,0,2,2,0,0,0,0,0,2,1,1,1
1,1,1,2,2,2,2,0,0,2,2,0,0,2,0,0,0,2,1,1,1
1,1,1,2,2,2,2,2,0,2,0,0,0,0,0,0,2,2,1,1,1
1,1,1,2,2,2,2,2,2,2,2,2,0,0,0,2,2,2,1,1,1
1,1,1,2,2,2,2,2,2,2,2,0,0,0,2,0,2,2,1,1,1
1,1,1,2,2,2,2,0,2,2,0,2,0,0,2,2,2,2,1,1,1
1,1,1,2,0,0,0,0,2,0,0,0,0,2,0,2,2,2,1,1,1
1,1,1,2,2,2,0,0,0,2,0,0,0,0,0,0,0,2,1,1,1
1,1,1,2,0,0,2,0,0,2,0,2,2,0,0,2,0,0,1,1,1
1,1,1,2,2,2,2,2,2,2,2,2,0,0,0,0,0,0,1,1,1
1,1,1,2,5,0,2,2,2,2,2,2,2,2,2,0,0,0,1,1,1
1,1,1,2,2,2,2,2,2,2,2,2,2,2,2,0,0,0,1,1,1
1,1,1,1,1,1,1,1,1,1,1,1,1,1,1,1,1,1,1,1,1
endlayer

layer
1,1,1,1,1,1,1,1,1,1,1,1,1,1,1,1,1,1,1,1,1
1,1,1,1,1,1,1,1,1,1,1,1,1,1,1,1,1,1,1,1,1
1,1,1,1,1,1,1,1,1,1,1,1,1,1,1,1,1,1,1,1,1
1,1,1,1,1,1,1,1,1,1,1,1,1,1,1,1,1,1,1,1,1
1,1,1,1,1,1,1,1,1,1,1,1,1,1,1,1,1,1,1,1,1
1,1,1,1,1,1,1,1,1,1,1,1,1,1,1,1,1,1,1,1,1
1,1,1,1,1,1,1,1,1,1,1,1,1,1,1,1,1,1,1,1,1
1,1,1,1,1,1,1,1,1,1,1,1,1,1,1,1,1,1,1,1,1
1,1,1,1,1,1,1,1,1,1,1,1,1,1,1,1,1,1,1,1,1
1,1,1,1,1,1,1,1,1,1,1,1,1,1,1,1,1,1,1,1,1
1,1,1,1,1,1,1,1,1,1,1,1,1,1,1,1,1,1,1,1,1
1,1,1,1,1,1,1,1,1,1,1,1,1,1,1,1,1,1,1,1,1
1,1,1,1,1,1,1,1,1,1,1,1,1,1,1,1,1,1,1,1,1
1,1,1,1,1,1,1,1,1,1,1,1,1,1,1,1,1,1,1,1,1
1,1,1,1,1,1,1,1,1,1,1,1,1,1,1,1,1,1,1,1,1
1,1,1,2,2,0,0,0,0,2,2,2,2,0,0,0,2,2,1,1,1
1,1,1,2,0,0,2,0,0,0,0,0,0,0,0,0,0,2,1,1,1
1,1,1,2,0,0,0,0,0,0,2,2,0,0,0,2,0,2,1,1,1
1,1,1,0,0,0,0,0,0,0,2,0,0,0,0,0,0,0,1,1,1
1,1,1,0,0,2,0,0,0,0,0,0,0,0,0,0,0,2,1,1,1
1,1,1,2,0,0,0,0,0,0,2,0,0,0,0,2,0,2,1,1,1
1,1,1,2,0,0,2,0,0,0,2,0,0,0,0,2,0,2,1,1,1
1,1,1,2,0,6,2,0,0,0,0,0,0,0,0,2,0,2,1,1,1
1,1,1,0,0,0,0,0,2,2,0,0,0,0,2,2,0,2,1,1,1
1,1,1,0,0,0,0,0,0,2,0,0,0,2,0,0,0,2,1,1,1
1,1,1,2,0,0,0,0,0,2,0,0,0,0,0,0,2,2,1,1,1
1,1,1,2,0,0,0,0,0,2,0,2,0,2,0,0,0,0,1,1,1
1,1,1,2,2,0,2,2,0,2,0,2,0,0,0,0,0,0,1,1,1
1,1,1,2,0,0,0,0,0,0,0,2,0,0,0,0,0,0,1,1,1
1,1,1,2,2,2,2,2,2,2,2,2,2,2,2,2,0,0,1,1,1
1,1,1,1,1,1,1,1,1,1,1,1,1,1,1,1,1,1,1,1,1
endlayer

layer
1,1,1,1,1,1,1,1,1,1,1,1,1,1,1,1,1,1,1,1,1
1,1,1,1,1,1,1,1,1,1,1,1,1,1,1,1,1,1,1,1,1
1,1,1,1,1,1,1,1,1,1,1,1,1,1,1,1,1,1,1,1,1
1,1,1,1,1,1,1,1,1,1,1,1,1,1,1,1,1,1,1,1,1
1,1,1,1,1,1,1,1,1,1,1,1,1,1,1,1,1,1,1,1,1
1,1,1,1,1,1,1,1,1,1,1,1,1,1,1,1,1,1,1,1,1
1,1,1,1,1,1,1,1,1,1,1,1,1,1,1,1,1,1,1,1,1
1,1,1,1,1,1,1,1,1,1,1,1,1,1,1,1,1,1,1,1,1
1,1,1,1,1,1,1,1,1,1,1,1,1,1,1,1,1,1,1,1,1
1,1,1,1,1,1,1,1,1,1,1,1,1,1,1,1,1,1,1,1,1
1,1,1,1,1,1,1,1,1,1,1,1,1,1,1,1,1,1,1,1,1
1,1,1,1,1,1,1,1,1,1,1,1,1,1,1,1,1,1,1,1,1
1,1,1,1,1,1,1,1,1,1,1,1,1,1,1,1,1,1,1,1,1
1,1,1,1,1,1,1,1,1,1,1,1,1,1,1,1,1,1,1,1,1
1,1,1,1,1,1,1,1,1,1,1,1,1,1,1,1,1,1,1,1,1
1,1,1,2,2,2,2,0,2,2,2,2,2,2,2,2,0,2,1,1,1
1,1,1,2,0,0,0,0,0,0,0,0,0,0,0,0,0,2,1,1,1
1,1,1,2,0,0,0,0,0,0,2,0,0,2,2,2,0,2,1,1,1
1,1,1,0,0,0,0,0,0,0,2,0,0,0,0,0,0,0,1,1,1
1,1,1,2,0,0,0,0,2,0,2,0,0,0,0,2,0,2,1,1,1
1,1,1,2,0,0,0,0,0,0,2,0,0,0,0,2,0,2,1,1,1
1,1,1,2,0,0,2,0,2,0,2,0,0,0,0,2,0,2,1,1,1
1,1,1,2,0,6,2,0,0,0,2,0,0,0,0,1,0,2,1,1,1
1,1,1,0,0,0,2,2,2,2,2,2,0,2,0,2,0,2,1,1,1
1,1,1,0,0,0,0,0,0,1,0,0,0,0,0,0,0,2,1,1,1
1,1,1,2,0,2,2,0,0,0,0,0,0,2,0,0,2,2,1,1,1
1,1,1,2,0,0,0,0,0,2,0,2,0,2,0,0,0,0,1,1,1
1,1,1,2,2,2,2,2,0,2,0,2,0,2,0,0,0,0,1,1,1
1,1,1,2,0,0,0,0,0,0,0,2,0,0,0,0,0,0,1,1,1
1,1,1,2,2,2,2,2,2,2,2,2,2,2,2,0,0,0,1,1,1
1,1,1,1,1,1,1,1,1,1,1,1,1,1,1,1,1,1,1,1,1
endlayer

layer
1,1,1,1,1,1,1,1,1,1,1,1,1,1,1,1,1,1,1,1,1
1,1,1,1,1,1,1,1,1,1,1,1,1,1,1,1,1,1,1,1,1
1,1,1,1,1,1,1,1,1,1,1,1,1,1,1,1,1,1,1,1,1
1,1,1,1,1,1,1,1,1,1,1,1,1,1,1,1,1,1,1,1,1
1,1,1,1,1,1,1,1,1,1,1,1,1,1,1,1,1,1,1,1,1
1,1,1,1,1,1,1,1,1,1,1,1,1,1,1,1,1,1,1,1,1
1,1,1,1,1,1,1,1,1,1,1,1,1,1,1,1,1,1,1,1,1
1,1,1,1,1,1,1,1,1,1,1,1,1,1,1,1,1,1,1,1,1
1,1,1,1,1,1,1,1,1,1,1,1,1,1,1,1,1,1,1,1,1
1,1,1,1,1,1,1,1,1,1,1,1,1,1,1,1,1,1,1,1,1
1,1,1,1,1,1,1,1,1,1,1,1,1,1,1,1,1,1,1,1,1
1,1,1,1,1,1,1,1,1,1,1,1,1,1,1,1,1,1,1,1,1
1,1,1,1,1,1,1,1,1,1,1,1,1,1,1,1,1,1,1,1,1
1,1,1,1,1,1,1,1,1,1,1,1,1,1,1,1,1,1,1,1,1
1,1,1,1,1,1,1,1,1,1,1,1,1,1,1,1,1,1,1,1,1
1,1,1,2,2,2,2,2,0,2,2,2,2,2,2,2,2,2,1,1,1
1,1,1,2,0,0,2,0,0,0,0,0,0,0,0,0,0,2,1,1,1
1,1,1,2,0,0,0,0,0,0,2,0,0,2,2,0,0,0,1,1,1
1,1,1,2,0,0,0,0,0,0,2,0,0,0,4,2,0,2,1,1,1
1,1,1,2,2,2,0,2,2,0,2,0,0,0,0,2,0,2,1,1,1
1,1,1,2,0,0,0,0,2,0,2,0,0,0,0,0,0,2,1,1,1
1,1,1,2,0,0,2,0,2,0,2,0,0,0,0,2,0,2,1,1,1
1,1,1,2,0,6,2,0,0,0,2,0,0,0,0,2,0,2,1,1,1
1,1,1,2,0,0,2,2,2,2,2,2,0,2,2,2,0,2,1,1,1
1,1,1,2,0,0,0,0,0,2,0,0,0,2,0,0,0,2,1,1,1
1,1,1,2,0,2,2,2,0,2,0,2,0,2,0,0,2,2,1,1,1
1,1,1,0,0,0,0,0,0,2,0,2,0,2,0,0,0,2,1,1,1
1,1,1,2,0,2,2,2,0,2,0,2,0,2,0,0,0,0,1,1,1
1,1,1,2,0,0,0,0,0,0,0,2,0,0,0,0,0,0,1,1,1
1,1,1,2,2,2,2,2,2,2,2,2,2,2,0,0,0,0,1,1,1
1,1,1,1,1,1,1,1,1,1,1,1,1,1,1,1,1,1,1,1,1
endlayer

layer
1,1,1,1,1,1,1,1,1,1,1,1,1,1,1,1,1,1,1,1,1
1,1,1,1,1,1,1,1,1,1,1,1,1,1,1,1,1,1,1,1,1
1,1,1,1,1,1,1,1,1,1,1,1,1,1,1,1,1,1,1,1,1
1,1,1,1,1,1,1,1,1,1,1,1,1,1,1,1,1,1,1,1,1
1,1,1,1,1,1,1,1,1,1,1,1,1,1,1,1,1,1,1,1,1
1,1,1,1,1,1,1,1,1,1,1,1,1,1,1,1,1,1,1,1,1
1,1,1,1,1,1,1,1,1,1,1,1,1,1,1,1,1,1,1,1,1
1,1,1,1,1,1,1,1,1,1,1,1,1,1,1,1,1,1,1,1,1
1,1,1,1,1,1,1,1,1,1,1,1,1,1,1,1,1,1,1,1,1
1,1,1,1,1,1,1,1,1,1,1,1,1,1,1,1,1,1,1,1,1
1,1,1,1,1,1,1,1,1,1,1,1,1,1,1,1,1,1,1,1,1
1,1,1,1,1,1,1,1,1,1,1,1,1,1,1,1,1,1,1,1,1
1,1,1,1,1,1,1,1,1,1,1,1,1,1,1,1,1,1,1,1,1
1,1,1,1,1,1,1,1,1,1,1,1,1,1,1,1,1,1,1,1,1
1,1,1,1,1,1,1,1,1,1,1,1,1,1,1,1,1,1,1,1,1
1,1,1,2,2,2,2,2,2,2,2,2,2,2,2,2,2,2,1,1,1
1,1,1,2,2,2,2,2,0,0,2,2,2,2,2,0,2,2,1,1,1
1,1,1,2,0,2,2,2,2,2,2,2,0,2,2,2,2,0,1,1,1
1,1,1,2,2,2,0,2,2,2,2,2,2,0,4,2,2,2,1,1,1
1,1,1,2,2,2,0,2,2,2,2,2,2,2,2,2,2,2,1,1,1
1,1,1,2,2,2,2,2,2,2,2,0,2,2,2,2,2,2,1,1,1
1,1,1,2,2,2,2,2,2,2,2,2,2,0,2,2,2,2,1,1,1
1,1,1,2,2,6,2,2,2,2,2,2,2,2,2,2,2,2,1,1,1
1,1,1,2,0,2,2,2,2,2,2,2,2,2,2,2,2,2,1,1,1
1,1,1,0,0,2,2,2,2,2,2,2,2,0,2,2,2,2,1,1,1
1,1,1,2,0,2,2,2,2,2,2,2,2,2,2,2,2,2,1,1,1
1,1,1,2,0,2,2,2,2,0,2,2,2,2,2,2,0,2,1,1,1
1,1,1,2,2,2,2,2,2,2,2,2,2,2,2,2,2,2,1,1,1
1,1,1,2,2,2,2,2,2,2,2,2,2,5,0,2,0,0,1,1,1
1,1,1,2,2,2,2,2,2,2,2,2,2,2,2,2,0,2,1,1,1
1,1,1,1,1,1,1,1,1,1,1,1,1,1,1,1,1,1,1,1,1
endlayer

layer
1,1,1,1,1,1,1,1,1,1,1,1,1,1,1,1,1,1,1,1,1
1,1,1,1,1,1,1,1,1,1,1,1,1,1,1,1,1,1,1,1,1
1,1,1,1,1,1,1,1,1,1,1,1,1,1,1,1,1,1,1,1,1
1,1,1,1,1,1,1,1,1,1,1,1,1,1,1,1,1,1,1,1,1
1,1,1,1,1,1,1,1,1,1,1,1,1,1,1,1,1,1,1,1,1
1,1,1,1,1,1,1,1,1,1,1,1,1,1,1,1,1,1,1,1,1
1,1,1,1,1,1,1,1,1,1,1,1,1,1,1,1,1,1,1,1,1
1,1,1,1,1,1,1,1,1,1,1,1,1,1,1,1,1,1,1,1,1
1,1,1,1,1,1,1,1,1,1,1,1,1,1,1,1,1,1,1,1,1
1,1,1,1,1,1,1,1,1,1,1,1,1,1,1,1,1,1,1,1,1
1,1,1,1,1,1,1,1,1,1,1,1,1,1,1,1,1,1,1,1,1
1,1,1,1,1,1,1,1,1,1,1,1,1,1,1,1,1,1,1,1,1
1,1,1,1,1,1,1,1,1,1,1,1,1,1,1,1,1,1,1,1,1
1,1,1,1,1,1,1,1,1,1,1,1,1,1,1,1,1,1,1,1,1
1,1,1,1,1,1,1,1,1,1,1,1,1,1,1,1,1,1,1,1,1
1,1,1,2,2,2,2,2,2,2,2,2,2,2,2,2,2,2,1,1,1
1,1,1,2,0,0,0,0,0,0,0,0,0,0,0,0,0,2,1,1,1
1,1,1,0,0,0,0,2,2,2,2,2,0,2,2,0,0,2,1,1,1
1,1,1,2,0,0,0,0,0,0,0,2,0,2,0,0,0,2,1,1,1
1,1,1,2,2,2,0,2,2,0,0,2,0,2,2,2,2,2,1,1,1
1,1,1,2,0,0,0,0,2,0,0,0,0,0,0,0,0,2,1,1,1
1,1,1,2,0,2,2,0,2,0,2,2,2,2,2,2,0,2,1,1,1
1,1,1,2,0,2,0,0,2,0,0,0,0,0,0,2,0,2,1,1,1
1,1,1,0,0,2,2,2,2,2,2,2,2,2,0,2,0,2,1,1,1
1,1,1,0,0,2,0,0,0,2,0,0,0,0,0,2,0,2,1,1,1
1,1,1,0,0,0,0,2,0,2,2,2,2,2,2,2,0,2,1,1,1
1,1,1,2,0,2,0,2,0,0,0,0,0,0,0,0,0,2,1,1,1
1,1,1,2,0,0,0,2,0,0,2,2,2,2,0,0,0,2,1,1,1
1,1,1,2,5,0,0,2,0,0,0,0,2,0,0,0,0,2,1,1,1
1,1,1,2,2,0,0,2,2,2,2,2,2,2,2,2,0,2,1,1,1
1,1,1,1,1,1,1,1,1,1,1,1,1,1,1,1,1,1,1,1,1
endlayer

layer
1,1,1,1,1,1,1,1,1,1,1,1,1,1,1,1,1,1,1,1,1
1,1,1,1,1,1,1,1,1,1,1,1,1,1,1,1,1,1,1,1,1
1,1,1,1,1,1,1,1,1,1,1,1,1,1,1,1,1,1,1,1,1
1,1,1,1,1,1,1,1,1,1,1,1,1,1,1,1,1,1,1,1,1
1,1,1,1,1,1,1,1,1,1,1,1,1,1,1,1,1,1,1,1,1
1,1,1,1,1,1,1,1,1,1,1,1,1,1,1,1,1,1,1,1,1
1,1,1,1,1,1,1,1,1,1,1,1,1,1,1,1,1,1,1,1,1
1,1,1,1,1,1,1,1,1,1,1,1,1,1,1,1,1,1,1,1,1
1,1,1,1,1,1,1,1,1,1,1,1,1,1,1,1,1,1,1,1,1
1,1,1,1,1,1,1,1,1,1,1,1,1,1,1,1,1,1,1,1,1
1,1,1,1,1,1,1,1,1,1,1,1,1,1,1,1,1,1,1,1,1
1,1,1,1,1,1,1,1,1,1,1,1,1,1,1,1,1,1,1,1,1
1,1,1,1,1,1,1,1,1,1,1,1,1,1,1,1,1,1,1,1,1
1,1,1,1,1,1,1,1,1,1,1,1,1,1,1,1,1,1,1,1,1
1,1,1,1,1,1,1,1,1,1,1,1,1,1,1,1,1,1,1,1,1
1,1,1,2,2,2,2,2,2,2,2,2,2,2,2,2,2,2,1,1,1
1,1,1,2,0,0,0,0,0,0,0,0,0,0,0,0,0,2,1,1,1
1,1,1,2,0,2,2,2,2,2,2,2,0,2,2,2,0,2,1,1,1
1,1,1,2,0,0,0,0,0,0,0,2,0,2,0,0,0,2,1,1,1
1,1,1,2,2,2,2,2,2,0,0,2,0,2,2,2,2,2,1,1,1
1,1,1,2,0,0,0,0,2,0,0,0,0,0,0,0,0,2,1,1,1
1,1,1,2,0,2,2,0,2,0,2,2,2,2,2,2,0,2,1,1,1
1,1,1,2,0,2,0,0,2,0,0,0,0,0,0,1,0,2,1,1,1
1,1,1,0,0,2,1,2,2,2,2,2,2,2,0,2,0,2,1,1,1
1,1,1,0,0,0,0,0,0,2,0,0,0,0,0,2,0,2,1,1,1
1,1,1,0,0,2,0,0,0,0,2,2,2,2,2,0,0,0,1,1,1
1,1,1,2,0,2,0,2,0,0,0,0,0,0,0,0,0,2,1,1,1
1,1,1,2,0,2,0,2,0,2,2,2,2,2,0,0,0,0,1,1,1
1,1,1,2,5,0,0,2,0,0,0,0,2,0,0,0,0,0,1,1,1
1,1,1,2,0,0,0,0,2,2,2,2,2,2,0,2,0,2,1,1,1
1,1,1,1,1,1,1,1,1,1,1,1,1,1,1,1,1,1,1,1,1
endlayer

layer
1,1,1,1,1,1,1,1,1,1,1,1,1,1,1,1,1,1,1,1,1
1,1,1,1,1,1,1,1,1,1,1,1,1,1,1,1,1,1,1,1,1
1,1,1,1,1,1,1,1,1,1,1,1,1,1,1,1,1,1,1,1,1
1,1,1,1,1,1,1,1,1,1,1,1,1,1,1,1,1,1,1,1,1
1,1,1,1,1,1,1,1,1,1,1,1,1,1,1,1,1,1,1,1,1
1,1,1,1,1,1,1,1,1,1,1,1,1,1,1,1,1,1,1,1,1
1,1,1,1,1,1,1,1,1,1,1,1,1,1,1,1,1,1,1,1,1
1,1,1,1,1,1,1,1,1,1,1,1,1,1,1,1,1,1,1,1,1
1,1,1,1,1,1,1,1,1,1,1,1,1,1,1,1,1,1,1,1,1
1,1,1,1,1,1,1,1,1,1,1,1,1,1,1,1,1,1,1,1,1
1,1,1,1,1,1,1,1,1,1,1,1,1,1,1,1,1,1,1,1,1
1,1,1,1,1,1,1,1,1,1,1,1,1,1,1,1,1,1,1,1,1
1,1,1,1,1,1,1,1,1,1,1,1,1,1,1,1,1,1,1,1,1
1,1,1,1,1,1,1,1,1,1,1,1,1,1,1,1,1,1,1,1,1
1,1,1,1,1,1,1,1,1,1,1,1,1,1,1,1,1,1,1,1,1
1,1,1,2,2,2,2,2,2,2,2,2,2,2,2,2,2,2,1,1,1
1,1,1,2,0,0,0,0,0,0,0,0,0,0,0,0,0,2,1,1,1
1,1,1,2,0,2,2,2,2,2,2,2,0,2,2,2,0,2,1,1,1
1,1,1,2,0,0,0,0,0,0,0,2,0,2,0,0,0,2,1,1,1
1,1,1,2,2,2,2,2,2,0,0,2,0,2,2,2,2,2,1,1,1
1,1,1,2,0,0,0,0,2,0,0,0,0,0,0,0,0,2,1,1,1
1,1,1,2,0,2,2,0,2,0,2,2,2,2,2,2,0,2,1,1,1
1,1,1,0,0,2,0,0,2,0,0,0,0,0,0,2,0,2,1,1,1
1,1,1,0,0,2,2,2,2,2,2,2,2,2,0,2,0,2,1,1,1
1,1,1,0,0,2,0,0,0,2,0,0,0,0,0,0,0,2,1,1,1
1,1,1,2,0,2,0,2,0,2,2,2,2,0,0,0,0,2,1,1,1
1,1,1,2,0,2,0,2,0,0,0,0,0,0,0,0,0,2,1,1,1
1,1,1,0,0,0,0,2,0,2,2,2,2,0,0,0,0,0,1,1,1
1,1,1,2,5,0,0,2,0,0,0,0,2,0,0,0,0,2,1,1,1
1,1,1,2,0,0,0,2,2,2,2,2,2,2,0,2,2,2,1,1,1
1,1,1,1,1,1,1,1,1,1,1,1,1,1,1,1,1,1,1,1,1
endlayer

layer
1,1,1,1,1,1,1,1,1,1,1,1,1,1,1,1,1,1,1,1,1
1,1,1,1,1,1,1,1,1,1,1,1,1,1,1,1,1,1,1,1,1
1,1,1,1,1,1,1,1,1,1,1,1,1,1,1,1,1,1,1,1,1
1,1,1,1,1,1,1,1,1,1,1,1,1,1,1,1,1,1,1,1,1
1,1,1,1,1,1,1,1,1,1,1,1,1,1,1,1,1,1,1,1,1
1,1,1,1,1,1,1,1,1,1,1,1,1,1,1,1,1,1,1,1,1
1,1,1,1,1,1,1,1,1,1,1,1,1,1,1,1,1,1,1,1,1
1,1,1,1,1,1,1,1,1,1,1,1,1,1,1,1,1,1,1,1,1
1,1,1,1,1,1,1,1,1,1,1,1,1,1,1,1,1,1,1,1,1
1,1,1,1,1,1,1,1,1,1,1,1,1,1,1,1,1,1,1,1,1
1,1,1,1,1,1,1,1,1,1,1,1,1,1,1,1,1,1,1,1,1
1,1,1,1,1,1,1,1,1,1,1,1,1,1,1,1,1,1,1,1,1
1,1,1,1,1,1,1,1,1,1,1,1,1,1,1,1,1,1,1,1,1
1,1,1,1,1,1,1,1,1,1,1,1,1,1,1,1,1,1,1,1,1
1,1,1,1,1,1,1,1,1,1,1,1,1,1,1,1,1,1,1,1,1
1,1,1,2,2,2,2,2,2,2,2,2,2,2,2,2,2,2,1,1,1
1,1,1,2,4,2,2,2,2,2,2,2,2,2,2,2,2,2,1,1,1
1,1,1,2,2,2,2,2,2,2,2,2,2,2,2,2,2,2,1,1,1
1,1,1,2,2,2,2,2,2,2,2,2,2,2,2,2,2,2,1,1,1
1,1,1,2,2,2,2,2,0,2,2,2,2,2,2,2,2,2,1,1,1
1,1,1,2,2,2,2,2,2,2,2,2,2,2,2,2,2,2,1,1,1
1,1,1,2,2,2,2,2,2,2,2,2,2,2,2,2,2,2,1,1,1
1,1,1,2,2,2,2,2,2,2,2,2,2,2,2,1,2,2,1,1,1
1,1,1,0,2,2,2,2,2,2,2,2,2,2,0,0,0,2,1,1,1
1,1,1,2,2,2,2,2,2,0,2,2,2,2,2,0,2,2,1,1,1
1,1,1,2,2,2,2,2,2,2,2,0,2,0,2,0,2,2,1,1,1
1,1,1,2,2,2,2,2,2,2,2,2,2,2,5,0,2,2,1,1,1
1,1,1,2,0,0,2,2,2,2,2,2,2,2,0,0,0,2,1,1,1
1,1,1,2,5,0,2,2,2,2,2,2,2,2,0,2,0,2,1,1,1
1,1,1,2,2,2,2,2,2,2,2,2,2,2,2,2,2,2,1,1,1
1,1,1,1,1,1,1,1,1,1,1,1,1,1,1,1,1,1,1,1,1
endlayer

layer
1,1,1,1,1,1,1,1,1,1,1,1,1,1,1,1,1,1,1,1,1
1,1,1,1,1,1,1,1,1,1,1,1,1,1,1,1,1,1,1,1,1
1,1,1,1,1,1,1,1,1,1,1,1,1,1,1,1,1,1,1,1,1
1,1,1,1,1,1,1,1,1,1,1,1,1,1,1,1,1,1,1,1,1
1,1,1,1,1,1,1,1,1,1,1,1,1,1,1,1,1,1,1,1,1
1,1,1,1,1,1,1,1,1,1,1,1,1,1,1,1,1,1,1,1,1
1,1,1,1,1,1,1,1,1,1,1,1,1,1,1,1,1,1,1,1,1
1,1,1,1,1,1,1,1,1,1,1,1,1,1,1,1,1,1,1,1,1
1,1,1,1,1,1,1,1,1,1,1,1,1,1,1,1,1,1,1,1,1
1,1,1,1,1,1,1,1,1,1,1,1,1,1,1,1,1,1,1,1,1
1,1,1,1,1,1,1,1,1,1,1,1,1,1,1,1,1,1,1,1,1
1,1,1,1,1,1,1,1,1,1,1,1,1,1,1,1,1,1,1,1,1
1,1,1,1,1,1,1,1,1,1,1,1,1,1,1,1,1,1,1,1,1
1,1,1,1,1,1,1,1,1,1,1,1,1,1,1,1,1,1,1,1,1
1,1,1,1,1,1,1,1,1,1,1,1,1,1,1,1,1,1,1,1,1
1,1,1,2,2,2,2,2,2,2,2,2,2,2,2,2,2,2,1,1,1
1,1,1,2,0,0,2,0,0,0,0,0,0,0,0,0,0,2,1,1,1
1,1,1,2,0,0,2,0,2,2,2,2,0,2,2,2,0,2,1,1,1
1,1,1,2,0,0,0,0,0,0,2,0,0,0,4,2,0,2,1,1,1
1,1,1,2,2,2,2,2,2,0,2,0,0,0,0,2,0,2,1,1,1
1,1,1,2,0,0,0,0,2,0,2,0,0,0,0,2,0,2,1,1,1
1,1,1,2,0,0,2,0,2,0,2,0,0,0,0,2,0,2,1,1,1
1,1,1,2,0,6,2,0,0,0,2,0,0,0,0,0,0,2,1,1,1
1,1,1,2,0,0,2,2,2,2,2,2,0,0,0,0,0,2,1,1,1
1,1,1,2,0,0,0,0,0,2,0,0,0,2,0,0,0,2,1,1,1
1,1,1,2,2,2,2,2,0,2,0,2,0,2,0,0,0,2,1,1,1
1,1,1,2,0,0,0,0,0,2,0,2,0,2,0,0,0,2,1,1,1
1,1,1,2,2,0,2,2,0,2,0,2,0,2,2,2,0,0,1,1,1
1,1,1,2,0,0,0,0,0,0,0,2,0,0,0,0,0,2,1,1,1
1,1,1,2,2,2,2,2,2,2,2,2,2,2,0,2,2,2,1,1,1
1,1,1,1,1,1,1,1,1,1,1,1,1,1,1,1,1,1,1,1,1
endlayer

layer
1,1,1,1,1,1,1,1,1,1,1,1,1,1,1,1,1,1,1,1,1
1,1,1,1,1,1,1,1,1,1,1,1,1,1,1,1,1,1,1,1,1
1,1,1,1,1,1,1,1,1,1,1,1,1,1,1,1,1,1,1,1,1
1,1,1,1,1,1,1,1,1,1,1,1,1,1,1,1,1,1,1,1,1
1,1,1,1,1,1,1,1,1,1,1,1,1,1,1,1,1,1,1,1,1
1,1,1,1,1,1,1,1,1,1,1,1,1,1,1,1,1,1,1,1,1
1,1,1,1,1,1,1,1,1,1,1,1,1,1,1,1,1,1,1,1,1
1,1,1,1,1,1,1,1,1,1,1,1,1,1,1,1,1,1,1,1,1
1,1,1,1,1,1,1,1,1,1,1,1,1,1,1,1,1,1,1,1,1
1,1,1,1,1,1,1,1,1,1,1,1,1,1,1,1,1,1,1,1,1
1,1,1,1,1,1,1,1,1,1,1,1,1,1,1,1,1,1,1,1,1
1,1,1,1,1,1,1,1,1,1,1,1,1,1,1,1,1,1,1,1,1
1,1,1,1,1,1,1,1,1,1,1,1,1,1,1,1,1,1,1,1,1
1,1,1,1,1,1,1,1,1,1,1,1,1,1,1,1,1,1,1,1,1
1,1,1,1,1,1,1,1,1,1,1,1,1,1,1,1,1,1,1,1,1
1,1,1,2,2,2,2,2,2,2,2,2,2,2,2,2,2,2,1,1,1
1,1,1,2,0,0,2,0,0,0,0,0,0,0,0,0,0,2,1,1,1
1,1,1,2,0,0,2,0,2,2,2,2,0,2,2,2,0,2,1,1,1
1,1,1,2,0,0,0,0,0,0,2,0,0,0,4,2,0,2,1,1,1
1,1,1,2,2,2,2,2,2,0,2,0,0,0,0,2,0,2,1,1,1
1,1,1,2,0,0,0,0,2,0,2,0,0,0,0,2,0,2,1,1,1
1,1,1,2,0,0,2,0,2,0,2,0,0,0,0,2,0,2,1,1,1
1,1,1,2,0,6,2,0,0,0,2,0,0,0,0,0,0,2,1,1,1
1,1,1,2,0,0,2,2,2,2,2,2,0,2,0,0,0,2,1,1,1
1,1,1,2,0,0,0,0,0,1,0,0,0,2,0,0,0,2,1,1,1
1,1,1,2,2,2,2,2,0,2,0,2,0,1,0,0,0,2,1,1,1
1,1,1,2,0,0,0,0,0,2,0,2,0,2,0,0,0,2,1,1,1
1,1,1,2,2,2,2,2,0,2,0,2,0,2,2,0,0,2,1,1,1
1,1,1,2,0,0,0,0,0,0,0,2,0,0,0,0,0,2,1,1,1
1,1,1,2,2,0,2,2,2,2,2,2,2,2,0,0,0,2,1,1,1
1,1,1,1,1,1,1,1,1,1,1,1,1,1,1,1,1,1,1,1,1
endlayer

layer
1,1,1,1,1,1,1,1,1,1,1,1,1,1,1,1,1,1,1,1,1
1,1,1,1,1,1,1,1,1,1,1,1,1,1,1,1,1,1,1,1,1
1,1,1,1,1,1,1,1,1,1,1,1,1,1,1,1,1,1,1,1,1
1,1,1,1,1,1,1,1,1,1,1,1,1,1,1,1,1,1,1,1,1
1,1,1,1,1,1,1,1,1,1,1,1,1,1,1,1,1,1,1,1,1
1,1,1,1,1,1,1,1,1,1,1,1,1,1,1,1,1,1,1,1,1
1,1,1,1,1,1,1,1,1,1,1,1,1,1,1,1,1,1,1,1,1
1,1,1,1,1,1,1,1,1,1,1,1,1,1,1,1,1,1,1,1,1
1,1,1,1,1,1,1,1,1,1,1,1,1,1,1,1,1,1,1,1,1
1,1,1,1,1,1,1,1,1,1,1,1,1,1,1,1,1,1,1,1,1
1,1,1,1,1,1,1,1,1,1,1,1,1,1,1,1,1,1,1,1,1
1,1,1,1,1,1,1,1,1,1,1,1,1,1,1,1,1,1,1,1,1
1,1,1,1,1,1,1,1,1,1,1,1,1,1,1,1,1,1,1,1,1
1,1,1,1,1,1,1,1,1,1,1,1,1,1,1,1,1,1,1,1,1
1,1,1,1,1,1,1,1,1,1,1,1,1,1,1,1,1,1,1,1,1
1,1,1,2,2,2,2,2,2,2,2,2,2,2,2,2,2,2,1,1,1
1,1,1,2,0,0,2,0,0,0,0,0,0,0,0,0,0,2,1,1,1
1,1,1,2,0,0,2,0,2,2,2,2,0,2,2,2,0,2,1,1,1
1,1,1,2,0,0,0,0,0,0,2,0,0,0,4,2,0,2,1,1,1
1,1,1,2,2,2,2,2,2,0,2,0,0,0,0,2,0,2,1,1,1
1,1,1,2,0,0,0,0,2,0,2,0,0,0,0,2,0,2,1,1,1
1,1,1,2,0,0,2,0,2,0,2,0,0,0,0,2,0,2,1,1,1
1,1,1,2,0,6,2,0,0,0,2,0,0,0,0,2,0,2,1,1,1
1,1,1,2,0,0,2,2,2,2,2,2,0,2,2,0,0,2,1,1,1
1,1,1,2,0,0,0,0,0,2,0,0,0,2,0,0,0,0,1,1,1
1,1,1,2,2,0,0,2,0,2,0,2,0,2,0,0,0,2,1,1,1
1,1,1,2,0,0,0,0,0,2,0,2,0,2,0,0,0,2,1,1,1
1,1,1,2,2,2,2,2,0,2,0,2,0,2,0,2,0,2,1,1,1
1,1,1,2,0,0,0,0,0,0,0,2,0,0,0,0,0,0,1,1,1
1,1,1,2,2,2,2,2,2,2,2,2,2,0,0,0,0,0,1,1,1
1,1,1,1,1,1,1,1,1,1,1,1,1,1,1,1,1,1,1,1,1
endlayer

layer
1,1,1,1,1,1,1,1,1,1,1,1,1,1,1,1,1,1,1,1,1
1,1,1,1,1,1,1,1,1,1,1,1,1,1,1,1,1,1,1,1,1
1,1,1,1,1,1,1,1,1,1,1,1,1,1,1,1,1,1,1,1,1
1,1,1,1,1,1,1,1,1,1,1,1,1,1,1,1,1,1,1,1,1
1,1,1,1,1,1,1,1,1,1,1,1,1,1,1,1,1,1,1,1,1
1,1,1,1,1,1,1,1,1,1,1,1,1,1,1,1,1,1,1,1,1
1,1,1,1,1,1,1,1,1,1,1,1,1,1,1,1,1,1,1,1,1
1,1,1,1,1,1,1,1,1,1,1,1,1,1,1,1,1,1,1,1,1
1,1,1,1,1,1,1,1,1,1,1,1,1,1,1,1,1,1,1,1,1
1,1,1,1,1,1,1,1,1,1,1,1,1,1,1,1,1,1,1,1,1
1,1,1,1,1,1,1,1,1,1,1,1,1,1,1,1,1,1,1,1,1
1,1,1,1,1,1,1,1,1,1,1,1,1,1,1,1,1,1,1,1,1
1,1,1,1,1,1,1,1,1,1,1,1,1,1,1,1,1,1,1,1,1
1,1,1,1,1,1,1,1,1,1,1,1,1,1,1,1,1,1,1,1,1
1,1,1,1,1,1,1,1,1,1,1,1,1,1,1,1,1,1,1,1,1
1,1,1,2,2,2,2,2,2,2,2,2,2,2,2,2,2,2,1,1,1
1,1,1,2,2,2,2,2,2,2,2,2,2,2,2,2,2,2,1,1,1
1,1,1,2,2,2,2,2,0,2,2,2,2,2,2,2,2,2,1,1,1
1,1,1,2,2,2,2,2,2,2,2,2,2,2,4,2,2,2,1,1,1
1,1,1,2,2,0,2,2,2,2,2,2,2,2,2,2,2,2,1,1,1
1,1,1,2,2,2,2,2,2,2,2,2,2,2,2,2,2,2,1,1,1
1,1,1,2,2,2,2,2,2,2,2,2,2,2,2,2,2,2,1,1,1
1,1,1,2,2,6,2,2,2,2,2,2,2,2,2,0,2,2,1,1,1
1,1,1,2,2,2,2,2,2,2,2,2,2,2,2,2,2,2,1,1,1
1,1,1,2,2,2,2,2,2,2,2,2,2,2,2,2,2,2,1,1,1
1,1,1,2,2,2,2,2,0,2,2,2,2,2,2,2,2,2,1,1,1
1,1,1,2,2,0,2,2,2,2,2,2,2,0,2,2,2,2,1,1,1
1,1,1,2,2,2,2,2,2,2,2,2,2,2,2,0,2,2,1,1,1
1,1,1,2,2,2,2,2,2,2,2,2,2,5,0,0,0,2,1,1,1
1,1,1,2,2,2,2,2,2,2,2,2,2,2,0,0,0,2,1,1,1
1,1,1,1,1,1,1,1,1,1,1,1,1,1,1,1,1,1,1,1,1
endlayer

layer
1,1,1,1,1,1,1,1,1,1,1,1,1,1,1,1,1,1,1,1,1
1,1,1,1,1,1,1,1,1,1,1,1,1,1,1,1,1,1,1,1,1
1,1,1,1,1,1,1,1,1,1,1,1,1,1,1,1,1,1,1,1,1
1,1,1,1,1,1,1,1,1,1,1,1,1,1,1,1,1,1,1,1,1
1,1,1,1,1,1,1,1,1,1,1,1,1,1,1,1,1,1,1,1,1
1,1,1,1,1,1,1,1,1,1,1,1,1,1,1,1,1,1,1,1,1
1,1,1,1,1,1,1,1,1,1,1,1,1,1,1,1,1,1,1,1,1
1,1,1,1,1,1,1,1,1,1,1,1,1,1,1,1,1,1,1,1,1
1,1,1,1,1,1,1,1,1,1,1,1,1,1,1,1,1,1,1,1,1
1,1,1,1,1,1,1,1,1,1,1,1,1,1,1,1,1,1,1,1,1
1,1,1,1,1,1,1,1,1,1,1,1,1,1,1,1,1,1,1,1,1
1,1,1,1,1,1,1,1,1,1,1,1,1,1,1,1,1,1,1,1,1
1,1,1,1,1,1,1,1,1,1,1,1,1,1,1,1,1,1,1,1,1
1,1,1,1,1,1,1,1,1,1,1,1,1,1,1,1,1,1,1,1,1
1,1,1,1,1,1,1,1,1,1,1,1,1,1,1,1,1,1,1,1,1
1,1,1,2,2,2,2,2,2,2,2,2,2,2,2,2,2,2,1,1,1
1,1,1,2,0,0,0,2,0,0,0,0,2,0,0,0,0,2,1,1,1
1,1,1,2,0,2,0,2,0,0,0,0,2,0,2,2,0,2,1,1,1
1,1,1,2,0,2,0,2,2,2,2,0,2,0,0,2,0,2,1,1,1
1,1,1,2,0,2,0,0,0,0,0,0,2,0,0,2,0,2,1,1,1
1,1,1,2,0,2,0,2,2,2,2,0,2,2,2,2,0,2,1,1,1
1,1,1,2,0,2,0,0,2,0,0,0,0,0,0,0,0,2,1,1,1
1,1,1,2,0,0,2,0,2,2,2,2,2,2,2,2,2,2,1,1,1
1,1,1,2,2,2,2,0,0,0,0,0,0,0,0,0,0,2,1,1,1
1,1,1,2,0,0,0,0,2,2,2,2,2,0,2,2,2,2,1,1,1
1,1,1,2,2,2,2,0,2,0,0,0,0,0,0,0,0,2,1,1,1
1,1,1,2,0,0,0,0,2,0,2,2,2,2,2,2,0,2,1,1,1
1,1,1,2,0,2,2,2,0,2,2,2,2,0,0,0,0,2,1,1,1
1,1,1,2,0,0,0,0,0,0,2,2,0,0,0,0,0,2,1,1,1
1,1,1,2,2,2,2,2,2,2,2,2,2,2,2,2,0,2,1,1,1
1,1,1,1,1,1,1,1,1,1,1,1,1,1,1,1,1,1,1,1,1
endlayer

layer
1,1,1,1,1,1,1,1,1,1,1,1,1,1,1,1,1,1,1,1,1
1,1,1,1,1,1,1,1,1,1,1,1,1,1,1,1,1,1,1,1,1
1,1,1,1,1,1,1,1,1,1,1,1,1,1,1,1,1,1,1,1,1
1,1,1,1,1,1,1,1,1,1,1,1,1,1,1,1,1,1,1,1,1
1,1,1,1,1,1,1,1,1,1,1,1,1,1,1,1,1,1,1,1,1
1,1,1,1,1,1,1,1,1,1,1,1,1,1,1,1,1,1,1,1,1
1,1,1,1,1,1,1,1,1,1,1,1,1,1,1,1,1,1,1,1,1
1,1,1,1,1,1,1,1,1,1,1,1,1,1,1,1,1,1,1,1,1
1,1,1,1,1,1,1,1,1,1,1,1,1,1,1,1,1,1,1,1,1
1,1,1,1,1,1,1,1,1,1,1,1,1,1,1,1,1,1,1,1,1
1,1,1,1,1,1,1,1,1,1,1,1,1,1,1,1,1,1,1,1,1
1,1,1,1,1,1,1,1,1,1,1,1,1,1,1,1,1,1,1,1,1
1,1,1,1,1,1,1,1,1,1,1,1,1,1,1,1,1,1,1,1,1
1,1,1,1,1,1,1,1,1,1,1,1,1,1,1,1,1,1,1,1,1
1,1,1,1,1,1,1,1,1,1,1,1,1,1,1,1,1,1,1,1,1
1,1,1,2,2,2,2,2,2,2,2,2,2,2,2,2,2,2,1,1,1
1,1,1,2,0,0,0,2,0,0,0,0,2,0,0,0,0,2,1,1,1
1,1,1,2,0,2,0,2,0,0,0,0,2,0,2,2,0,2,1,1,1
1,1,1,2,0,2,0,2,2,2,2,0,2,0,0,2,0,2,1,1,1
1,1,1,2,0,1,0,0,0,0,0,0,2,0,0,2,0,2,1,1,1
1,1,1,2,0,2,0,2,2,2,2,0,2,2,2,2,0,2,1,1,1
1,1,1,2,0,2,0,0,2,0,0,0,0,0,0,0,0,2,1,1,1
1,1,1,2,0,0,2,0,2,2,2,2,2,2,2,1,2,2,1,1,1
1,1,1,2,2,2,2,0,0,0,0,0,0,0,0,0,0,2,1,1,1
1,1,1,2,0,0,0,0,2,2,2,2,2,0,2,2,2,2,1,1,1
1,1,1,2,2,2,2,0,1,0,0,0,0,0,0,0,0,2,1,1,1
1,1,1,2,0,0,0,0,2,0,2,2,2,2,2,2,0,2,1,1,1
1,1,1,2,0,2,2,2,0,0,2,2,2,0,0,0,0,2,1,1,1
1,1,1,2,0,0,0,0,0,0,2,2,2,0,0,0,2,2,1,1,1
1,1,1,2,2,2,2,2,2,2,2,2,2,2,2,2,2,2,1,1,1
1,1,1,1,1,1,1,1,1,1,1,1,1,1,1,1,1,1,1,1,1
endlayer

layer
1,1,1,1,1,1,1,1,1,1,1,1,1,1,1,1,1,1,1,1,1
1,1,1,1,1,1,1,1,1,1,1,1,1,1,1,1,1,1,1,1,1
1,1,1,1,1,1,1,1,1,1,1,1,1,1,1,1,1,1,1,1,1
1,1,1,1,1,1,1,1,1,1,1,1,1,1,1,1,1,1,1,1,1
1,1,1,1,1,1,1,1,1,1,1,1,1,1,1,1,1,1,1,1,1
1,1,1,1,1,1,1,1,1,1,1,1,1,1,1,1,1,1,1,1,1
1,1,1,1,1,1,1,1,1,1,1,1,1,1,1,1,1,1,1,1,1
1,1,1,1,1,1,1,1,1,1,1,1,1,1,1,1,1,1,1,1,1
1,1,1,1,1,1,1,1,1,1,1,1,1,1,1,1,1,1,1,1,1
1,1,1,1,1,1,1,1,1,1,1,1,1,1,1,1,1,1,1,1,1
1,1,1,1,1,1,1,1,1,1,1,1,1,1,1,1,1,1,1,1,1
1,1,1,1,1,1,1,1,1,1,1,1,1,1,1,1,1,1,1,1,1
1,1,1,1,1,1,1,1,1,1,1,1,1,1,1,1,1,1,1,1,1
1,1,1,1,1,1,1,1,1,1,1,1,1,1,1,1,1,1,1,1,1
1,1,1,1,1,1,1,1,1,1,1,1,1,1,1,1,1,1,1,1,1
1,1,1,2,2,2,2,2,2,2,2,2,2,2,2,2,2,2,1,1,1
1,1,1,2,0,0,0,2,0,0,0,0,2,0,0,0,0,2,1,1,1
1,1,1,2,0,2,0,2,0,0,0,0,2,0,2,2,0,2,1,1,1
1,1,1,2,0,2,0,2,2,2,2,0,2,0,0,2,0,2,1,1,1
1,1,1,2,0,2,0,0,0,0,0,0,2,0,0,2,0,2,1,1,1
1,1,1,2,0,2,0,2,2,2,2,0,2,2,2,2,0,2,1,1,1
1,1,1,2,0,2,0,0,2,0,0,0,0,0,0,0,0,2,1,1,1
1,1,1,2,0,0,2,0,2,2,2,2,2,2,2,2,2,2,1,1,1
1,1,1,2,2,2,2,0,0,0,0,0,0,0,0,0,0,2,1,1,1
1,1,1,2,0,0,0,0,2,2,2,2,2,0,2,2,2,2,1,1,1
1,1,1,2,2,2,2,0,2,0,0,0,0,0,0,0,0,2,1,1,1
1,1,1,2,0,0,0,0,2,0,2,2,2,2,2,2,0,2,1,1,1
1,1,1,2,0,2,2,2,0,0,0,2,2,2,0,0,0,2,1,1,1
1,1,1,2,0,0,0,0,0,0,2,2,2,2,0,2,2,2,1,1,1
1,1,1,2,2,2,2,2,2,2,2,2,2,2,2,2,2,2,1,1,1
1,1,1,1,1,1,1,1,1,1,1,1,1,1,1,1,1,1,1,1,1
endlayer

layer
1,1,1,1,1,1,1,1,1,1,1,1,1,1,1,1,1,1,1,1,1
1,1,1,1,1,1,1,1,1,1,1,1,1,1,1,1,1,1,1,1,1
1,1,1,1,1,1,1,1,1,1,1,1,1,1,1,1,1,1,1,1,1
1,1,1,1,1,1,1,1,1,1,1,1,1,1,1,1,1,1,1,1,1
1,1,1,1,1,1,1,1,1,1,1,1,1,1,1,1,1,1,1,1,1
1,1,1,1,1,1,1,1,1,1,1,1,1,1,1,1,1,1,1,1,1
1,1,1,1,1,1,1,1,1,1,1,1,1,1,1,1,1,1,1,1,1
1,1,1,1,1,1,1,1,1,1,1,1,1,1,1,1,1,1,1,1,1
1,1,1,1,1,1,1,1,1,1,1,1,1,1,1,1,1,1,1,1,1
1,1,1,1,1,1,1,1,1,1,1,1,1,1,1,1,1,1,1,1,1
1,1,1,1,1,1,1,1,1,1,1,1,1,1,1,1,1,1,1,1,1
1,1,1,1,1,1,1,1,1,1,1,1,1,1,1,1,1,1,1,1,1
1,1,1,1,1,1,1,1,1,1,1,1,1,1,1,1,1,1,1,1,1
1,1,1,1,1,1,1,1,1,1,1,1,1,1,1,1,1,1,1,1,1
1,1,1,1,1,1,1,1,1,1,1,1,1,1,1,1,1,1,1,1,1
1,1,1,2,2,2,2,2,2,2,2,2,2,2,2,2,2,2,1,1,1
1,1,1,2,2,2,2,2,2,2,2,2,2,2,2,2,2,2,1,1,1
1,1,1,2,2,2,2,2,2,2,2,2,2,2,2,2,2,2,1,1,1
1,1,1,2,2,2,2,2,2,2,2,2,2,2,2,2,2,2,1,1,1
1,1,1,2,2,2,2,2,2,2,2,2,2,2,2,2,2,2,1,1,1
1,1,1,2,2,2,2,2,2,2,2,2,2,2,2,2,2,2,1,1,1
1,1,1,2,2,2,2,2,2,2,2,2,2,2,2,2,2,2,1,1,1
1,1,1,2,2,2,2,2,2,2,2,2,2,2,2,2,2,2,1,1,1
1,1,1,2,2,2,2,2,2,2,2,2,2,2,2,2,2,2,1,1,1
1,1,1,2,2,2,2,2,2,2,2,2,2,2,2,2,2,2,1,1,1
1,1,1,2,2,2,2,2,2,2,2,2,2,2,2,2,2,2,1,1,1
1,1,1,2,2,2,2,2,2,2,2,2,2,2,2,2,2,2,1,1,1
1,1,1,2,2,2,2,2,2,2,0,0,2,2,2,2,2,2,1,1,1
1,1,1,2,2,2,2,2,2,2,2,2,2,2,2,2,2,2,1,1,1
1,1,1,2,2,2,2,2,2,2,2,2,2,2,2,2,2,2,1,1,1
1,1,1,1,1,1,1,1,1,1,1,1,1,1,1,1,1,1,1,1,1
endlayer

layer
0,0,0,0,0,0,0,0,0,0,0,0,0,0,0,0,0,0,0,0,0
0,0,0,0,0,0,0,0,0,0,0,0,0,0,0,0,0,0,0,0,0
0,0,0,0,0,0,0,0,0,0,0,0,0,0,0,0,0,0,0,0,0
0,0,0,0,0,0,0,0,0,0,0,0,0,0,0,0,0,0,0,0,0
0,0,0,0,0,0,0,0,0,0,0,0,0,0,0,0,0,0,0,0,0
2,2,2,2,2,2,2,2,2,2,2,2,2,2,2,2,2,2,2,2,2
2,8,8,8,8,8,8,8,8,8,8,8,8,8,8,8,8,8,8,8,2
2,8,8,9,8,7,7,8,8,8,8,8,8,8,7,7,8,9,8,8,2
2,8,8,8,8,7,7,8,8,9,8,8,8,8,7,7,8,8,8,8,2
2,8,8,9,8,7,7,8,8,8,8,8,8,8,7,7,8,9,8,8,2
2,8,8,8,8,7,7,8,8,8,8,8,8,8,7,7,8,8,8,8,2
2,8,8,9,8,7,7,8,9,8,8,8,9,8,7,7,8,9,8,8,2
2,8,8,8,8,7,7,8,8,8,8,8,8,8,7,7,8,8,8,8,2
2,8,8,9,8,7,7,8,9,8,8,8,9,8,7,7,8,9,8,8,2
2,8,8,8,8,7,7,8,8,8,8,8,8,8,7,7,8,8,8,8,2
2,8,8,9,8,7,7,8,9,8,8,8,9,8,7,7,8,9,8,8,2
2,8,8,8,8,7,7,8,8,8,8,8,8,8,7,7,8,8,8,8,2
7,7,7,7,7,7,7,7,7,7,7,7,7,7,7,7,7,7,7,7,7
7,7,7,7,7,7,7,7,7,7,7,7,7,7,7,7,7,7,7,7,7
2,8,8,8,8,7,7,8,8,8,8,8,8,8,7,7,8,8,8,8,2
2,8,8,9,8,7,7,8,9,8,8,8,9,8,7,7,8,9,8,8,2
2,8,8,8,8,7,7,8,8,8,8,8,8,8,7,7,8,8,8,8,2
2,8,8,9,8,7,7,8,9,8,8,8,9,8,7,7,8,9,8,8,2
2,8,8,8,8,7,7,8,8,8,8,8,8,8,7,7,8,8,8,8,2
2,8,8,9,8,7,7,8,9,8,8,8,9,8,7,7,8,9,8,8,2
2,8,8,8,8,7,7,8,8,8,8,8,8,8,7,7,8,8,8,8,2
2,8,8,9,8,7,7,8,8,8,8,8,8,8,7,7,8,9,8,8,2
2,8,8,8,8,7,7,8,8,8,0,0,8,8,7,7,8,8,8,8,2
2,8,8,9,8,7,7,8,8,8,8,8,8,8,7,7,8,9,8,8,2
2,8,8,8,8,8,8,8,8,8,8,8,8,8,8,8,8,8,8,8,2
2,2,2,2,2,2,2,2,2,2,2,2,2,2,2,2,2,2,2,2,2
endlayer

layer
0,0,0,0,0,0,0,0,0,0,0,0,0,0,0,0,0,0,0,0,0
0,0,0,0,0,0,0,0,0,0,0,0,0,0,0,0,0,0,0,0,0
0,0,0,0,0,0,0,0,0,0,0,0,0,0,0,0,0,0,0,0,0
0,0,0,0,0,0,0,0,0,0,0,0,0,0,0,0,0,0,0,0,0
0,0,0,0,0,0,0,0,0,0,0,0,0,0,0,0,0,0,0,0,0
2,2,2,2,2,2,2,2,2,2,2,2,2,2,2,2,2,2,2,2,2
2,10,10,10,10,10,10,10,10,10,10,10,10,10,13,10,10,10,10,10,2
2,10,11,12,0,0,0,0,14,14,14,0,0,0,0,0,0,12,11,10,2
2,10,0,0,0,0,0,0,0,11,14,0,0,0,0,0,0,0,0,10,2
2,10,11,12,0,0,0,0,14,14,14,0,0,0,0,0,0,12,11,10,2
2,10,0,0,0,0,0,0,0,0,0,0,0,0,0,0,0,0,0,10,2
2,10,11,12,0,0,0,0,12,11,0,11,12,0,0,0,0,12,11,10,2
2,10,0,0,0,0,0,0,0,0,0,0,0,0,0,0,0,0,0,10,2
2,10,11,12,0,0,0,0,12,11,0,11,12,0,0,0,0,12,11,10,2
2,10,0,0,0,0,0,0,0,0,0,0,0,0,0,0,0,0,0,10,2
2,10,11,12,0,0,0,0,12,11,0,11,12,0,0,0,0,12,11,10,2
2,10,0,0,0,0,0,0,0,0,0,0,0,0,0,0,0,0,0,10,2
0,0,0,0,0,0,0,0,0,0,0,0,0,0,0,0,0,0,0,0,0
0,0,0,0,0,0,0,0,0,0,0,0,0,0,0,0,0,0,0,0,0
2,10,0,0,0,0,0,0,0,0,0,0,0,0,0,0,0,0,0,10,2
2,10,11,12,0,0,0,0,12,11,0,11,12,0,0,0,0,12,11,10,2
2,10,0,0,0,0,0,0,0,0,0,0,0,0,0,0,0,0,0,10,2
2,10,11,12,0,0,0,0,12,11,0,11,12,0,0,0,0,12,11,10,2
2,10,0,0,0,0,0,0,0,0,0,0,0,0,0,0,0,0,0,10,2
2,10,11,12,0,0,0,0,12,11,0,11,12,0,0,0,0,12,11,10,2
2,10,0,0,0,0,0,0,0,0,0,0,0,0,0,0,0,0,0,10,2
2,10,11,12,0,0,0,0,0,0,14,14,14,0,0,0,0,12,11,10,2
2,10,0,0,0,0,0,0,0,0,14,11,0,0,0,0,0,0,0,10,2
2,10,11,12,0,0,0,13,0,0,14,14,14,0,0,0,0,12,11,10,2
2,10,10,10,10,10,10,10,10,10,10,10,10,10,10,10,10,10,10,10,2
2,2,2,2,2,2,2,2,2,2,2,2,2,2,2,2,2,2,2,2,2
endlayer

layer
0,0,0,0,0,0,0,0,0,0,0,0,0,0,0,0,0,0,0,0,0
0,0,0,0,0,0,0,0,0,0,0,0,0,0,0,0,0,0,0,0,0
0,0,0,0,0,0,0,0,0,0,0,0,0,0,0,0,0,0,0,0,0
0,0,0,0,0,0,0,0,0,0,0,0,0,0,0,0,0,0,0,0,0
0,0,0,0,0,0,0,0,0,0,0,0,0,0,0,0,0,0,0,0,0
15,15,15,15,15,15,15,15,15,15,15,15,15,15,15,15,15,15,15,15,15
15,10,0,0,0,0,0,0,0,0,0,0,0,0,13,0,0,0,0,10,15
15,0,0,0,0,0,0,0,14,14,14,0,0,0,0,0,0,0,0,0,15
15,0,0,0,0,0,0,0,0,11,14,0,0,0,0,0,0,0,0,0,15
15,0,0,0,0,0,0,0,14,14,14,0,0,0,0,0,0,0,0,0,15
15,0,0,0,0,0,0,0,0,0,0,0,0,0,0,0,0,0,0,0,15
15,0,0,0,0,0,0,0,0,0,0,0,0,0,0,0,0,0,0,0,15
15,0,0,0,0,0,0,0,0,0,0,0,0,0,0,0,0,0,0,0,15
15,0,0,0,0,0,0,0,0,0,0,0,0,0,0,0,0,0,0,0,15
15,0,0,0,0,0,0,0,0,0,0,0,0,0,0,0,0,0,0,0,15
15,0,0,0,0,0,0,0,0,0,0,0,0,0,0,0,0,0,0,0,15
2,10,0,0,0,0,0,0,0,0,0,0,0,0,0,0,0,0,0,10,2
0,0,0,0,0,0,0,0,0,0,0,0,0,0,0,0,0,0,0,0,0
0,0,0,0,0,0,0,0,0,0,0,0,0,0,0,0,0,0,0,0,0
2,10,0,0,0,0,0,0,0,0,0,0,0,0,0,0,0,0,0,10,2
15,0,0,0,0,0,0,0,0,0,0,0,0,0,0,0,0,0,0,0,15
15,0,0,0,0,0,0,0,0,0,0,0,0,0,0,0,0,0,0,0,15
15,0,0,0,0,0,0,0,0,0,0,0,0,0,0,0,0,0,0,0,15
15,0,0,0,0,0,0,0,0,0,0,0,0,0,0,0,0,0,0,0,15
15,0,0,0,0,0,0,0,0,0,0,0,0,0,0,0,0,0,0,0,15
15,0,0,0,0,0,0,0,0,0,0,0,0,0,0,0,0,0,0,0,15
15,0,0,0,0,0,0,0,0,0,14,14,14,0,0,0,0,0,0,0,15
15,0,0,0,0,0,0,0,0,0,14,11,0,0,0,0,0,0,0,0,15
15,0,0,0,0,0,0,13,0,0,14,14,14,0,0,0,0,0,0,0,15
15,10,0,0,0,0,0,0,0,0,0,0,0,0,0,0,0,0,0,10,15
15,15,15,15,15,15,15,15,15,15,15,15,15,15,15,15,15,15,15,15,15
endlayer

layer
0,0,0,0,0,0,0,0,0,0,0,0,0,0,0,0,0,0,0,0,0
0,0,0,0,0,0,0,0,0,0,0,0,0,0,0,0,0,0,0,0,0
0,0,0,0,0,0,0,0,0,0,0,0,0,0,0,0,0,0,0,0,0
0,0,0,0,0,0,0,0,0,0,0,0,0,0,0,0,0,0,0,0,0
0,0,0,0,0,0,0,0,0,0,0,0,0,0,0,0,0,0,0,0,0
16,16,16,16,16,16,16,16,16,16,16,16,16,16,16,16,16,16,16,16,16
16,0,0,0,0,0,0,0,0,0,0,0,0,0,13,0,0,0,0,0,16
16,0,0,0,0,0,0,0,0,14,0,0,0,0,0,0,0,0,0,0,16
16,0,0,0,0,0,0,0,14,0,14,0,0,0,0,0,0,0,0,0,16
16,0,0,0,0,0,0,0,0,14,0,0,0,0,0,0,0,0,0,0,16
16,0,0,0,0,0,0,0,0,0,0,0,0,0,0,0,0,0,0,0,16
16,0,0,0,0,0,0,0,0,0,0,0,0,0,0,0,0,0,0,0,16
16,0,0,0,0,0,0,0,0,0,0,0,0,0,0,0,0,0,0,0,16
16,0,0,0,0,0,0,0,0,0,0,0,0,0,0,0,0,0,0,0,16
16,0,0,0,0,0,0,0,0,0,0,0,0,0,0,0,0,0,0,0,16
16,0,0,0,0,0,0,0,0,0,0,0,0,0,0,0,0,0,0,0,16
2,0,0,0,0,0,0,0,0,0,0,0,0,0,0,0,0,0,0,0,2
15,0,0,0,0,0,0,0,0,0,0,0,0,0,0,0,0,0,0,0,15
15,0,0,0,0,0,0,0,0,0,0,0,0,0,0,0,0,0,0,0,15
2,0,0,0,0,0,0,0,0,0,0,0,0,0,0,0,0,0,0,0,2
16,0,0,0,0,0,0,0,0,0,0,0,0,0,0,0,0,0,0,0,16
16,0,0,0,0,0,0,0,0,0,0,0,0,0,0,0,0,0,0,0,16
16,0,0,0,0,0,0,0,0,0,0,0,0,0,0,0,0,0,0,0,16
16,0,0,0,0,0,0,0,0,0,0,0,0,0,0,0,0,0,0,0,16
16,0,0,0,0,0,0,0,0,0,0,0,0,0,0,0,0,0,0,0,16
16,0,0,0,0,0,0,0,0,0,0,0,0,0,0,0,0,0,0,0,16
16,0,0,0,0,0,0,0,0,0,0,14,0,0,0,0,0,0,0,0,16
16,0,0,0,0,0,0,0,0,0,14,0,14,0,0,0,0,0,0,0,16
16,0,0,0,0,0,0,13,0,0,0,14,0,0,0,0,0,0,0,0,16
16,0,0,0,0,0,0,0,0,0,0,0,0,0,0,0,0,0,0,0,16
16,16,16,16,16,16,16,16,16,16,16,16,16,16,16,16,16,16,16,16,16
endlayer

layer
0,0,0,0,0,0,0,0,0,0,0,0,0,0,0,0,0,0,0,0,0
0,0,0,0,0,0,0,0,0,0,0,0,0,0,0,0,0,0,0,0,0
0,0,0,0,0,0,0,0,0,0,0,0,0,0,0,0,0,0,0,0,0
0,0,0,0,0,0,0,0,0,0,0,0,0,0,0,0,0,0,0,0,0
0,0,0,0,0,0,0,0,0,0,0,0,0,0,0,0,0,0,0,0,0
0,0,0,0,0,0,0,0,0,0,0,0,0,0,0,0,0,0,0,0,0
0,0,0,0,0,0,0,0,0,0,0,0,0,0,13,0,0,0,0,0,0
0,0,0,0,0,0,0,0,0,0,0,0,0,0,0,0,0,0,0,0,0
0,0,0,0,0,0,0,0,0,14,0,0,0,0,0,0,0,0,0,0,0
0,0,0,0,0,0,0,0,0,0,0,0,0,0,0,0,0,0,0,0,0
0,0,0,0,0,0,0,0,0,0,0,0,0,0,0,0,0,0,0,0,0
0,0,0,0,0,0,0,0,0,0,0,0,0,0,0,0,0,0,0,0,0
0,0,0,0,0,0,0,0,0,0,0,0,0,0,0,0,0,0,0,0,0
0,0,0,0,0,0,0,0,0,0,0,0,0,0,0,0,0,0,0,0,0
0,0,0,0,0,0,0,0,0,0,0,0,0,0,0,0,0,0,0,0,0
0,0,0,0,0,0,0,0,0,0,0,0,0,0,0,0,0,0,0,0,0
0,0,0,0,0,0,0,0,0,0,0,0,0,0,0,0,0,0,0,0,0
2,0,0,0,0,0,0,0,0,0,0,0,0,0,0,0,0,0,0,0,2
2,0,0,0,0,0,0,0,0,0,0,0,0,0,0,0,0,0,0,0,2
0,0,0,0,0,0,0,0,0,0,0,0,0,0,0,0,0,0,0,0,0
0,0,0,0,0,0,0,0,0,0,0,0,0,0,0,0,0,0,0,0,0
0,0,0,0,0,0,0,0,0,0,0,0,0,0,0,0,0,0,0,0,0
0,0,0,0,0,0,0,0,0,0,0,0,0,0,0,0,0,0,0,0,0
0,0,0,0,0,0,0,0,0,0,0,0,0,0,0,0,0,0,0,0,0
0,0,0,0,0,0,0,0,0,0,0,0,0,0,0,0,0,0,0,0,0
0,0,0,0,0,0,0,0,0,0,0,0,0,0,0,0,0,0,0,0,0
0,0,0,0,0,0,0,0,0,0,0,0,0,0,0,0,0,0,0,0,0
0,0,0,0,0,0,0,0,0,0,0,14,0,0,0,0,0,0,0,0,0
0,0,0,0,0,0,0,13,0,0,0,0,0,0,0,0,0,0,0,0,0
0,0,0,0,0,0,0,0,0,0,0,0,0,0,0,0,0,0,0,0,0
0,0,0,0,0,0,0,0,0,0,0,0,0,0,0,0,0,0,0,0,0
endlayer

layer
0,0,0,0,0,0,0,0,0,0,0,0,0,0,0,0,0,0,0,0,0
0,0,0,0,0,0,0,0,0,0,0,0,0,0,0,0,0,0,0,0,0
0,0,0,0,0,0,0,0,0,0,0,0,0,0,0,0,0,0,0,0,0
0,0,0,0,0,0,0,0,0,0,0,0,0,0,0,0,0,0,0,0,0
0,0,0,0,0,0,0,0,0,0,0,0,0,0,0,0,0,0,0,0,0
0,0,0,0,0,0,0,0,0,0,0,0,0,0,0,0,0,0,0,0,0
0,0,0,0,0,0,0,0,0,0,0,0,0,0,13,0,0,0,0,0,0
0,0,0,0,0,0,0,0,0,0,0,0,0,17,17,0,0,0,0,0,0
0,0,0,0,0,0,0,0,0,0,0,0,10,17,17,0,0,0,0,0,0
0,0,0,0,0,0,0,0,0,0,0,0,0,10,0,0,0,0,0,0,0
0,0,0,0,0,0,0,0,0,0,0,0,10,10,10,0,0,0,0,0,0
0,0,0,0,0,0,0,0,0,0,0,0,0,10,0,0,0,0,0,0,0
0,0,0,0,0,0,0,0,0,0,0,0,0,0,0,0,0,0,0,0,0
0,0,0,0,0,0,0,0,0,0,0,0,0,0,0,0,0,0,0,0,0
0,0,0,0,0,0,0,0,0,0,0,0,0,0,0,0,0,0,0,0,0
0,0,0,0,0,0,0,0,0,0,0,0,0,0,0,0,0,0,0,0,0
0,0,0,0,0,0,0,0,0,0,0,0,0,0,0,0,0,0,0,0,0
0,0,0,0,0,0,0,0,0,0,0,0,0,0,0,0,0,0,0,0,0
0,0,0,0,0,0,0,0,0,0,0,0,0,0,0,0,0,0,0,0,0
0,0,0,0,0,0,0,0,0,0,0,0,0,0,0,0,0,0,0,0,0
0,0,0,0,0,0,0,0,0,0,0,0,0,0,0,0,0,0,0,0,0
0,0,0,0,0,0,0,0,0,0,0,0,0,0,0,0,0,0,0,0,0
0,0,0,0,0,0,0,0,0,0,0,0,0,0,0,0,0,0,0,0,0
0,0,0,0,0,0,0,0,0,0,0,0,0,0,0,0,0,0,0,0,0
0,0,0,0,0,0,0,0,0,0,0,0,0,0,0,0,0,0,0,0,0
0,0,0,0,0,0,0,0,0,0,0,0,0,0,0,0,0,0,0,0,0
0,0,0,0,0,10,10,10,10,10,0,0,0,0,0,0,0,0,0,0,0
0,0,0,0,0,10,10,10,10,10,0,0,0,0,0,0,0,0,0,0,0
0,0,0,0,0,10,10,13,10,10,0,0,0,0,0,0,0,0,0,0,0
0,0,0,0,0,10,10,10,10,10,0,0,0,0,0,0,0,0,0,0,0
0,0,0,0,0,0,10,10,10,0,0,0,0,0,0,0,0,0,0,0,0
endlayer

layer
0,0,0,0,0,0,0,0,0,0,0,0,0,0,0,0,0,0,0,0,0
0,0,0,0,0,0,0,0,0,0,0,0,0,0,0,0,0,0,0,0,0
0,0,0,0,0,0,0,0,0,0,0,0,0,0,0,0,0,0,0,0,0
0,0,0,0,0,0,0,0,0,0,0,0,0,0,0,0,0,0,0,0,0
0,0,0,0,0,0,0,0,0,0,0,0,0,0,0,0,0,0,0,0,0
0,0,0,0,0,0,0,0,0,0,0,0,0,0,0,0,0,0,0,0,0
0,0,0,0,0,0,0,0,0,0,0,0,10,10,13,0,0,0,0,0,0
0,0,0,0,0,0,0,0,0,0,0,10,10,10,10,10,0,0,0,0,0
0,0,0,0,0,0,0,0,0,0,0,10,10,10,10,10,0,0,0,0,0
0,0,0,0,0,0,0,0,0,0,0,10,17,10,17,10,0,0,0,0,0
0,0,0,0,0,0,0,0,0,0,0,10,10,10,17,10,0,0,0,0,0
0,0,0,0,0,0,0,0,0,0,0,10,10,10,10,10,0,0,0,0,0
0,0,0,0,0,0,0,0,0,0,0,0,10,10,10,0,0,0,0,0,0
0,0,0,0,0,0,0,0,0,0,0,0,0,0,0,0,0,0,0,0,0
0,0,0,0,0,0,0,0,0,0,0,0,0,0,0,0,0,0,0,0,0
0,0,0,0,0,0,0,0,0,0,0,0,0,0,0,0,0,0,0,0,0
0,0,0,0,0,0,0,0,0,0,0,0,0,0,0,0,0,0,0,0,0
0,0,0,0,0,0,0,0,0,0,0,0,0,0,0,0,0,0,0,0,0
0,0,0,0,0,0,0,0,0,0,0,0,0,0,0,0,0,0,0,0,0
0,0,0,0,0,0,0,0,0,0,0,0,0,0,0,0,0,0,0,0,0
0,0,0,0,0,0,0,0,0,0,0,0,0,0,0,0,0,0,0,0,0
0,0,0,0,0,0,0,0,0,0,0,0,0,0,0,0,0,0,0,0,0
0,0,0,0,0,0,0,0,0,0,0,0,0,0,0,0,0,0,0,0,0
0,0,0,0,0,0,0,0,0,0,0,0,0,0,0,0,0,0,0,0,0
0,0,0,0,0,0,0,0,0,0,0,0,0,0,0,0,0,0,0,0,0
0,0,0,0,0,0,0,0,0,0,0,0,0,0,0,0,0,0,0,0,0
0,0,0,0,0,0,10,10,10,0,0,0,0,0,0,0,0,0,0,0,0
0,0,0,0,0,10,10,10,10,10,0,0,0,0,0,0,0,0,0,0,0
0,0,0,0,0,10,10,13,10,10,0,0,0,0,0,0,0,0,0,0,0
0,0,0,0,0,10,10,10,10,10,0,0,0,0,0,0,0,0,0,0,0
0,0,0,0,0,0,10,10,10,10,0,0,0,0,0,0,0,0,0,0,0
endlayer

layer
0,0,0,0,0,0,0,0,0,0,0,0,0,0,0,0,0,0,0,0,0
0,0,0,0,0,0,0,0,0,0,0,0,0,0,0,0,0,0,0,0,0
0,0,0,0,0,0,0,0,0,0,0,0,0,0,0,0,0,0,0,0,0
0,0,0,0,0,0,0,0,0,0,0,0,0,0,0,0,0,0,0,0,0
0,0,0,0,0,0,0,0,0,0,0,0,0,0,0,0,17,0,0,0,0
0,0,0,0,0,0,0,0,0,0,0,0,0,0,0,17,0,0,0,0,0
0,0,0,0,0,0,0,0,0,0,0,0,10,10,13,10,10,0,0,0,0
0,0,0,0,0,0,0,0,0,0,0,10,10,17,10,17,18,10,0,0,0
0,0,0,0,0,0,0,0,0,0,10,10,17,10,10,10,10,0,0,0,0
0,0,0,0,0,0,0,0,0,0,10,10,10,10,10,10,10,0,0,0,0
0,0,0,0,0,0,0,0,0,0,10,10,10,10,10,10,10,0,0,0,0
0,0,0,0,0,0,0,0,0,0,0,10,10,10,10,10,10,0,0,0,0
0,0,0,0,0,0,0,0,0,0,0,0,10,10,10,10,0,0,0,0,0
0,0,0,0,0,0,0,0,0,0,0,0,0,0,0,0,0,0,0,0,0
0,0,0,0,0,0,0,0,0,0,0,0,0,0,0,0,0,0,0,0,0
0,0,0,0,0,0,0,0,0,0,0,0,0,0,0,0,0,0,0,0,0
0,0,0,0,0,0,0,0,0,0,0,0,0,0,0,0,0,0,0,0,0
0,0,0,0,0,0,0,0,0,0,0,0,0,0,0,0,0,0,0,0,0
0,0,0,0,0,0,0,0,0,0,0,0,0,0,0,0,0,0,0,0,0
0,0,0,0,0,0,0,0,0,0,0,0,0,0,0,0,0,0,0,0,0
0,0,0,0,0,0,0,0,0,0,0,0,0,0,0,0,0,0,0,0,0
0,0,0,0,0,0,0,0,0,0,0,0,0,0,0,0,0,0,0,0,0
0,0,0,0,0,0,0,0,0,0,0,0,0,0,0,0,0,0,0,0,0
0,0,0,0,0,0,0,0,0,0,0,0,0,0,0,0,0,0,0,0,0
0,0,0,0,0,0,0,0,0,0,0,0,0,0,0,0,0,0,0,0,0
0,0,0,0,0,0,0,0,0,0,0,0,0,0,0,0,0,0,0,0,0
0,0,0,0,0,0,0,0,0,0,0,0,0,0,0,0,0,0,0,0,0
0,0,0,0,0,0,10,10,10,0,0,0,0,0,0,0,0,0,0,0,0
0,0,0,0,0,0,10,13,10,0,0,0,0,0,0,0,0,0,0,0,0
0,0,0,0,0,0,0,10,0,0,0,0,0,0,0,0,0,0,0,0,0
0,0,0,0,0,0,0,0,0,0,0,0,0,0,0,0,0,0,0,0,0
endlayer

layer
0,0,0,0,0,0,0,0,0,0,0,0,0,0,0,0,0,0,0,0,0
0,0,0,0,0,0,0,0,0,0,0,0,0,0,0,0,0,0,0,0,0
0,0,0,0,0,0,0,0,0,0,0,0,0,0,0,0,0,10,0,0,0
0,0,0,0,0,0,0,0,0,0,0,0,0,0,0,0,10,17,10,0,0
0,0,0,0,0,0,0,0,0,0,0,0,0,0,0,0,0,10,0,0,0
0,0,0,0,0,0,0,0,0,0,0,0,18,0,10,10,10,10,0,0,0
0,0,0,0,0,0,0,0,0,0,0,0,0,18,13,10,10,10,10,0,0
0,0,0,0,0,0,0,0,0,0,0,10,10,10,17,10,10,10,10,0,0
0,0,0,0,0,0,0,0,0,0,10,10,10,10,17,10,10,10,10,0,0
0,0,0,0,0,0,0,0,0,0,10,17,10,10,10,10,10,10,0,0,0
0,0,0,0,0,0,0,0,0,0,10,10,10,10,10,10,10,0,0,0,0
0,0,0,0,0,0,0,0,0,0,0,10,10,10,10,10,10,0,0,0,0
0,0,0,0,0,0,0,0,0,0,0,0,0,10,10,10,0,0,0,0,0
0,0,0,0,0,0,0,0,0,0,0,0,0,0,0,0,0,0,0,0,0
0,0,0,0,0,0,0,0,0,0,0,0,0,0,0,0,0,0,0,0,0
0,0,0,0,0,0,0,0,0,0,0,0,0,0,0,0,0,0,0,0,0
0,0,0,0,0,0,0,0,0,0,0,0,0,0,0,0,0,0,0,0,0
0,0,0,0,0,0,0,0,0,0,0,0,0,0,0,0,0,0,0,0,0
0,0,0,0,0,0,0,0,0,0,0,0,0,0,0,0,0,0,0,0,0
0,0,0,0,0,0,0,0,0,0,0,0,0,0,0,0,0,0,0,0,0
0,0,0,0,0,0,0,0,0,0,0,0,0,0,0,0,0,0,0,0,0
0,0,0,0,0,0,0,0,0,0,0,0,0,0,0,0,0,0,0,0,0
0,0,0,0,0,0,0,0,0,0,0,0,0,0,0,0,0,0,0,0,0
0,0,0,0,0,0,0,0,0,0,0,0,0,0,0,0,0,0,0,0,0
0,0,0,0,0,0,0,0,0,0,0,0,0,0,0,0,0,0,0,0,0
0,0,0,0,0,0,0,0,0,0,0,0,0,0,0,0,0,0,0,0,0
0,0,0,0,0,0,0,0,0,0,0,0,0,0,0,0,0,0,0,0,0
0,0,0,0,0,0,0,10,0,0,0,0,0,0,0,0,0,0,0,0,0
0,0,0,0,0,0,10,10,10,0,0,0,0,0,0,0,0,0,0,0,0
0,0,0,0,0,0,0,10,0,0,0,0,0,0,0,0,0,0,0,0,0
0,0,0,0,0,0,0,0,0,0,0,0,0,0,0,0,0,0,0,0,0
endlayer

layer
0,0,0,0,0,0,0,0,0,0,0,0,0,0,0,0,0,0,0,0,0
0,0,0,0,0,0,0,0,0,0,0,0,0,0,0,0,10,10,10,0,0
0,0,0,0,0,0,0,0,0,0,0,0,0,0,0,10,10,10,10,10,0
0,0,0,0,0,0,0,0,0,0,0,0,0,0,0,10,10,10,10,10,0
0,0,0,0,0,0,0,0,0,0,0,10,0,0,0,10,10,10,10,10,0
0,0,0,0,0,0,0,0,0,0,10,18,10,17,10,10,10,10,10,0,0
0,0,0,0,0,0,0,0,0,0,0,10,0,10,13,10,10,10,10,0,0
0,0,0,0,0,0,0,0,0,0,10,10,10,10,10,10,10,10,10,0,0
0,0,0,0,0,0,0,0,0,10,10,10,10,10,10,10,10,10,10,0,0
0,0,0,0,0,0,0,0,0,10,10,10,10,10,17,10,10,10,0,0,0
0,0,0,0,0,0,0,0,0,10,10,10,10,10,17,10,0,0,0,0,0
0,0,0,0,0,0,0,0,0,0,10,10,10,0,10,0,0,0,0,0,0
0,0,0,0,0,0,0,0,0,0,0,0,0,0,0,0,0,0,0,0,0
0,0,0,0,0,0,0,0,0,0,0,0,0,0,0,0,0,0,0,0,0
0,0,0,0,0,0,0,0,0,0,0,0,0,0,0,0,0,0,0,0,0
0,0,0,0,0,0,0,0,0,0,0,0,0,0,0,0,0,0,0,0,0
0,0,0,0,0,0,0,0,0,0,0,0,0,0,0,0,0,0,0,0,0
0,0,0,0,0,0,0,0,0,0,0,0,0,0,0,0,0,0,0,0,0
0,0,0,0,0,0,0,0,0,0,0,0,0,0,0,0,0,0,0,0,0
0,0,0,0,0,0,0,0,0,0,0,0,0,0,0,0,0,0,0,0,0
0,0,0,0,0,0,0,0,0,0,0,0,0,0,0,0,0,0,0,0,0
0,0,0,0,0,0,0,0,0,0,0,0,0,0,0,0,0,0,0,0,0
0,0,0,0,0,0,0,0,0,0,0,0,0,0,0,0,0,0,0,0,0
0,0,0,0,0,0,0,0,0,0,0,0,0,0,0,0,0,0,0,0,0
0,0,0,0,0,0,0,0,0,0,0,0,0,0,0,0,0,0,0,0,0
0,0,0,0,0,0,0,0,0,0,0,0,0,0,0,0,0,0,0,0,0
0,0,0,0,0,0,0,0,0,0,0,0,0,0,0,0,0,0,0,0,0
0,0,0,0,0,0,0,0,0,0,0,0,0,0,0,0,0,0,0,0,0
0,0,0,0,0,0,0,0,0,0,0,0,0,0,0,0,0,0,0,0,0
0,0,0,0,0,0,0,0,0,0,0,0,0,0,0,0,0,0,0,0,0
0,0,0,0,0,0,0,0,0,0,0,0,0,0,0,0,0,0,0,0,0
endlayer

layer
0,0,0,0,0,0,0,0,0,0,0,0,0,0,0,0,0,0,0,0,0
0,0,0,0,0,0,0,0,0,0,0,0,0,0,0,0,10,10,10,0,0
0,0,0,0,0,0,0,0,0,0,0,0,0,0,0,10,10,10,10,10,0
0,0,0,0,0,0,0,0,0,0,10,10,10,0,0,10,10,10,10,10,0
0,0,0,0,0,0,0,0,0,10,10,10,17,10,10,17,10,10,10,10,0
0,0,0,0,0,0,0,0,0,10,10,10,10,10,17,10,10,10,10,0,0
0,0,0,0,0,0,0,0,0,10,10,10,10,10,13,10,10,0,0,0,0
0,0,0,0,0,0,0,0,0,0,10,10,10,0,10,10,10,10,0,0,0
0,0,0,0,0,0,0,0,0,10,10,10,10,10,10,10,10,0,0,0,0
0,0,0,0,0,0,0,0,0,10,10,10,10,10,10,10,10,0,0,0,0
0,0,0,0,0,0,0,0,0,10,10,10,10,10,10,10,10,0,0,0,0
0,0,0,0,0,0,0,0,0,0,10,10,10,10,10,10,10,0,0,0,0
0,0,0,0,0,0,0,0,0,0,0,0,0,10,10,10,0,0,0,0,0
0,0,0,0,0,0,0,0,0,0,0,0,0,0,0,0,0,0,0,0,0
0,0,0,0,0,0,0,0,0,0,0,0,0,0,0,0,0,0,0,0,0
0,0,0,0,0,0,0,0,0,0,0,0,0,0,0,0,0,0,0,0,0
0,0,0,0,0,0,0,0,0,0,0,0,0,0,0,0,0,0,0,0,0
0,0,0,0,0,0,0,0,0,0,0,0,0,0,0,0,0,0,0,0,0
0,0,0,0,0,0,0,0,0,0,0,0,0,0,0,0,0,0,0,0,0
0,0,0,0,0,0,0,0,0,0,0,0,0,0,0,0,0,0,0,0,0
0,0,0,0,0,0,0,0,0,0,0,0,0,0,0,0,0,0,0,0,0
0,0,0,0,0,0,0,0,0,0,0,0,0,0,0,0,0,0,0,0,0
0,0,0,0,0,0,0,0,0,0,0,0,0,0,0,0,0,0,0,0,0
0,0,0,0,0,0,0,0,0,0,0,0,0,0,0,0,0,0,0,0,0
0,0,0,0,0,0,0,0,0,0,0,0,0,0,0,0,0,0,0,0,0
0,0,0,0,0,0,0,0,0,0,0,0,0,0,0,0,0,0,0,0,0
0,0,0,0,0,0,0,0,0,0,0,0,0,0,0,0,0,0,0,0,0
0,0,0,0,0,0,0,0,0,0,0,0,0,0,0,0,0,0,0,0,0
0,0,0,0,0,0,0,0,0,0,0,0,0,0,0,0,0,0,0,0,0
0,0,0,0,0,0,0,0,0,0,0,0,0,0,0,0,0,0,0,0,0
0,0,0,0,0,0,0,0,0,0,0,0,0,0,0,0,0,0,0,0,0
endlayer

layer
0,0,0,0,0,0,0,0,0,0,0,0,0,0,0,0,0,0,0,0,0
0,0,0,0,0,0,0,0,0,0,0,0,0,0,0,0,0,0,0,0,0
0,0,0,0,0,0,0,0,0,0,0,10,10,10,10,10,10,10,0,0,0
0,0,0,0,0,0,0,0,0,0,10,10,10,10,10,10,10,10,10,0,0
0,0,0,0,0,0,0,0,0,10,10,10,10,10,10,10,10,10,0,0,0
0,0,0,0,0,0,0,0,0,10,10,10,10,10,10,10,10,10,0,0,0
0,0,0,0,0,0,0,0,0,10,10,10,10,10,13,10,10,0,0,0,0
0,0,0,0,0,0,0,0,0,0,10,10,10,0,10,0,0,0,0,0,0
0,0,0,0,0,0,0,0,0,0,0,10,0,10,10,10,0,0,0,0,0
0,0,0,0,0,0,0,0,0,0,10,10,10,10,10,10,10,0,0,0,0
0,0,0,0,0,0,0,0,0,0,0,10,10,10,10,10,10,0,0,0,0
0,0,0,0,0,0,0,0,0,0,0,0,10,10,10,10,10,0,0,0,0
0,0,0,0,0,0,0,0,0,0,0,0,0,10,10,10,0,0,0,0,0
0,0,0,0,0,0,0,0,0,0,0,0,0,0,0,0,0,0,0,0,0
0,0,0,0,0,0,0,0,0,0,0,0,0,0,0,0,0,0,0,0,0
0,0,0,0,0,0,0,0,0,0,0,0,0,0,0,0,0,0,0,0,0
0,0,0,0,0,0,0,0,0,0,0,0,0,0,0,0,0,0,0,0,0
0,0,0,0,0,0,0,0,0,0,0,0,0,0,0,0,0,0,0,0,0
0,0,0,0,0,0,0,0,0,0,0,0,0,0,0,0,0,0,0,0,0
0,0,0,0,0,0,0,0,0,0,0,0,0,0,0,0,0,0,0,0,0
0,0,0,0,0,0,0,0,0,0,0,0,0,0,0,0,0,0,0,0,0
0,0,0,0,0,0,0,0,0,0,0,0,0,0,0,0,0,0,0,0,0
0,0,0,0,0,0,0,0,0,0,0,0,0,0,0,0,0,0,0,0,0
0,0,0,0,0,0,0,0,0,0,0,0,0,0,0,0,0,0,0,0,0
0,0,0,0,0,0,0,0,0,0,0,0,0,0,0,0,0,0,0,0,0
0,0,0,0,0,0,0,0,0,0,0,0,0,0,0,0,0,0,0,0,0
0,0,0,0,0,0,0,0,0,0,0,0,0,0,0,0,0,0,0,0,0
0,0,0,0,0,0,0,0,0,0,0,0,0,0,0,0,0,0,0,0,0
0,0,0,0,0,0,0,0,0,0,0,0,0,0,0,0,0,0,0,0,0
0,0,0,0,0,0,0,0,0,0,0,0,0,0,0,0,0,0,0,0,0
0,0,0,0,0,0,0,0,0,0,0,0,0,0,0,0,0,0,0,0,0
endlayer

layer
0,0,0,0,0,0,0,0,0,0,0,0,0,0,0,0,0,0,0,0,0
0,0,0,0,0,0,0,0,0,0,0,0,0,0,0,0,0,0,0,0,0
0,0,0,0,0,0,0,0,0,0,0,10,10,10,10,10,10,0,0,0,0
0,0,0,0,0,0,0,0,0,0,10,10,10,10,10,10,10,10,0,0,0
0,0,0,0,0,0,0,0,0,0,10,10,10,10,10,10,10,10,0,0,0
0,0,0,0,0,0,0,0,0,0,10,10,10,10,10,10,10,10,0,0,0
0,0,0,0,0,0,0,0,0,0,0,10,10,10,10,10,10,0,0,0,0
0,0,0,0,0,0,0,0,0,0,0,0,10,10,10,10,10,0,0,0,0
0,0,0,0,0,0,0,0,0,0,0,0,0,10,10,10,0,0,0,0,0
0,0,0,0,0,0,0,0,0,0,0,0,0,0,10,0,0,0,0,0,0
0,0,0,0,0,0,0,0,0,0,0,0,0,10,10,10,0,0,0,0,0
0,0,0,0,0,0,0,0,0,0,0,0,0,0,10,0,0,0,0,0,0
0,0,0,0,0,0,0,0,0,0,0,0,0,0,0,0,0,0,0,0,0
0,0,0,0,0,0,0,0,0,0,0,0,0,0,0,0,0,0,0,0,0
0,0,0,0,0,0,0,0,0,0,0,0,0,0,0,0,0,0,0,0,0
0,0,0,0,0,0,0,0,0,0,0,0,0,0,0,0,0,0,0,0,0
0,0,0,0,0,0,0,0,0,0,0,0,0,0,0,0,0,0,0,0,0
0,0,0,0,0,0,0,0,0,0,0,0,0,0,0,0,0,0,0,0,0
0,0,0,0,0,0,0,0,0,0,0,0,0,0,0,0,0,0,0,0,0
0,0,0,0,0,0,0,0,0,0,0,0,0,0,0,0,0,0,0,0,0
0,0,0,0,0,0,0,0,0,0,0,0,0,0,0,0,0,0,0,0,0
0,0,0,0,0,0,0,0,0,0,0,0,0,0,0,0,0,0,0,0,0
0,0,0,0,0,0,0,0,0,0,0,0,0,0,0,0,0,0,0,0,0
0,0,0,0,0,0,0,0,0,0,0,0,0,0,0,0,0,0,0,0,0
0,0,0,0,0,0,0,0,0,0,0,0,0,0,0,0,0,0,0,0,0
0,0,0,0,0,0,0,0,0,0,0,0,0,0,0,0,0,0,0,0,0
0,0,0,0,0,0,0,0,0,0,0,0,0,0,0,0,0,0,0,0,0
0,0,0,0,0,0,0,0,0,0,0,0,0,0,0,0,0,0,0,0,0
0,0,0,0,0,0,0,0,0,0,0,0,0,0,0,0,0,0,0,0,0
0,0,0,0,0,0,0,0,0,0,0,0,0,0,0,0,0,0,0,0,0
0,0,0,0,0,0,0,0,0,0,0,0,0,0,0,0,0,0,0,0,0
endlayer

layer
0,0,0,0,0,0,0,0,0,0,0,0,0,0,0,0,0,0,0,0,0
0,0,0,0,0,0,0,0,0,0,0,0,0,0,0,0,0,0,0,0,0
0,0,0,0,0,0,0,0,0,0,0,0,0,0,0,0,0,0,0,0,0
0,0,0,0,0,0,0,0,0,0,0,0,10,0,0,10,0,0,0,0,0
0,0,0,0,0,0,0,0,0,0,0,10,10,10,10,10,10,0,0,0,0
0,0,0,0,0,0,0,0,0,0,0,0,10,10,10,10,10,0,0,0,0
0,0,0,0,0,0,0,0,0,0,0,0,10,10,10,10,10,0,0,0,0
0,0,0,0,0,0,0,0,0,0,0,0,10,10,10,10,10,0,0,0,0
0,0,0,0,0,0,0,0,0,0,0,0,0,10,10,10,0,0,0,0,0
0,0,0,0,0,0,0,0,0,0,0,0,0,0,0,0,0,0,0,0,0
0,0,0,0,0,0,0,0,0,0,0,0,0,0,0,0,0,0,0,0,0
0,0,0,0,0,0,0,0,0,0,0,0,0,0,0,0,0,0,0,0,0
0,0,0,0,0,0,0,0,0,0,0,0,0,0,0,0,0,0,0,0,0
0,0,0,0,0,0,0,0,0,0,0,0,0,0,0,0,0,0,0,0,0
0,0,0,0,0,0,0,0,0,0,0,0,0,0,0,0,0,0,0,0,0
0,0,0,0,0,0,0,0,0,0,0,0,0,0,0,0,0,0,0,0,0
0,0,0,0,0,0,0,0,0,0,0,0,0,0,0,0,0,0,0,0,0
0,0,0,0,0,0,0,0,0,0,0,0,0,0,0,0,0,0,0,0,0
0,0,0,0,0,0,0,0,0,0,0,0,0,0,0,0,0,0,0,0,0
0,0,0,0,0,0,0,0,0,0,0,0,0,0,0,0,0,0,0,0,0
0,0,0,0,0,0,0,0,0,0,0,0,0,0,0,0,0,0,0,0,0
0,0,0,0,0,0,0,0,0,0,0,0,0,0,0,0,0,0,0,0,0
0,0,0,0,0,0,0,0,0,0,0,0,0,0,0,0,0,0,0,0,0
0,0,0,0,0,0,0,0,0,0,0,0,0,0,0,0,0,0,0,0,0
0,0,0,0,0,0,0,0,0,0,0,0,0,0,0,0,0,0,0,0,0
0,0,0,0,0,0,0,0,0,0,0,0,0,0,0,0,0,0,0,0,0
0,0,0,0,0,0,0,0,0,0,0,0,0,0,0,0,0,0,0,0,0
0,0,0,0,0,0,0,0,0,0,0,0,0,0,0,0,0,0,0,0,0
0,0,0,0,0,0,0,0,0,0,0,0,0,0,0,0,0,0,0,0,0
0,0,0,0,0,0,0,0,0,0,0,0,0,0,0,0,0,0,0,0,0
0,0,0,0,0,0,0,0,0,0,0,0,0,0,0,0,0,0,0,0,0
endlayer

layer
0,0,0,0,0,0,0,0,0,0,0,0,0,0,0,0,0,0,0,0,0
0,0,0,0,0,0,0,0,0,0,0,0,0,0,0,0,0,0,0,0,0
0,0,0,0,0,0,0,0,0,0,0,0,0,0,0,0,0,0,0,0,0
0,0,0,0,0,0,0,0,0,0,0,0,0,0,0,0,0,0,0,0,0
0,0,0,0,0,0,0,0,0,0,0,0,0,0,0,0,0,0,0,0,0
0,0,0,0,0,0,0,0,0,0,0,0,0,0,10,0,0,0,0,0,0
0,0,0,0,0,0,0,0,0,0,0,0,0,10,10,10,0,0,0,0,0
0,0,0,0,0,0,0,0,0,0,0,0,0,0,10,0,0,0,0,0,0
0,0,0,0,0,0,0,0,0,0,0,0,0,0,0,0,0,0,0,0,0
0,0,0,0,0,0,0,0,0,0,0,0,0,0,0,0,0,0,0,0,0
0,0,0,0,0,0,0,0,0,0,0,0,0,0,0,0,0,0,0,0,0
0,0,0,0,0,0,0,0,0,0,0,0,0,0,0,0,0,0,0,0,0
0,0,0,0,0,0,0,0,0,0,0,0,0,0,0,0,0,0,0,0,0
0,0,0,0,0,0,0,0,0,0,0,0,0,0,0,0,0,0,0,0,0
0,0,0,0,0,0,0,0,0,0,0,0,0,0,0,0,0,0,0,0,0
0,0,0,0,0,0,0,0,0,0,0,0,0,0,0,0,0,0,0,0,0
0,0,0,0,0,0,0,0,0,0,0,0,0,0,0,0,0,0,0,0,0
0,0,0,0,0,0,0,0,0,0,0,0,0,0,0,0,0,0,0,0,0
0,0,0,0,0,0,0,0,0,0,0,0,0,0,0,0,0,0,0,0,0
0,0,0,0,0,0,0,0,0,0,0,0,0,0,0,0,0,0,0,0,0
0,0,0,0,0,0,0,0,0,0,0,0,0,0,0,0,0,0,0,0,0
0,0,0,0,0,0,0,0,0,0,0,0,0,0,0,0,0,0,0,0,0
0,0,0,0,0,0,0,0,0,0,0,0,0,0,0,0,0,0,0,0,0
0,0,0,0,0,0,0,0,0,0,0,0,0,0,0,0,0,0,0,0,0
0,0,0,0,0,0,0,0,0,0,0,0,0,0,0,0,0,0,0,0,0
0,0,0,0,0,0,0,0,0,0,0,0,0,0,0,0,0,0,0,0,0
0,0,0,0,0,0,0,0,0,0,0,0,0,0,0,0,0,0,0,0,0
0,0,0,0,0,0,0,0,0,0,0,0,0,0,0,0,0,0,0,0,0
0,0,0,0,0,0,0,0,0,0,0,0,0,0,0,0,0,0,0,0,0
0,0,0,0,0,0,0,0,0,0,0,0,0,0,0,0,0,0,0,0,0
0,0,0,0,0,0,0,0,0,0,0,0,0,0,0,0,0,0,0,0,0
endlayer

